Workbook

Sheet Sheet1
A1: Id | B1: ItemId | C1: Type | D1: ArtifactLevel | E1: DiamondsCost | F1: ItemCost | G1: Attr
A2: Int | B2: Int | C2: Int | D2: Int | E2: Int | F2: String | G2: String
A3: 序ID | B3: 物品表ID | C3: 神器类型 | D3: 神器等级 | E3: 升级消耗钻石 | F3: 升级消耗道具 | G3: 加成属性
A4: 1001 | B4: 22001000 | C4: 53 | D4: 0 | E4: =VLOOKUP(D:D,[1]神器碎片!$A$18:$E$519,5,FALSE) -> 0 | F4: 0 | G4: 0
A5: 1002 | B5: 22001000 | C5: 53 | D5: 1 | E5: =VLOOKUP(D:D,[1]神器碎片!$A$18:$E$519,5,FALSE) -> 15 | F5: 1010006,1 | G5: 13,10000|33,5
A6: 1003 | B6: 22001000 | C6: 53 | D6: 2 | E6: =VLOOKUP(D:D,[1]神器碎片!$A$18:$E$519,5,FALSE) -> 29 | F6: 1010006,2 | G6: 13,20000|33,10
A7: 1004 | B7: 22001000 | C7: 53 | D7: 3 | E7: =VLOOKUP(D:D,[1]神器碎片!$A$18:$E$519,5,FALSE) -> 44 | F7: 1010006,2 | G7: 13,30000|33,15
A8: 1005 | B8: 22001000 | C8: 53 | D8: 4 | E8: =VLOOKUP(D:D,[1]神器碎片!$A$18:$E$519,5,FALSE) -> 58 | F8: 1010006,3 | G8: 13,40000|33,20
A9: 1006 | B9: 22001000 | C9: 53 | D9: 5 | E9: =VLOOKUP(D:D,[1]神器碎片!$A$18:$E$519,5,FALSE) -> 73 | F9: 1010006,4 | G9: 13,50000|33,25
A10: 1007 | B10: 22001000 | C10: 53 | D10: 6 | E10: =VLOOKUP(D:D,[1]神器碎片!$A$18:$E$519,5,FALSE) -> 87 | F10: 1010006,5 | G10: 13,60000|33,30
A11: 1008 | B11: 22001000 | C11: 53 | D11: 7 | E11: =VLOOKUP(D:D,[1]神器碎片!$A$18:$E$519,5,FALSE) -> 102 | F11: 1010006,6 | G11: 13,70000|33,35
A12: 1009 | B12: 22001000 | C12: 53 | D12: 8 | E12: =VLOOKUP(D:D,[1]神器碎片!$A$18:$E$519,5,FALSE) -> 117 | F12: 1010006,6 | G12: 13,80000|33,40
A13: 1010 | B13: 22001000 | C13: 53 | D13: 9 | E13: =VLOOKUP(D:D,[1]神器碎片!$A$18:$E$519,5,FALSE) -> 131 | F13: 1010006,7 | G13: 13,90000|33,45
A14: 1011 | B14: 22001000 | C14: 53 | D14: 10 | E14: =VLOOKUP(D:D,[1]神器碎片!$A$18:$E$519,5,FALSE) -> 146 | F14: 1010006,8 | G14: 13,100000|33,50
A15: 1012 | B15: 22001000 | C15: 53 | D15: 11 | E15: =VLOOKUP(D:D,[1]神器碎片!$A$18:$E$519,5,FALSE) -> 160 | F15: 1010006,9 | G15: 13,110000|33,55
A16: 1013 | B16: 22001000 | C16: 53 | D16: 12 | E16: =VLOOKUP(D:D,[1]神器碎片!$A$18:$E$519,5,FALSE) -> 175 | F16: 1010006,10 | G16: 13,120000|33,60
... A504: 1501 | B504: 22001001 | C504: 53 | D504: 500 | E504: =VLOOKUP(D:D,[1]神器碎片!$A$18:$E$519,5,FALSE) -> 7285 | F504: 1010006,399 | G504: 13,5000000|33,2500
A505: =A4+1000 -> 2001 | B505: 22002000 | C505: 54 | D505: 0 | E505: =VLOOKUP(D:D,[1]神器碎片!$A$18:$E$519,5,FALSE) -> 0 | F505: 0 | G505: 0
A506: =A5+1000 -> 2002 | B506: 22002000 | C506: 54 | D506: 1 | E506: =VLOOKUP(D:D,[1]神器碎片!$A$18:$E$519,5,FALSE) -> 15 | F506: 1010007,1 | G506: 29,10|30,5000
A507: =A6+1000 -> 2003 | B507: 22002000 | C507: 54 | D507: 2 | E507: =VLOOKUP(D:D,[1]神器碎片!$A$18:$E$519,5,FALSE) -> 29 | F507: 1010007,2 | G507: 29,20|30,10000
A508: =A7+1000 -> 2004 | B508: 22002000 | C508: 54 | D508: 3 | E508: =VLOOKUP(D:D,[1]神器碎片!$A$18:$E$519,5,FALSE) -> 44 | F508: 1010007,2 | G508: 29,30|30,15000
A509: =A8+1000 -> 2005 | B509: 22002000 | C509: 54 | D509: 4 | E509: =VLOOKUP(D:D,[1]神器碎片!$A$18:$E$519,5,FALSE) -> 58 | F509: 1010007,3 | G509: 29,40|30,20000
A510: =A9+1000 -> 2006 | B510: 22002000 | C510: 54 | D510: 5 | E510: =VLOOKUP(D:D,[1]神器碎片!$A$18:$E$519,5,FALSE) -> 73 | F510: 1010007,4 | G510: 29,50|30,25000
A511: =A10+1000 -> 2007 | B511: 22002000 | C511: 54 | D511: 6 | E511: =VLOOKUP(D:D,[1]神器碎片!$A$18:$E$519,5,FALSE) -> 87 | F511: 1010007,5 | G511: 29,60|30,30000
A512: =A11+1000 -> 2008 | B512: 22002000 | C512: 54 | D512: 7 | E512: =VLOOKUP(D:D,[1]神器碎片!$A$18:$E$519,5,FALSE) -> 102 | F512: 1010007,6 | G512: 29,70|30,35000
A513: =A12+1000 -> 2009 | B513: 22002000 | C513: 54 | D513: 8 | E513: =VLOOKUP(D:D,[1]神器碎片!$A$18:$E$519,5,FALSE) -> 117 | F513: 1010007,6 | G513: 29,80|30,40000
A514: =A13+1000 -> 2010 | B514: 22002000 | C514: 54 | D514: 9 | E514: =VLOOKUP(D:D,[1]神器碎片!$A$18:$E$519,5,FALSE) -> 131 | F514: 1010007,7 | G514: 29,90|30,45000
A515: =A14+1000 -> 2011 | B515: 22002000 | C515: 54 | D515: 10 | E515: =VLOOKUP(D:D,[1]神器碎片!$A$18:$E$519,5,FALSE) -> 146 | F515: 1010007,8 | G515: 29,100|30,50000
A516: =A15+1000 -> 2012 | B516: 22002000 | C516: 54 | D516: 11 | E516: =VLOOKUP(D:D,[1]神器碎片!$A$18:$E$519,5,FALSE) -> 160 | F516: 1010007,9 | G516: 29,110|30,55000
A517: =A16+1000 -> 2013 | B517: 22002000 | C517: 54 | D517: 12 | E517: =VLOOKUP(D:D,[1]神器碎片!$A$18:$E$519,5,FALSE) -> 175 | F517: 1010007,10 | G517: 29,120|30,60000
... A1005: =A504+1000 -> 2501 | B1005: 22002001 | C1005: 54 | D1005: 500 | E1005: =VLOOKUP(D:D,[1]神器碎片!$A$18:$E$519,5,FALSE) -> 7285 | F1005: 1010007,399 | G1005: 29,5000|30,2500000
A1006: =A505+1000 -> 3001 | B1006: 22003000 | C1006: 56 | D1006: 0 | E1006: =VLOOKUP(D:D,[1]神器碎片!$A$18:$E$519,5,FALSE) -> 0 | F1006: 0 | G1006: 0
A1007: =A506+1000 -> 3002 | B1007: 22003000 | C1007: 56 | D1007: 1 | E1007: =VLOOKUP(D:D,[1]神器碎片!$A$18:$E$519,5,FALSE) -> 15 | F1007: 1010008,1 | G1007: 36,3000|37,200
A1008: =A507+1000 -> 3003 | B1008: 22003000 | C1008: 56 | D1008: 2 | E1008: =VLOOKUP(D:D,[1]神器碎片!$A$18:$E$519,5,FALSE) -> 29 | F1008: 1010008,2 | G1008: 36,6000|37,400
A1009: =A508+1000 -> 3004 | B1009: 22003000 | C1009: 56 | D1009: 3 | E1009: =VLOOKUP(D:D,[1]神器碎片!$A$18:$E$519,5,FALSE) -> 44 | F1009: 1010008,2 | G1009: 36,9000|37,600
A1010: =A509+1000 -> 3005 | B1010: 22003000 | C1010: 56 | D1010: 4 | E1010: =VLOOKUP(D:D,[1]神器碎片!$A$18:$E$519,5,FALSE) -> 58 | F1010: 1010008,3 | G1010: 36,12000|37,800
A1011: =A510+1000 -> 3006 | B1011: 22003000 | C1011: 56 | D1011: 5 | E1011: =VLOOKUP(D:D,[1]神器碎片!$A$18:$E$519,5,FALSE) -> 73 | F1011: 1010008,4 | G1011: 36,15000|37,1000
A1012: =A511+1000 -> 3007 | B1012: 22003000 | C1012: 56 | D1012: 6 | E1012: =VLOOKUP(D:D,[1]神器碎片!$A$18:$E$519,5,FALSE) -> 87 | F1012: 1010008,5 | G1012: 36,18000|37,1200
A1013: =A512+1000 -> 3008 | B1013: 22003000 | C1013: 56 | D1013: 7 | E1013: =VLOOKUP(D:D,[1]神器碎片!$A$18:$E$519,5,FALSE) -> 102 | F1013: 1010008,6 | G1013: 36,21000|37,1400
A1014: =A513+1000 -> 3009 | B1014: 22003000 | C1014: 56 | D1014: 8 | E1014: =VLOOKUP(D:D,[1]神器碎片!$A$18:$E$519,5,FALSE) -> 117 | F1014: 1010008,6 | G1014: 36,24000|37,1600
...

Sheet Sheet2
A3: 神器等级 | B3: 升级消耗道具 | D3: 道具ID | E3: 连接符
A4: 0 | B4: =VLOOKUP(A:A,[1]神器碎片!$A$18:$E$519,4,FALSE) -> 0 | D4: 1010006 | E4: , | F4: =D4&E4&B4 -> 1010006,0
A5: 1 | B5: =VLOOKUP(A:A,[1]神器碎片!$A$18:$E$519,4,FALSE) -> 1 | D5: 1010006 | E5: , | F5: =D5&E5&B5 -> 1010006,1
A6: 2 | B6: =VLOOKUP(A:A,[1]神器碎片!$A$18:$E$519,4,FALSE) -> 2 | D6: 1010006 | E6: , | F6: =D6&E6&B6 -> 1010006,2
A7: 3 | B7: =VLOOKUP(A:A,[1]神器碎片!$A$18:$E$519,4,FALSE) -> 2 | D7: 1010006 | E7: , | F7: =D7&E7&B7 -> 1010006,2
A8: 4 | B8: =VLOOKUP(A:A,[1]神器碎片!$A$18:$E$519,4,FALSE) -> 3 | D8: 1010006 | E8: , | F8: =D8&E8&B8 -> 1010006,3
A9: 5 | B9: =VLOOKUP(A:A,[1]神器碎片!$A$18:$E$519,4,FALSE) -> 4 | D9: 1010006 | E9: , | F9: =D9&E9&B9 -> 1010006,4
A10: 6 | B10: =VLOOKUP(A:A,[1]神器碎片!$A$18:$E$519,4,FALSE) -> 5 | D10: 1010006 | E10: , | F10: =D10&E10&B10 -> 1010006,5
A11: 7 | B11: =VLOOKUP(A:A,[1]神器碎片!$A$18:$E$519,4,FALSE) -> 6 | D11: 1010006 | E11: , | F11: =D11&E11&B11 -> 1010006,6
A12: 8 | B12: =VLOOKUP(A:A,[1]神器碎片!$A$18:$E$519,4,FALSE) -> 6 | D12: 1010006 | E12: , | F12: =D12&E12&B12 -> 1010006,6
A13: 9 | B13: =VLOOKUP(A:A,[1]神器碎片!$A$18:$E$519,4,FALSE) -> 7 | D13: 1010006 | E13: , | F13: =D13&E13&B13 -> 1010006,7
A14: 10 | B14: =VLOOKUP(A:A,[1]神器碎片!$A$18:$E$519,4,FALSE) -> 8 | D14: 1010006 | E14: , | F14: =D14&E14&B14 -> 1010006,8
A15: 11 | B15: =VLOOKUP(A:A,[1]神器碎片!$A$18:$E$519,4,FALSE) -> 9 | D15: 1010006 | E15: , | F15: =D15&E15&B15 -> 1010006,9
... A504: 500 | B504: =VLOOKUP(A:A,[1]神器碎片!$A$18:$E$519,4,FALSE) -> 399 | D504: 1010006 | E504: , | F504: =D504&E504&B504 -> 1010006,399
A505: 0 | B505: =VLOOKUP(A:A,[1]神器碎片!$A$18:$E$519,4,FALSE) -> 0 | D505: =D4+1 -> 1010007 | E505: , | F505: =D505&E505&B505 -> 1010007,0
A506: 1 | B506: =VLOOKUP(A:A,[1]神器碎片!$A$18:$E$519,4,FALSE) -> 1 | D506: =D5+1 -> 1010007 | E506: , | F506: =D506&E506&B506 -> 1010007,1
A507: 2 | B507: =VLOOKUP(A:A,[1]神器碎片!$A$18:$E$519,4,FALSE) -> 2 | D507: =D6+1 -> 1010007 | E507: , | F507: =D507&E507&B507 -> 1010007,2
A508: 3 | B508: =VLOOKUP(A:A,[1]神器碎片!$A$18:$E$519,4,FALSE) -> 2 | D508: =D7+1 -> 1010007 | E508: , | F508: =D508&E508&B508 -> 1010007,2
A509: 4 | B509: =VLOOKUP(A:A,[1]神器碎片!$A$18:$E$519,4,FALSE) -> 3 | D509: =D8+1 -> 1010007 | E509: , | F509: =D509&E509&B509 -> 1010007,3
A510: 5 | B510: =VLOOKUP(A:A,[1]神器碎片!$A$18:$E$519,4,FALSE) -> 4 | D510: =D9+1 -> 1010007 | E510: , | F510: =D510&E510&B510 -> 1010007,4
A511: 6 | B511: =VLOOKUP(A:A,[1]神器碎片!$A$18:$E$519,4,FALSE) -> 5 | D511: =D10+1 -> 1010007 | E511: , | F511: =D511&E511&B511 -> 1010007,5
A512: 7 | B512: =VLOOKUP(A:A,[1]神器碎片!$A$18:$E$519,4,FALSE) -> 6 | D512: =D11+1 -> 1010007 | E512: , | F512: =D512&E512&B512 -> 1010007,6
A513: 8 | B513: =VLOOKUP(A:A,[1]神器碎片!$A$18:$E$519,4,FALSE) -> 6 | D513: =D12+1 -> 1010007 | E513: , | F513: =D513&E513&B513 -> 1010007,6
A514: 9 | B514: =VLOOKUP(A:A,[1]神器碎片!$A$18:$E$519,4,FALSE) -> 7 | D514: =D13+1 -> 1010007 | E514: , | F514: =D514&E514&B514 -> 1010007,7
A515: 10 | B515: =VLOOKUP(A:A,[1]神器碎片!$A$18:$E$519,4,FALSE) -> 8 | D515: =D14+1 -> 1010007 | E515: , | F515: =D515&E515&B515 -> 1010007,8
A516: 11 | B516: =VLOOKUP(A:A,[1]神器碎片!$A$18:$E$519,4,FALSE) -> 9 | D516: =D15+1 -> 1010007 | E516: , | F516: =D516&E516&B516 -> 1010007,9
... A2007: 500 | B2007: =VLOOKUP(A:A,[1]神器碎片!$A$18:$E$519,4,FALSE) -> 399 | D2007: =D1506+1 -> 1010009 | E2007: , | F2007: =D2007&E2007&B2007 -> 1010009,399

Sheet Sheet3
