Workbook

Sheet Sheet1
A1: Id | B1: Name_Note | C1: Name | D1: Name_param | E1: Type | F1: Stage | G1: MonsterData | H1: HarmType | I1: EntryNumber | J1: EntryGroup | K1: PhysicalAtk | L1: MagicAtk | M1: SorceryAtk | N1: PhysicalDef | O1: MagicDef | P1: SorceryDef | Q1: Hp | R1: Reply | S1: Time | T1: PassReward
A2: Int | B2: String | C2: String | D2: String | E2: Int | F2: Int | G2: ArrayInt | H2: Int | I2: Int | J2: Int | K2: String | L2: String | M2: String | N2: String | O2: String | P2: String | Q2: String | R2: String | S2: int | T2: String
A3: 关卡ID | B3: <c>关卡名称 | C3: 关卡名称 | D3: 关卡名称参数 | E3: 副本type | F3: 副本关数 | G3: 关卡刷怪数据 | H3: 伤害类型 | I3: 词条数量 | J3: 词条组 | K3: 物理伤害 | L3: 魔法伤害 | M3: 道术伤害 | N3: 物理防御 | O3: 魔法防御 | P3: 道术防御 | Q3: 生命值 | R3: 生命恢复 | S3: 通关时间 | T3: 通关奖励
A4: 10001 | B4: 金币副本lv.1 | C4: DungeonStage_Name_30001 | D4: 1 | E4: 1 | F4: 1 | G4: 10055 | H4: 2 | I4: 0 | J4: 4 | K4: 2125 | L4: 2125 | M4: 2125 | N4: 0 | O4: 0 | P4: 0 | Q4: 18975 | R4: =[1]Sheet1!Q8 -> 0 | S4: 60 | T4: 2000,408960
A5: 10002 | B5: 金币副本lv.2 | C5: DungeonStage_Name_30001 | D5: 2 | E5: 1 | F5: 2 | G5: 10105 | H5: 1 | I5: 0 | J5: 4 | K5: 21420 | L5: 21420 | M5: 21420 | N5: 0 | O5: 0 | P5: 0 | Q5: 480400 | R5: =[1]Sheet1!Q9 -> 0 | S5: 60 | T5: 2000,442800
A6: 10003 | B6: 金币副本lv.3 | C6: DungeonStage_Name_30001 | D6: 3 | E6: 1 | F6: 3 | G6: 10155 | H6: 3 | I6: 0 | J6: 4 | K6: 96540 | L6: 96540 | M6: 96540 | N6: 0 | O6: 0 | P6: 0 | Q6: 7033975 | R6: =[1]Sheet1!Q10 -> 0 | S6: 60 | T6: 2000,461520
A7: 10004 | B7: 金币副本lv.4 | C7: DungeonStage_Name_30001 | D7: 4 | E7: 1 | F7: 4 | G7: 10205 | H7: 2 | I7: 0 | J7: 4 | K7: 208495 | L7: 208495 | M7: 208495 | N7: 0 | O7: 0 | P7: 0 | Q7: 27080900 | R7: =[1]Sheet1!Q11 -> 0 | S7: 60 | T7: 2000,461520
A8: 10005 | B8: 金币副本lv.5 | C8: DungeonStage_Name_30001 | D8: 5 | E8: 1 | F8: 5 | G8: 20055 | H8: 1 | I8: 2 | J8: 4 | K8: 685670 | L8: 685670 | M8: 685670 | N8: 0 | O8: 0 | P8: 0 | Q8: 495343500 | R8: =[1]Sheet1!Q12 -> 0 | S8: 60 | T8: 2000,465120
A9: 10006 | B9: 金币副本lv.6 | C9: DungeonStage_Name_30001 | D9: 6 | E9: 1 | F9: 6 | G9: 20105 | H9: 3 | I9: 2 | J9: 4 | K9: 1067940 | L9: 1067940 | M9: 1067940 | N9: 0 | O9: 0 | P9: 0 | Q9: 973025250 | R9: =[1]Sheet1!Q13 -> 0 | S9: 60 | T9: 2000,465120
A10: 10007 | B10: 金币副本lv.7 | C10: DungeonStage_Name_30001 | D10: 7 | E10: 1 | F10: 7 | G10: 20155 | H10: 2 | I10: 2 | J10: 4 | K10: 1574180 | L10: 1574180 | M10: 1574180 | N10: 0 | O10: 0 | P10: 0 | Q10: 2134528150 | R10: =[1]Sheet1!Q14 -> 0 | S10: 60 | T10: 2000,465120
A11: 10008 | B11: 金币副本lv.8 | C11: DungeonStage_Name_30001 | D11: 8 | E11: 1 | F11: 8 | G11: 20205 | H11: 1 | I11: 2 | J11: 4 | K11: 2244425 | L11: 2244425 | M11: 2244425 | N11: 0 | O11: 0 | P11: 0 | Q11: 4136039450 | R11: =[1]Sheet1!Q15 -> 0 | S11: 60 | T11: 2000,465120
A12: 10009 | B12: 金币副本lv.9 | C12: DungeonStage_Name_30001 | D12: 9 | E12: 1 | F12: 9 | G12: 30055 | H12: 3 | I12: 2 | J12: 4 | K12: 7392785 | L12: 7392785 | M12: 7392785 | N12: 0 | O12: 0 | P12: 0 | Q12: 17071043050 | R12: =[1]Sheet1!Q16 -> 0 | S12: 60 | T12: 2000,697680
A13: 10010 | B13: 金币副本lv.10 | C13: DungeonStage_Name_30001 | D13: 10 | E13: 1 | F13: 10 | G13: 30105 | H13: 2 | I13: 2 | J13: 4 | K13: 9690620 | L13: 9690620 | M13: 9690620 | N13: 0 | O13: 0 | P13: 0 | Q13: 32665383950 | R13: =[1]Sheet1!Q17 -> 0 | S13: 60 | T13: 2000,697680
A14: 10011 | B14: 金币副本lv.11 | C14: DungeonStage_Name_30001 | D14: 11 | E14: 1 | F14: 11 | G14: 30155 | H14: 1 | I14: 2 | J14: 4 | K14: 12472805 | L14: 12472805 | M14: 12472805 | N14: 0 | O14: 0 | P14: 0 | Q14: 56612113850 | R14: =[1]Sheet1!Q18 -> 0 | S14: 60 | T14: 2000,697680
A15: 10012 | B15: 金币副本lv.12 | C15: DungeonStage_Name_30001 | D15: 12 | E15: 1 | F15: 12 | G15: 30205 | H15: 3 | I15: 2 | J15: 4 | K15: 15756730 | L15: 15756730 | M15: 15756730 | N15: 0 | O15: 0 | P15: 0 | Q15: 90093679900 | R15: =[1]Sheet1!Q19 -> 0 | S15: 60 | T15: 2000,697680
... A123: 10120 | B123: 金币副本lv.120 | C123: DungeonStage_Name_30001 | D123: 120 | E123: 1 | F123: 120 | G123: 50045 | H123: 3 | I123: 2 | J123: 6 | K123: 11196545828205 | L123: 11196545828205 | M123: 11196545828205 | N123: 0 | O123: 0 | P123: 0 | Q123: 2.6968238e+27 | R123: =[1]Sheet1!Q127 -> 0 | S123: 60 | T123: 2000,8334000
A124: =A4+10000 -> 20001 | B124: 铸造副本lv.1 | C124: DungeonStage_Name_10001 | D124: 1 | E124: 2 | F124: 1 | G124: 10055 | H124: 2 | I124: =I4 -> 0 | J124: =J4 -> 4 | K124: =K4 -> 2125 | L124: =L4 -> 2125 | M124: =M4 -> 2125 | N124: =N4 -> 0 | O124: =O4 -> 0 | P124: =P4 -> 0 | Q124: =Q4 -> 18975 | R124: 0 | S124: 60 | T124: 10000001,8
A125: =A5+10000 -> 20002 | B125: 铸造副本lv.2 | C125: DungeonStage_Name_10001 | D125: 2 | E125: 2 | F125: 2 | G125: 10105 | H125: 1 | I125: =I5 -> 0 | J125: =J5 -> 4 | K125: =K5 -> 21420 | L125: =L5 -> 21420 | M125: =M5 -> 21420 | N125: =N5 -> 0 | O125: =O5 -> 0 | P125: =P5 -> 0 | Q125: =Q5 -> 480400 | R125: 0 | S125: 60 | T125: 10000001,8
A126: =A6+10000 -> 20003 | B126: 铸造副本lv.3 | C126: DungeonStage_Name_10001 | D126: 3 | E126: 2 | F126: 3 | G126: 10155 | H126: 3 | I126: =I6 -> 0 | J126: =J6 -> 4 | K126: =K6 -> 96540 | L126: =L6 -> 96540 | M126: =M6 -> 96540 | N126: =N6 -> 0 | O126: =O6 -> 0 | P126: =P6 -> 0 | Q126: =Q6 -> 7033975 | R126: 0 | S126: 60 | T126: 10000001,8
A127: =A7+10000 -> 20004 | B127: 铸造副本lv.4 | C127: DungeonStage_Name_10001 | D127: 4 | E127: 2 | F127: 4 | G127: 10205 | H127: 2 | I127: =I7 -> 0 | J127: =J7 -> 4 | K127: =K7 -> 208495 | L127: =L7 -> 208495 | M127: =M7 -> 208495 | N127: =N7 -> 0 | O127: =O7 -> 0 | P127: =P7 -> 0 | Q127: =Q7 -> 27080900 | R127: 0 | S127: 60 | T127: 10000001,8
A128: =A8+10000 -> 20005 | B128: 铸造副本lv.5 | C128: DungeonStage_Name_10001 | D128: 5 | E128: 2 | F128: 5 | G128: 20055 | H128: 1 | I128: =I8 -> 2 | J128: =J8 -> 4 | K128: =K8 -> 685670 | L128: =L8 -> 685670 | M128: =M8 -> 685670 | N128: =N8 -> 0 | O128: =O8 -> 0 | P128: =P8 -> 0 | Q128: =Q8 -> 495343500 | R128: 0 | S128: 60 | T128: 10000001,9
A129: =A9+10000 -> 20006 | B129: 铸造副本lv.6 | C129: DungeonStage_Name_10001 | D129: 6 | E129: 2 | F129: 6 | G129: 20105 | H129: 3 | I129: =I9 -> 2 | J129: =J9 -> 4 | K129: =K9 -> 1067940 | L129: =L9 -> 1067940 | M129: =M9 -> 1067940 | N129: =N9 -> 0 | O129: =O9 -> 0 | P129: =P9 -> 0 | Q129: =Q9 -> 973025250 | R129: 0 | S129: 60 | T129: 10000001,9
A130: =A10+10000 -> 20007 | B130: 铸造副本lv.7 | C130: DungeonStage_Name_10001 | D130: 7 | E130: 2 | F130: 7 | G130: 20155 | H130: 2 | I130: =I10 -> 2 | J130: =J10 -> 4 | K130: =K10 -> 1574180 | L130: =L10 -> 1574180 | M130: =M10 -> 1574180 | N130: =N10 -> 0 | O130: =O10 -> 0 | P130: =P10 -> 0 | Q130: =Q10 -> 2134528150 | R130: 0 | S130: 60 | T130: 10000001,9
A131: =A11+10000 -> 20008 | B131: 铸造副本lv.8 | C131: DungeonStage_Name_10001 | D131: 8 | E131: 2 | F131: 8 | G131: 20205 | H131: 1 | I131: =I11 -> 2 | J131: =J11 -> 4 | K131: =K11 -> 2244425 | L131: =L11 -> 2244425 | M131: =M11 -> 2244425 | N131: =N11 -> 0 | O131: =O11 -> 0 | P131: =P11 -> 0 | Q131: =Q11 -> 4136039450 | R131: 0 | S131: 60 | T131: 10000001,9
A132: =A12+10000 -> 20009 | B132: 铸造副本lv.9 | C132: DungeonStage_Name_10001 | D132: 9 | E132: 2 | F132: 9 | G132: 30055 | H132: 3 | I132: =I12 -> 2 | J132: =J12 -> 4 | K132: =K12 -> 7392785 | L132: =L12 -> 7392785 | M132: =M12 -> 7392785 | N132: =N12 -> 0 | O132: =O12 -> 0 | P132: =P12 -> 0 | Q132: =Q12 -> 17071043050 | R132: 0 | S132: 60 | T132: 10000001,10
A133: =A13+10000 -> 20010 | B133: 铸造副本lv.10 | C133: DungeonStage_Name_10001 | D133: 10 | E133: 2 | F133: 10 | G133: 30105 | H133: 2 | I133: =I13 -> 2 | J133: =J13 -> 4 | K133: =K13 -> 9690620 | L133: =L13 -> 9690620 | M133: =M13 -> 9690620 | N133: =N13 -> 0 | O133: =O13 -> 0 | P133: =P13 -> 0 | Q133: =Q13 -> 32665383950 | R133: 0 | S133: 60 | T133: 10000001,10
A134: =A14+10000 -> 20011 | B134: 铸造副本lv.11 | C134: DungeonStage_Name_10001 | D134: 11 | E134: 2 | F134: 11 | G134: 30155 | H134: 1 | I134: =I14 -> 2 | J134: =J14 -> 4 | K134: =K14 -> 12472805 | L134: =L14 -> 12472805 | M134: =M14 -> 12472805 | N134: =N14 -> 0 | O134: =O14 -> 0 | P134: =P14 -> 0 | Q134: =Q14 -> 56612113850 | R134: 0 | S134: 60 | T134: 10000001,10
A135: =A15+10000 -> 20012 | B135: 铸造副本lv.12 | C135: DungeonStage_Name_10001 | D135: 12 | E135: 2 | F135: 12 | G135: 30205 | H135: 3 | I135: =I15 -> 2 | J135: =J15 -> 4 | K135: =K15 -> 15756730 | L135: =L15 -> 15756730 | M135: =M15 -> 15756730 | N135: =N15 -> 0 | O135: =O15 -> 0 | P135: =P15 -> 0 | Q135: =Q15 -> 90093679900 | R135: 0 | S135: 60 | T135: 10000001,10
... A363: =A243+10000 -> 30120 | B363: 钻石副本lv.120 | C363: DungeonStage_Name_20001 | D363: 120 | E363: 3 | F363: 120 | G363: 50045 | H363: 3 | I363: =I243 -> 2 | J363: =J243 -> 6 | K363: =K243 -> 11196545828205 | L363: =L243 -> 11196545828205 | M363: =M243 -> 11196545828205 | N363: =N243 -> 0 | O363: =O243 -> 0 | P363: =P243 -> 0 | Q363: =Q243 -> 2.6968238e+27 | R363: 0 | S363: 60 | T363: 1000,590
A364: 40001 | B364: 英雄经验副本lv.1 | C364: DungeonStage_Name_40001 | D364: 1 | E364: 4 | F364: 1 | G364: =G250 -> 20155 | H364: =H250 -> 2 | I364: =I244 -> 0 | J364: =J244 -> 4 | K364: =K244 -> 2125 | L364: =L244 -> 2125 | M364: =M244 -> 2125 | N364: =N244 -> 0 | O364: =O244 -> 0 | P364: =P244 -> 0 | Q364: =Q244 -> 18975 | R364: 0 | S364: 60 | T364: 1010001,25|1010002,1
A365: 40002 | B365: 英雄经验副本lv.2 | C365: DungeonStage_Name_40001 | D365: 2 | E365: 4 | F365: 2 | G365: =G251 -> 20205 | H365: =H251 -> 1 | I365: =I245 -> 0 | J365: =J245 -> 4 | K365: =K245 -> 21420 | L365: =L245 -> 21420 | M365: =M245 -> 21420 | N365: =N245 -> 0 | O365: =O245 -> 0 | P365: =P245 -> 0 | Q365: =Q245 -> 480400 | R365: 0 | S365: 60 | T365: 1010001,25|1010002,1
A366: 40003 | B366: 英雄经验副本lv.3 | C366: DungeonStage_Name_40001 | D366: 3 | E366: 4 | F366: 3 | G366: =G252 -> 30055 | H366: =H252 -> 3 | I366: =I246 -> 0 | J366: =J246 -> 4 | K366: =K246 -> 96540 | L366: =L246 -> 96540 | M366: =M246 -> 96540 | N366: =N246 -> 0 | O366: =O246 -> 0 | P366: =P246 -> 0 | Q366: =Q246 -> 7033975 | R366: 0 | S366: 60 | T366: 1010001,25|1010002,1
A367: 40004 | B367: 英雄经验副本lv.4 | C367: DungeonStage_Name_40001 | D367: 4 | E367: 4 | F367: 4 | G367: =G253 -> 30105 | H367: =H253 -> 2 | I367: =I247 -> 0 | J367: =J247 -> 4 | K367: =K247 -> 208495 | L367: =L247 -> 208495 | M367: =M247 -> 208495 | N367: =N247 -> 0 | O367: =O247 -> 0 | P367: =P247 -> 0 | Q367: =Q247 -> 27080900 | R367: 0 | S367: 60 | T367: 1010001,25|1010002,1
A368: 40005 | B368: 英雄经验副本lv.5 | C368: DungeonStage_Name_40001 | D368: 5 | E368: 4 | F368: 5 | G368: =G254 -> 30155 | H368: =H254 -> 1 | I368: =I248 -> 2 | J368: =J248 -> 4 | K368: =K248 -> 685670 | L368: =L248 -> 685670 | M368: =M248 -> 685670 | N368: =N248 -> 0 | O368: =O248 -> 0 | P368: =P248 -> 0 | Q368: =Q248 -> 495343500 | R368: 0 | S368: 60 | T368: 1010001,26|1010002,1
A369: 40006 | B369: 英雄经验副本lv.6 | C369: DungeonStage_Name_40001 | D369: 6 | E369: 4 | F369: 6 | G369: =G255 -> 30205 | H369: =H255 -> 3 | I369: =I249 -> 2 | J369: =J249 -> 4 | K369: =K249 -> 1067940 | L369: =L249 -> 1067940 | M369: =M249 -> 1067940 | N369: =N249 -> 0 | O369: =O249 -> 0 | P369: =P249 -> 0 | Q369: =Q249 -> 973025250 | R369: 0 | S369: 60 | T369: 1010001,26|1010002,1
A370: 40007 | B370: 英雄经验副本lv.7 | C370: DungeonStage_Name_40001 | D370: 7 | E370: 4 | F370: 7 | G370: =G256 -> 40055 | H370: =H256 -> 2 | I370: =I250 -> 2 | J370: =J250 -> 4 | K370: =K250 -> 1574180 | L370: =L250 -> 1574180 | M370: =M250 -> 1574180 | N370: =N250 -> 0 | O370: =O250 -> 0 | P370: =P250 -> 0 | Q370: =Q250 -> 2134528150 | R370: 0 | S370: 60 | T370: 1010001,26|1010002,1
A371: 40008 | B371: 英雄经验副本lv.8 | C371: DungeonStage_Name_40001 | D371: 8 | E371: 4 | F371: 8 | G371: =G257 -> 40105 | H371: =H257 -> 1 | I371: =I251 -> 2 | J371: =J251 -> 4 | K371: =K251 -> 2244425 | L371: =L251 -> 2244425 | M371: =M251 -> 2244425 | N371: =N251 -> 0 | O371: =O251 -> 0 | P371: =P251 -> 0 | Q371: =Q251 -> 4136039450 | R371: 0 | S371: 60 | T371: 1010001,26|1010002,1
A372: 40009 | B372: 英雄经验副本lv.9 | C372: DungeonStage_Name_40001 | D372: 9 | E372: 4 | F372: 9 | G372: =G258 -> 40155 | H372: =H258 -> 3 | I372: =I252 -> 2 | J372: =J252 -> 4 | K372: =K252 -> 7392785 | L372: =L252 -> 7392785 | M372: =M252 -> 7392785 | N372: =N252 -> 0 | O372: =O252 -> 0 | P372: =P252 -> 0 | Q372: =Q252 -> 17071043050 | R372: 0 | S372: 60 | T372: 1010001,27|1010002,1
A373: 40010 | B373: 英雄经验副本lv.10 | C373: DungeonStage_Name_40001 | D373: 10 | E373: 4 | F373: 10 | G373: =G259 -> 40205 | H373: =H259 -> 2 | I373: =I253 -> 2 | J373: =J253 -> 4 | K373: =K253 -> 9690620 | L373: =L253 -> 9690620 | M373: =M253 -> 9690620 | N373: =N253 -> 0 | O373: =O253 -> 0 | P373: =P253 -> 0 | Q373: =Q253 -> 32665383950 | R373: 0 | S373: 60 | T373: 1010001,27|1010002,1
A374: 40011 | B374: 英雄经验副本lv.11 | C374: DungeonStage_Name_40001 | D374: 11 | E374: 4 | F374: 11 | G374: =G260 -> 50055 | H374: =H260 -> 1 | I374: =I254 -> 2 | J374: =J254 -> 4 | K374: =K254 -> 12472805 | L374: =L254 -> 12472805 | M374: =M254 -> 12472805 | N374: =N254 -> 0 | O374: =O254 -> 0 | P374: =P254 -> 0 | Q374: =Q254 -> 56612113850 | R374: 0 | S374: 60 | T374: 1010001,27|1010002,1
...

Sheet 钻石
A1: 钻石关卡 | B1: 钻石数量 | C1: 钻石道具ID | D1: 链接符
A2: 1 | B2: =VLOOKUP(A:A,[2]钻石产出!$B$28:$C$147,2,FALSE) -> 300 | C2: 1000 | D2: , | E2: =C2&D2&B2 -> 1000,300
A3: 2 | B3: =VLOOKUP(A:A,[2]钻石产出!$B$28:$C$147,2,FALSE) -> 300 | C3: 1000 | D3: , | E3: =C3&D3&B3 -> 1000,300
A4: 3 | B4: =VLOOKUP(A:A,[2]钻石产出!$B$28:$C$147,2,FALSE) -> 300 | C4: 1000 | D4: , | E4: =C4&D4&B4 -> 1000,300
A5: 4 | B5: =VLOOKUP(A:A,[2]钻石产出!$B$28:$C$147,2,FALSE) -> 300 | C5: 1000 | D5: , | E5: =C5&D5&B5 -> 1000,300
A6: 5 | B6: =VLOOKUP(A:A,[2]钻石产出!$B$28:$C$147,2,FALSE) -> 310 | C6: 1000 | D6: , | E6: =C6&D6&B6 -> 1000,310
A7: 6 | B7: =VLOOKUP(A:A,[2]钻石产出!$B$28:$C$147,2,FALSE) -> 310 | C7: 1000 | D7: , | E7: =C7&D7&B7 -> 1000,310
A8: 7 | B8: =VLOOKUP(A:A,[2]钻石产出!$B$28:$C$147,2,FALSE) -> 310 | C8: 1000 | D8: , | E8: =C8&D8&B8 -> 1000,310
A9: 8 | B9: =VLOOKUP(A:A,[2]钻石产出!$B$28:$C$147,2,FALSE) -> 310 | C9: 1000 | D9: , | E9: =C9&D9&B9 -> 1000,310
A10: 9 | B10: =VLOOKUP(A:A,[2]钻石产出!$B$28:$C$147,2,FALSE) -> 320 | C10: 1000 | D10: , | E10: =C10&D10&B10 -> 1000,320
A11: 10 | B11: =VLOOKUP(A:A,[2]钻石产出!$B$28:$C$147,2,FALSE) -> 320 | C11: 1000 | D11: , | E11: =C11&D11&B11 -> 1000,320
A12: 11 | B12: =VLOOKUP(A:A,[2]钻石产出!$B$28:$C$147,2,FALSE) -> 320 | C12: 1000 | D12: , | E12: =C12&D12&B12 -> 1000,320
A13: 12 | B13: =VLOOKUP(A:A,[2]钻石产出!$B$28:$C$147,2,FALSE) -> 320 | C13: 1000 | D13: , | E13: =C13&D13&B13 -> 1000,320
... A121: 120 | B121: =VLOOKUP(A:A,[2]钻石产出!$B$28:$C$147,2,FALSE) -> 590 | C121: 1000 | D121: , | E121: =C121&D121&B121 -> 1000,590

Sheet 金币掉落
A1: 金币关卡 | B1: 关卡金币 | C1: 金币道具ID | D1: 链接符
A2: 1 | B2: =VLOOKUP(A:A,[2]金币产出!$O$37:$R$157,4,FALSE) -> 408960 | C2: 2000 | D2: , | E2: =C2&D2&B2 -> 2000,408960
A3: 2 | B3: =VLOOKUP(A:A,[2]金币产出!$O$37:$R$157,4,FALSE) -> 442800 | C3: 2000 | D3: , | E3: =C3&D3&B3 -> 2000,442800
A4: 3 | B4: =VLOOKUP(A:A,[2]金币产出!$O$37:$R$157,4,FALSE) -> 461520 | C4: 2000 | D4: , | E4: =C4&D4&B4 -> 2000,461520
A5: 4 | B5: =VLOOKUP(A:A,[2]金币产出!$O$37:$R$157,4,FALSE) -> 461520 | C5: 2000 | D5: , | E5: =C5&D5&B5 -> 2000,461520
A6: 5 | B6: =VLOOKUP(A:A,[2]金币产出!$O$37:$R$157,4,FALSE) -> 465120 | C6: 2000 | D6: , | E6: =C6&D6&B6 -> 2000,465120
A7: 6 | B7: =VLOOKUP(A:A,[2]金币产出!$O$37:$R$157,4,FALSE) -> 474120 | C7: 2000 | D7: , | E7: =C7&D7&B7 -> 2000,474120
A8: 7 | B8: =VLOOKUP(A:A,[2]金币产出!$O$37:$R$157,4,FALSE) -> 474120 | C8: 2000 | D8: , | E8: =C8&D8&B8 -> 2000,474120
A9: 8 | B9: =VLOOKUP(A:A,[2]金币产出!$O$37:$R$157,4,FALSE) -> 474120 | C9: 2000 | D9: , | E9: =C9&D9&B9 -> 2000,474120
A10: 9 | B10: =VLOOKUP(A:A,[2]金币产出!$O$37:$R$157,4,FALSE) -> 717840 | C10: 2000 | D10: , | E10: =C10&D10&B10 -> 2000,717840
A11: 10 | B11: =VLOOKUP(A:A,[2]金币产出!$O$37:$R$157,4,FALSE) -> 717840 | C11: 2000 | D11: , | E11: =C11&D11&B11 -> 2000,717840
A12: 11 | B12: =VLOOKUP(A:A,[2]金币产出!$O$37:$R$157,4,FALSE) -> 717840 | C12: 2000 | D12: , | E12: =C12&D12&B12 -> 2000,717840
A13: 12 | B13: =VLOOKUP(A:A,[2]金币产出!$O$37:$R$157,4,FALSE) -> 717840 | C13: 2000 | D13: , | E13: =C13&D13&B13 -> 2000,717840
... A121: 120 | B121: =VLOOKUP(A:A,[2]金币产出!$O$37:$R$157,4,FALSE) -> 8334000 | C121: 2000 | D121: , | E121: =C121&D121&B121 -> 2000,8334000

Sheet 寻宝铲
A1: 铸造锤关卡 | B1: 锤子数量 | C1: 锤子道具ID | D1: 链接符
A2: 1 | B2: =VLOOKUP(A:A,[2]寻宝铲产出!$H$24:$I$144,2,FALSE) -> 8 | C2: 10000001 | D2: , | E2: =C2&D2&B2 -> 10000001,8
A3: 2 | B3: =VLOOKUP(A:A,[2]寻宝铲产出!$H$24:$I$144,2,FALSE) -> 8 | C3: 10000001 | D3: , | E3: =C3&D3&B3 -> 10000001,8
A4: 3 | B4: =VLOOKUP(A:A,[2]寻宝铲产出!$H$24:$I$144,2,FALSE) -> 8 | C4: 10000001 | D4: , | E4: =C4&D4&B4 -> 10000001,8
A5: 4 | B5: =VLOOKUP(A:A,[2]寻宝铲产出!$H$24:$I$144,2,FALSE) -> 8 | C5: 10000001 | D5: , | E5: =C5&D5&B5 -> 10000001,8
A6: 5 | B6: =VLOOKUP(A:A,[2]寻宝铲产出!$H$24:$I$144,2,FALSE) -> 9 | C6: 10000001 | D6: , | E6: =C6&D6&B6 -> 10000001,9
A7: 6 | B7: =VLOOKUP(A:A,[2]寻宝铲产出!$H$24:$I$144,2,FALSE) -> 9 | C7: 10000001 | D7: , | E7: =C7&D7&B7 -> 10000001,9
A8: 7 | B8: =VLOOKUP(A:A,[2]寻宝铲产出!$H$24:$I$144,2,FALSE) -> 9 | C8: 10000001 | D8: , | E8: =C8&D8&B8 -> 10000001,9
A9: 8 | B9: =VLOOKUP(A:A,[2]寻宝铲产出!$H$24:$I$144,2,FALSE) -> 9 | C9: 10000001 | D9: , | E9: =C9&D9&B9 -> 10000001,9
A10: 9 | B10: =VLOOKUP(A:A,[2]寻宝铲产出!$H$24:$I$144,2,FALSE) -> 10 | C10: 10000001 | D10: , | E10: =C10&D10&B10 -> 10000001,10
A11: 10 | B11: =VLOOKUP(A:A,[2]寻宝铲产出!$H$24:$I$144,2,FALSE) -> 10 | C11: 10000001 | D11: , | E11: =C11&D11&B11 -> 10000001,10
A12: 11 | B12: =VLOOKUP(A:A,[2]寻宝铲产出!$H$24:$I$144,2,FALSE) -> 10 | C12: 10000001 | D12: , | E12: =C12&D12&B12 -> 10000001,10
A13: 12 | B13: =VLOOKUP(A:A,[2]寻宝铲产出!$H$24:$I$144,2,FALSE) -> 10 | C13: 10000001 | D13: , | E13: =C13&D13&B13 -> 10000001,10
... A121: 120 | B121: =VLOOKUP(A:A,[2]寻宝铲产出!$H$24:$I$144,2,FALSE) -> 37 | C121: 10000001 | D121: , | E121: =C121&D121&B121 -> 10000001,37

Sheet 英雄经验副本
A1: 奶酪锤关卡 | B1: 奶酪数量 | C1: 奶酪道具ID | E1: 帝王蟹数量 | F1: 帝王蟹ID | H1: 技能强化石数量 | I1: 技能强化石ID | K1: 天赋点数量 | L1: 天赋点ID | P1: 链接符
A2: 1 | B2: =VLOOKUP(A:A,[2]奶酪产出!$G$18:$H$138,2,FALSE) -> 25 | C2: 1010001 | E2: 1 | F2: 1010002 | H2: =VLOOKUP(A:A,[2]技能强化石!$L$14:$M$133,2,2) -> 8 | I2: 1010004 | K2: =VLOOKUP(A:A,[2]天赋点产出!$G$18:$H$138,2,FALSE) -> 4 | L2: 1010014 | O2: | | P2: , | Q2: =C2&P2&B2&O2&F2&P2&E2&O2&I2&P2&H2&O2&L2&P2&K2 -> 1010001,25|1010002,1|1010004,8|1010014,4
A3: 2 | B3: =VLOOKUP(A:A,[2]奶酪产出!$G$18:$H$138,2,FALSE) -> 25 | C3: 1010001 | E3: 1 | F3: 1010002 | H3: =VLOOKUP(A:A,[2]技能强化石!$L$14:$M$133,2,2) -> 8 | I3: 1010004 | K3: =VLOOKUP(A:A,[2]天赋点产出!$G$18:$H$138,2,FALSE) -> 4 | L3: 1010014 | O3: | | P3: , | Q3: =C3&P3&B3&O3&F3&P3&E3&O3&I3&P3&H3&O3&L3&P3&K3 -> 1010001,25|1010002,1|1010004,8|1010014,4
A4: 3 | B4: =VLOOKUP(A:A,[2]奶酪产出!$G$18:$H$138,2,FALSE) -> 25 | C4: 1010001 | E4: 1 | F4: 1010002 | H4: =VLOOKUP(A:A,[2]技能强化石!$L$14:$M$133,2,2) -> 8 | I4: 1010004 | K4: =VLOOKUP(A:A,[2]天赋点产出!$G$18:$H$138,2,FALSE) -> 4 | L4: 1010014 | O4: | | P4: , | Q4: =C4&P4&B4&O4&F4&P4&E4&O4&I4&P4&H4&O4&L4&P4&K4 -> 1010001,25|1010002,1|1010004,8|1010014,4
A5: 4 | B5: =VLOOKUP(A:A,[2]奶酪产出!$G$18:$H$138,2,FALSE) -> 25 | C5: 1010001 | E5: 1 | F5: 1010002 | H5: =VLOOKUP(A:A,[2]技能强化石!$L$14:$M$133,2,2) -> 8 | I5: 1010004 | K5: =VLOOKUP(A:A,[2]天赋点产出!$G$18:$H$138,2,FALSE) -> 4 | L5: 1010014 | O5: | | P5: , | Q5: =C5&P5&B5&O5&F5&P5&E5&O5&I5&P5&H5&O5&L5&P5&K5 -> 1010001,25|1010002,1|1010004,8|1010014,4
A6: 5 | B6: =VLOOKUP(A:A,[2]奶酪产出!$G$18:$H$138,2,FALSE) -> 26 | C6: 1010001 | E6: 1 | F6: 1010002 | H6: =VLOOKUP(A:A,[2]技能强化石!$L$14:$M$133,2,2) -> 9 | I6: 1010004 | K6: =VLOOKUP(A:A,[2]天赋点产出!$G$18:$H$138,2,FALSE) -> 5 | L6: 1010014 | O6: | | P6: , | Q6: =C6&P6&B6&O6&F6&P6&E6&O6&I6&P6&H6&O6&L6&P6&K6 -> 1010001,26|1010002,1|1010004,9|1010014,5
A7: 6 | B7: =VLOOKUP(A:A,[2]奶酪产出!$G$18:$H$138,2,FALSE) -> 26 | C7: 1010001 | E7: 1 | F7: 1010002 | H7: =VLOOKUP(A:A,[2]技能强化石!$L$14:$M$133,2,2) -> 9 | I7: 1010004 | K7: =VLOOKUP(A:A,[2]天赋点产出!$G$18:$H$138,2,FALSE) -> 5 | L7: 1010014 | O7: | | P7: , | Q7: =C7&P7&B7&O7&F7&P7&E7&O7&I7&P7&H7&O7&L7&P7&K7 -> 1010001,26|1010002,1|1010004,9|1010014,5
A8: 7 | B8: =VLOOKUP(A:A,[2]奶酪产出!$G$18:$H$138,2,FALSE) -> 26 | C8: 1010001 | E8: 1 | F8: 1010002 | H8: =VLOOKUP(A:A,[2]技能强化石!$L$14:$M$133,2,2) -> 9 | I8: 1010004 | K8: =VLOOKUP(A:A,[2]天赋点产出!$G$18:$H$138,2,FALSE) -> 5 | L8: 1010014 | O8: | | P8: , | Q8: =C8&P8&B8&O8&F8&P8&E8&O8&I8&P8&H8&O8&L8&P8&K8 -> 1010001,26|1010002,1|1010004,9|1010014,5
A9: 8 | B9: =VLOOKUP(A:A,[2]奶酪产出!$G$18:$H$138,2,FALSE) -> 26 | C9: 1010001 | E9: 1 | F9: 1010002 | H9: =VLOOKUP(A:A,[2]技能强化石!$L$14:$M$133,2,2) -> 9 | I9: 1010004 | K9: =VLOOKUP(A:A,[2]天赋点产出!$G$18:$H$138,2,FALSE) -> 5 | L9: 1010014 | O9: | | P9: , | Q9: =C9&P9&B9&O9&F9&P9&E9&O9&I9&P9&H9&O9&L9&P9&K9 -> 1010001,26|1010002,1|1010004,9|1010014,5
A10: 9 | B10: =VLOOKUP(A:A,[2]奶酪产出!$G$18:$H$138,2,FALSE) -> 27 | C10: 1010001 | E10: 1 | F10: 1010002 | H10: =VLOOKUP(A:A,[2]技能强化石!$L$14:$M$133,2,2) -> 10 | I10: 1010004 | K10: =VLOOKUP(A:A,[2]天赋点产出!$G$18:$H$138,2,FALSE) -> 6 | L10: 1010014 | O10: | | P10: , | Q10: =C10&P10&B10&O10&F10&P10&E10&O10&I10&P10&H10&O10&L10&P10&K10 -> 1010001,27|1010002,1|1010004,10|1010014,6
A11: 10 | B11: =VLOOKUP(A:A,[2]奶酪产出!$G$18:$H$138,2,FALSE) -> 27 | C11: 1010001 | E11: 1 | F11: 1010002 | H11: =VLOOKUP(A:A,[2]技能强化石!$L$14:$M$133,2,2) -> 10 | I11: 1010004 | K11: =VLOOKUP(A:A,[2]天赋点产出!$G$18:$H$138,2,FALSE) -> 6 | L11: 1010014 | O11: | | P11: , | Q11: =C11&P11&B11&O11&F11&P11&E11&O11&I11&P11&H11&O11&L11&P11&K11 -> 1010001,27|1010002,1|1010004,10|1010014,6
A12: 11 | B12: =VLOOKUP(A:A,[2]奶酪产出!$G$18:$H$138,2,FALSE) -> 27 | C12: 1010001 | E12: 1 | F12: 1010002 | H12: =VLOOKUP(A:A,[2]技能强化石!$L$14:$M$133,2,2) -> 10 | I12: 1010004 | K12: =VLOOKUP(A:A,[2]天赋点产出!$G$18:$H$138,2,FALSE) -> 6 | L12: 1010014 | O12: | | P12: , | Q12: =C12&P12&B12&O12&F12&P12&E12&O12&I12&P12&H12&O12&L12&P12&K12 -> 1010001,27|1010002,1|1010004,10|1010014,6
A13: 12 | B13: =VLOOKUP(A:A,[2]奶酪产出!$G$18:$H$138,2,FALSE) -> 27 | C13: 1010001 | E13: 1 | F13: 1010002 | H13: =VLOOKUP(A:A,[2]技能强化石!$L$14:$M$133,2,2) -> 10 | I13: 1010004 | K13: =VLOOKUP(A:A,[2]天赋点产出!$G$18:$H$138,2,FALSE) -> 6 | L13: 1010014 | O13: | | P13: , | Q13: =C13&P13&B13&O13&F13&P13&E13&O13&I13&P13&H13&O13&L13&P13&K13 -> 1010001,27|1010002,1|1010004,10|1010014,6
... A121: 120 | B121: =VLOOKUP(A:A,[2]奶酪产出!$G$18:$H$138,2,FALSE) -> 54 | C121: 1010001 | E121: 1 | F121: 1010002 | H121: =VLOOKUP(A:A,[2]技能强化石!$L$14:$M$133,2,2) -> 37 | I121: 1010004 | K121: =VLOOKUP(A:A,[2]天赋点产出!$G$18:$H$138,2,FALSE) -> 33 | L121: 1010014 | O121: | | P121: , | Q121: =C121&P121&B121&O121&F121&P121&E121&O121&I121&P121&H121&O121&L121&P121&K121 -> 1010001,54|1010002,1|1010004,37|1010014,33

Sheet 神器碎片
A1: 序 | B1: 数量 | C1: 盾牌碎片 | D1: 勋章碎片 | E1: 护符碎片 | F1: 印记碎片 | U1: 1010006 | V1: 盾牌碎片
A2: 1 | B2: =VLOOKUP(A:A,[2]神器碎片!$H$26:$I$145,2,FALSE) -> 5 | C2: 1010006 | D2: 1010007 | E2: 1010008 | F2: 1010009 | H2: , | I2: | | K2: =C2&H2&B2&I2&D2&H2&B2&I2&E2&H2&B2&I2&F2&H2&B2 -> 1010006,5|1010007,5|1010008,5|1010009,5 | U2: 1010007 | V2: 勋章碎片
A3: 2 | B3: =VLOOKUP(A:A,[2]神器碎片!$H$26:$I$145,2,FALSE) -> 5 | C3: 1010006 | D3: 1010007 | E3: 1010008 | F3: 1010009 | H3: , | I3: | | K3: =C3&H3&B3&I3&D3&H3&B3&I3&E3&H3&B3&I3&F3&H3&B3 -> 1010006,5|1010007,5|1010008,5|1010009,5 | U3: 1010008 | V3: 护符碎片
A4: 3 | B4: =VLOOKUP(A:A,[2]神器碎片!$H$26:$I$145,2,FALSE) -> 5 | C4: 1010006 | D4: 1010007 | E4: 1010008 | F4: 1010009 | H4: , | I4: | | K4: =C4&H4&B4&I4&D4&H4&B4&I4&E4&H4&B4&I4&F4&H4&B4 -> 1010006,5|1010007,5|1010008,5|1010009,5 | U4: 1010009 | V4: 印记碎片
A5: 4 | B5: =VLOOKUP(A:A,[2]神器碎片!$H$26:$I$145,2,FALSE) -> 5 | C5: 1010006 | D5: 1010007 | E5: 1010008 | F5: 1010009 | H5: , | I5: | | K5: =C5&H5&B5&I5&D5&H5&B5&I5&E5&H5&B5&I5&F5&H5&B5 -> 1010006,5|1010007,5|1010008,5|1010009,5
A6: 5 | B6: =VLOOKUP(A:A,[2]神器碎片!$H$26:$I$145,2,FALSE) -> 6 | C6: 1010006 | D6: 1010007 | E6: 1010008 | F6: 1010009 | H6: , | I6: | | K6: =C6&H6&B6&I6&D6&H6&B6&I6&E6&H6&B6&I6&F6&H6&B6 -> 1010006,6|1010007,6|1010008,6|1010009,6
A7: 6 | B7: =VLOOKUP(A:A,[2]神器碎片!$H$26:$I$145,2,FALSE) -> 6 | C7: 1010006 | D7: 1010007 | E7: 1010008 | F7: 1010009 | H7: , | I7: | | K7: =C7&H7&B7&I7&D7&H7&B7&I7&E7&H7&B7&I7&F7&H7&B7 -> 1010006,6|1010007,6|1010008,6|1010009,6
A8: 7 | B8: =VLOOKUP(A:A,[2]神器碎片!$H$26:$I$145,2,FALSE) -> 6 | C8: 1010006 | D8: 1010007 | E8: 1010008 | F8: 1010009 | H8: , | I8: | | K8: =C8&H8&B8&I8&D8&H8&B8&I8&E8&H8&B8&I8&F8&H8&B8 -> 1010006,6|1010007,6|1010008,6|1010009,6
A9: 8 | B9: =VLOOKUP(A:A,[2]神器碎片!$H$26:$I$145,2,FALSE) -> 6 | C9: 1010006 | D9: 1010007 | E9: 1010008 | F9: 1010009 | H9: , | I9: | | K9: =C9&H9&B9&I9&D9&H9&B9&I9&E9&H9&B9&I9&F9&H9&B9 -> 1010006,6|1010007,6|1010008,6|1010009,6
A10: 9 | B10: =VLOOKUP(A:A,[2]神器碎片!$H$26:$I$145,2,FALSE) -> 7 | C10: 1010006 | D10: 1010007 | E10: 1010008 | F10: 1010009 | H10: , | I10: | | K10: =C10&H10&B10&I10&D10&H10&B10&I10&E10&H10&B10&I10&F10&H10&B10 -> 1010006,7|1010007,7|1010008,7|1010009,7
A11: 10 | B11: =VLOOKUP(A:A,[2]神器碎片!$H$26:$I$145,2,FALSE) -> 7 | C11: 1010006 | D11: 1010007 | E11: 1010008 | F11: 1010009 | H11: , | I11: | | K11: =C11&H11&B11&I11&D11&H11&B11&I11&E11&H11&B11&I11&F11&H11&B11 -> 1010006,7|1010007,7|1010008,7|1010009,7
A12: 11 | B12: =VLOOKUP(A:A,[2]神器碎片!$H$26:$I$145,2,FALSE) -> 7 | C12: 1010006 | D12: 1010007 | E12: 1010008 | F12: 1010009 | H12: , | I12: | | K12: =C12&H12&B12&I12&D12&H12&B12&I12&E12&H12&B12&I12&F12&H12&B12 -> 1010006,7|1010007,7|1010008,7|1010009,7
A13: 12 | B13: =VLOOKUP(A:A,[2]神器碎片!$H$26:$I$145,2,FALSE) -> 7 | C13: 1010006 | D13: 1010007 | E13: 1010008 | F13: 1010009 | H13: , | I13: | | K13: =C13&H13&B13&I13&D13&H13&B13&I13&E13&H13&B13&I13&F13&H13&B13 -> 1010006,7|1010007,7|1010008,7|1010009,7
A14: 13 | B14: =VLOOKUP(A:A,[2]神器碎片!$H$26:$I$145,2,FALSE) -> 8 | C14: 1010006 | D14: 1010007 | E14: 1010008 | F14: 1010009 | H14: , | I14: | | K14: =C14&H14&B14&I14&D14&H14&B14&I14&E14&H14&B14&I14&F14&H14&B14 -> 1010006,8|1010007,8|1010008,8|1010009,8
A15: 14 | B15: =VLOOKUP(A:A,[2]神器碎片!$H$26:$I$145,2,FALSE) -> 8 | C15: 1010006 | D15: 1010007 | E15: 1010008 | F15: 1010009 | H15: , | I15: | | K15: =C15&H15&B15&I15&D15&H15&B15&I15&E15&H15&B15&I15&F15&H15&B15 -> 1010006,8|1010007,8|1010008,8|1010009,8
A16: 15 | B16: =VLOOKUP(A:A,[2]神器碎片!$H$26:$I$145,2,FALSE) -> 8 | C16: 1010006 | D16: 1010007 | E16: 1010008 | F16: 1010009 | H16: , | I16: | | K16: =C16&H16&B16&I16&D16&H16&B16&I16&E16&H16&B16&I16&F16&H16&B16 -> 1010006,8|1010007,8|1010008,8|1010009,8
... A121: 120 | B121: =VLOOKUP(A:A,[2]神器碎片!$H$26:$I$145,2,FALSE) -> 34 | C121: 1010006 | D121: 1010007 | E121: 1010008 | F121: 1010009 | H121: , | I121: | | K121: =C121&H121&B121&I121&D121&H121&B121&I121&E121&H121&B121&I121&F121&H121&B121 -> 1010006,34|1010007,34|1010008,34|1010009,34

Sheet 圣物碎片
A1: 序 | B1: 数量 | C1: 圣物碎片
A2: 1 | B2: =VLOOKUP(A:A,[2]圣物碎片!$F$22:$G$141,2,FALSE) -> 5 | C2: 1010015 | D2: , | E2: =C2&D2&B2 -> 1010015,5
A3: 2 | B3: =VLOOKUP(A:A,[2]圣物碎片!$F$22:$G$141,2,FALSE) -> 5 | C3: 1010015 | D3: , | E3: =C3&D3&B3 -> 1010015,5
A4: 3 | B4: =VLOOKUP(A:A,[2]圣物碎片!$F$22:$G$141,2,FALSE) -> 5 | C4: 1010015 | D4: , | E4: =C4&D4&B4 -> 1010015,5
A5: 4 | B5: =VLOOKUP(A:A,[2]圣物碎片!$F$22:$G$141,2,FALSE) -> 5 | C5: 1010015 | D5: , | E5: =C5&D5&B5 -> 1010015,5
A6: 5 | B6: =VLOOKUP(A:A,[2]圣物碎片!$F$22:$G$141,2,FALSE) -> 6 | C6: 1010015 | D6: , | E6: =C6&D6&B6 -> 1010015,6
A7: 6 | B7: =VLOOKUP(A:A,[2]圣物碎片!$F$22:$G$141,2,FALSE) -> 6 | C7: 1010015 | D7: , | E7: =C7&D7&B7 -> 1010015,6
A8: 7 | B8: =VLOOKUP(A:A,[2]圣物碎片!$F$22:$G$141,2,FALSE) -> 6 | C8: 1010015 | D8: , | E8: =C8&D8&B8 -> 1010015,6
A9: 8 | B9: =VLOOKUP(A:A,[2]圣物碎片!$F$22:$G$141,2,FALSE) -> 6 | C9: 1010015 | D9: , | E9: =C9&D9&B9 -> 1010015,6
A10: 9 | B10: =VLOOKUP(A:A,[2]圣物碎片!$F$22:$G$141,2,FALSE) -> 7 | C10: 1010015 | D10: , | E10: =C10&D10&B10 -> 1010015,7
A11: 10 | B11: =VLOOKUP(A:A,[2]圣物碎片!$F$22:$G$141,2,FALSE) -> 7 | C11: 1010015 | D11: , | E11: =C11&D11&B11 -> 1010015,7
A12: 11 | B12: =VLOOKUP(A:A,[2]圣物碎片!$F$22:$G$141,2,FALSE) -> 7 | C12: 1010015 | D12: , | E12: =C12&D12&B12 -> 1010015,7
A13: 12 | B13: =VLOOKUP(A:A,[2]圣物碎片!$F$22:$G$141,2,FALSE) -> 7 | C13: 1010015 | D13: , | E13: =C13&D13&B13 -> 1010015,7
... A121: 120 | B121: =VLOOKUP(A:A,[2]圣物碎片!$F$22:$G$141,2,FALSE) -> 34 | C121: 1010015 | D121: , | E121: =C121&D121&B121 -> 1010015,34

Sheet 宠物
A1: 序 | B1: 数量 | C1: 宠物天赋令 | E1: 数量 | F1: 宠物天赋水晶 | R1: 1010010 | S1: 宠物天赋令
A2: 1 | B2: =VLOOKUP(A:A,[2]宠物天赋!$F$27:$G$147,2,FALSE) -> 4 | C2: 1010010 | E2: =VLOOKUP(A:A,[2]宠物天赋!$R$27:$S$147,2,FALSE) -> 8 | F2: 1010011 | H2: , | I2: | | J2: =C2&H2&B2&I2&F2&H2&E2 -> 1010010,4|1010011,8 | R2: 1010011 | S2: 宠物天赋水晶
A3: 2 | B3: =VLOOKUP(A:A,[2]宠物天赋!$F$27:$G$147,2,FALSE) -> 4 | C3: 1010010 | E3: =VLOOKUP(A:A,[2]宠物天赋!$R$27:$S$147,2,FALSE) -> 8 | F3: 1010011 | H3: , | I3: | | J3: =C3&H3&B3&I3&F3&H3&E3 -> 1010010,4|1010011,8 | R3: 1010012 | S3: 宠物打孔石
A4: 3 | B4: =VLOOKUP(A:A,[2]宠物天赋!$F$27:$G$147,2,FALSE) -> 4 | C4: 1010010 | E4: =VLOOKUP(A:A,[2]宠物天赋!$R$27:$S$147,2,FALSE) -> 8 | F4: 1010011 | H4: , | I4: | | J4: =C4&H4&B4&I4&F4&H4&E4 -> 1010010,4|1010011,8
A5: 4 | B5: =VLOOKUP(A:A,[2]宠物天赋!$F$27:$G$147,2,FALSE) -> 4 | C5: 1010010 | E5: =VLOOKUP(A:A,[2]宠物天赋!$R$27:$S$147,2,FALSE) -> 8 | F5: 1010011 | H5: , | I5: | | J5: =C5&H5&B5&I5&F5&H5&E5 -> 1010010,4|1010011,8
A6: 5 | B6: =VLOOKUP(A:A,[2]宠物天赋!$F$27:$G$147,2,FALSE) -> 5 | C6: 1010010 | E6: =VLOOKUP(A:A,[2]宠物天赋!$R$27:$S$147,2,FALSE) -> 9 | F6: 1010011 | H6: , | I6: | | J6: =C6&H6&B6&I6&F6&H6&E6 -> 1010010,5|1010011,9
A7: 6 | B7: =VLOOKUP(A:A,[2]宠物天赋!$F$27:$G$147,2,FALSE) -> 5 | C7: 1010010 | E7: =VLOOKUP(A:A,[2]宠物天赋!$R$27:$S$147,2,FALSE) -> 9 | F7: 1010011 | H7: , | I7: | | J7: =C7&H7&B7&I7&F7&H7&E7 -> 1010010,5|1010011,9
A8: 7 | B8: =VLOOKUP(A:A,[2]宠物天赋!$F$27:$G$147,2,FALSE) -> 5 | C8: 1010010 | E8: =VLOOKUP(A:A,[2]宠物天赋!$R$27:$S$147,2,FALSE) -> 9 | F8: 1010011 | H8: , | I8: | | J8: =C8&H8&B8&I8&F8&H8&E8 -> 1010010,5|1010011,9
A9: 8 | B9: =VLOOKUP(A:A,[2]宠物天赋!$F$27:$G$147,2,FALSE) -> 5 | C9: 1010010 | E9: =VLOOKUP(A:A,[2]宠物天赋!$R$27:$S$147,2,FALSE) -> 9 | F9: 1010011 | H9: , | I9: | | J9: =C9&H9&B9&I9&F9&H9&E9 -> 1010010,5|1010011,9
A10: 9 | B10: =VLOOKUP(A:A,[2]宠物天赋!$F$27:$G$147,2,FALSE) -> 6 | C10: 1010010 | E10: =VLOOKUP(A:A,[2]宠物天赋!$R$27:$S$147,2,FALSE) -> 10 | F10: 1010011 | H10: , | I10: | | J10: =C10&H10&B10&I10&F10&H10&E10 -> 1010010,6|1010011,10
A11: 10 | B11: =VLOOKUP(A:A,[2]宠物天赋!$F$27:$G$147,2,FALSE) -> 6 | C11: 1010010 | E11: =VLOOKUP(A:A,[2]宠物天赋!$R$27:$S$147,2,FALSE) -> 10 | F11: 1010011 | H11: , | I11: | | J11: =C11&H11&B11&I11&F11&H11&E11 -> 1010010,6|1010011,10
A12: 11 | B12: =VLOOKUP(A:A,[2]宠物天赋!$F$27:$G$147,2,FALSE) -> 6 | C12: 1010010 | E12: =VLOOKUP(A:A,[2]宠物天赋!$R$27:$S$147,2,FALSE) -> 10 | F12: 1010011 | H12: , | I12: | | J12: =C12&H12&B12&I12&F12&H12&E12 -> 1010010,6|1010011,10
A13: 12 | B13: =VLOOKUP(A:A,[2]宠物天赋!$F$27:$G$147,2,FALSE) -> 6 | C13: 1010010 | E13: =VLOOKUP(A:A,[2]宠物天赋!$R$27:$S$147,2,FALSE) -> 10 | F13: 1010011 | H13: , | I13: | | J13: =C13&H13&B13&I13&F13&H13&E13 -> 1010010,6|1010011,10
A14: 13 | B14: =VLOOKUP(A:A,[2]宠物天赋!$F$27:$G$147,2,FALSE) -> 7 | C14: 1010010 | E14: =VLOOKUP(A:A,[2]宠物天赋!$R$27:$S$147,2,FALSE) -> 11 | F14: 1010011 | H14: , | I14: | | J14: =C14&H14&B14&I14&F14&H14&E14 -> 1010010,7|1010011,11
A15: 14 | B15: =VLOOKUP(A:A,[2]宠物天赋!$F$27:$G$147,2,FALSE) -> 7 | C15: 1010010 | E15: =VLOOKUP(A:A,[2]宠物天赋!$R$27:$S$147,2,FALSE) -> 11 | F15: 1010011 | H15: , | I15: | | J15: =C15&H15&B15&I15&F15&H15&E15 -> 1010010,7|1010011,11
... A121: 120 | B121: =VLOOKUP(A:A,[2]宠物天赋!$F$27:$G$147,2,FALSE) -> #N/A | C121: 1010010 | E121: =VLOOKUP(A:A,[2]宠物天赋!$R$27:$S$147,2,FALSE) -> #N/A | F121: 1010011 | H121: , | I121: | | J121: =C121&H121&B121&I121&F121&H121&E121 -> #N/A
