Workbook

Sheet Sheet1
A1: Id | B1: Chapter | C1: Type | D1: Gold | E1: Diamond | F1: Reward | G1: Name_notes | H1: Range
A2: int | B2: int | C2: int | D2: String | E2: String | F2: int | G2: String | H2: String
A3: 序ID | B3: 章节ID | C3: 事件类型 | D3: 金币奖励 | E3: 钻石奖励 | F3: 奖励道具 | G3: 事件名称 | H3: 随机区间
A4: 10001 | B4: 1 | C4: 1 | D4: =VLOOKUP(B4:B33,[1]金币产出!$K$38:$L$67,2,FALSE)*3 -> 1563 | E4: 35 | F4: 3001 | G4: 深埋宝藏 | H4: 9500,10000
A5: 10002 | B5: 2 | C5: 1 | D5: =VLOOKUP(B5:B34,[1]金币产出!$K$38:$L$67,2,FALSE)*3 -> 1563 | E5: 35 | F5: 3002 | G5: 深埋宝藏 | H5: 9500,10000
A6: 10003 | B6: 3 | C6: 1 | D6: =VLOOKUP(B6:B35,[1]金币产出!$K$38:$L$67,2,FALSE)*3 -> 2343 | E6: 35 | F6: 3003 | G6: 深埋宝藏 | H6: 9500,10000
A7: 10004 | B7: 4 | C7: 1 | D7: =VLOOKUP(B7:B36,[1]金币产出!$K$38:$L$67,2,FALSE)*3 -> 2343 | E7: 35 | F7: 3004 | G7: 深埋宝藏 | H7: 9500,10000
A8: 10005 | B8: 5 | C8: 1 | D8: =VLOOKUP(B8:B37,[1]金币产出!$K$38:$L$67,2,FALSE)*3 -> 3126 | E8: 35 | F8: 3005 | G8: 深埋宝藏 | H8: 9500,10000
A9: 10006 | B9: 6 | C9: 1 | D9: =VLOOKUP(B9:B38,[1]金币产出!$K$38:$L$67,2,FALSE)*3 -> 3126 | E9: 35 | F9: 3006 | G9: 深埋宝藏 | H9: 9500,10000
A10: 10007 | B10: 7 | C10: 1 | D10: =VLOOKUP(B10:B39,[1]金币产出!$K$38:$L$67,2,FALSE)*3 -> 3906 | E10: 35 | F10: 3007 | G10: 深埋宝藏 | H10: 9500,10000
A11: 10008 | B11: 8 | C11: 1 | D11: =VLOOKUP(B11:B40,[1]金币产出!$K$38:$L$67,2,FALSE)*3 -> 3906 | E11: 35 | F11: 3008 | G11: 深埋宝藏 | H11: 9500,10000
A12: 10009 | B12: 9 | C12: 1 | D12: =VLOOKUP(B12:B41,[1]金币产出!$K$38:$L$67,2,FALSE)*3 -> 4689 | E12: 35 | F12: 3009 | G12: 深埋宝藏 | H12: 9500,10000
A13: 10010 | B13: 10 | C13: 1 | D13: =VLOOKUP(B13:B42,[1]金币产出!$K$38:$L$67,2,FALSE)*3 -> 4689 | E13: 35 | F13: 3010 | G13: 深埋宝藏 | H13: 9500,10000
A14: 10011 | B14: 11 | C14: 1 | D14: =VLOOKUP(B14:B43,[1]金币产出!$K$38:$L$67,2,FALSE)*3 -> 5484 | E14: 35 | F14: 3011 | G14: 深埋宝藏 | H14: 9500,10000
A15: 10012 | B15: 12 | C15: 1 | D15: =VLOOKUP(B15:B44,[1]金币产出!$K$38:$L$67,2,FALSE)*3 -> 5484 | E15: 35 | F15: 3012 | G15: 深埋宝藏 | H15: 9500,10000
... A19: 10016 | B19: 16 | C19: 1 | D19: =VLOOKUP(B19:B48,[1]金币产出!$K$38:$L$67,2,FALSE)*3 -> 6273 | E19: 35 | F19: 3016 | G19: 深埋宝藏 | H19: 9500,10000
A20: 10017 | B20: 17 | C20: 1 | D20: =VLOOKUP(B20:B49,[1]金币产出!$K$38:$L$67,2,FALSE)*3 -> 7059 | E20: 35 | F20: =F19 -> 3016 | G20: 深埋宝藏 | H20: 9500,10000
A21: 10018 | B21: 18 | C21: 1 | D21: =VLOOKUP(B21:B50,[1]金币产出!$K$38:$L$67,2,FALSE)*3 -> 7059 | E21: 35 | F21: =F20 -> 3016 | G21: 深埋宝藏 | H21: 9500,10000
A22: 10019 | B22: 19 | C22: 1 | D22: =VLOOKUP(B22:B51,[1]金币产出!$K$38:$L$67,2,FALSE)*3 -> 7059 | E22: 35 | F22: =F21 -> 3016 | G22: 深埋宝藏 | H22: 9500,10000
A23: 10020 | B23: 20 | C23: 1 | D23: =VLOOKUP(B23:B52,[1]金币产出!$K$38:$L$67,2,FALSE)*3 -> 7857 | E23: 35 | F23: =F22 -> 3016 | G23: 深埋宝藏 | H23: 9500,10000
A24: 10021 | B24: 21 | C24: 1 | D24: =VLOOKUP(B24:B53,[1]金币产出!$K$38:$L$67,2,FALSE)*3 -> 7857 | E24: 35 | F24: =F23 -> 3016 | G24: 深埋宝藏 | H24: 9500,10000
A25: 10022 | B25: 22 | C25: 1 | D25: =VLOOKUP(B25:B54,[1]金币产出!$K$38:$L$67,2,FALSE)*3 -> 7857 | E25: 35 | F25: =F24 -> 3016 | G25: 深埋宝藏 | H25: 9500,10000
A26: 10023 | B26: 23 | C26: 1 | D26: =VLOOKUP(B26:B55,[1]金币产出!$K$38:$L$67,2,FALSE)*3 -> 8667 | E26: 35 | F26: =F25 -> 3016 | G26: 深埋宝藏 | H26: 9500,10000
A27: 10024 | B27: 24 | C27: 1 | D27: =VLOOKUP(B27:B56,[1]金币产出!$K$38:$L$67,2,FALSE)*3 -> 8667 | E27: 35 | F27: =F26 -> 3016 | G27: 深埋宝藏 | H27: 9500,10000
A28: 10025 | B28: 25 | C28: 1 | D28: =VLOOKUP(B28:B57,[1]金币产出!$K$38:$L$67,2,FALSE)*3 -> 8667 | E28: 35 | F28: =F27 -> 3016 | G28: 深埋宝藏 | H28: 9500,10000
A29: 10026 | B29: 26 | C29: 1 | D29: =VLOOKUP(B29:B58,[1]金币产出!$K$38:$L$67,2,FALSE)*3 -> 9456 | E29: 35 | F29: =F28 -> 3016 | G29: 深埋宝藏 | H29: 9500,10000
A30: 10027 | B30: 27 | C30: 1 | D30: =VLOOKUP(B30:B59,[1]金币产出!$K$38:$L$67,2,FALSE)*3 -> 9456 | E30: 35 | F30: =F29 -> 3016 | G30: 深埋宝藏 | H30: 9500,10000
A31: 10028 | B31: 28 | C31: 1 | D31: =VLOOKUP(B31:B60,[1]金币产出!$K$38:$L$67,2,FALSE)*3 -> 9456 | E31: 35 | F31: =F30 -> 3016 | G31: 深埋宝藏 | H31: 9500,10000
... A33: 10030 | B33: 30 | C33: 1 | D33: =VLOOKUP(B33:B62,[1]金币产出!$K$38:$L$67,2,FALSE)*3 -> 10245 | E33: 35 | F33: =F32 -> 3016 | G33: 深埋宝藏 | H33: 9500,10000
A34: 40001 | B34: =B4 -> 1 | C34: =C4+3 -> 4 | D34: =D4 -> 1563 | E34: 55 | F34: 4001 | G34: 搜寻宠物 | H34: 9500,10000
A35: 40002 | B35: =B5 -> 2 | C35: =C5+3 -> 4 | D35: =D5 -> 1563 | E35: 55 | F35: 4002 | G35: 搜寻宠物 | H35: 9500,10000
A36: 40003 | B36: =B6 -> 3 | C36: =C6+3 -> 4 | D36: =D6 -> 2343 | E36: 55 | F36: 4003 | G36: 搜寻宠物 | H36: 9500,10000
A37: 40004 | B37: =B7 -> 4 | C37: =C7+3 -> 4 | D37: =D7 -> 2343 | E37: 55 | F37: 4004 | G37: 搜寻宠物 | H37: 9500,10000
A38: 40005 | B38: =B8 -> 5 | C38: =C8+3 -> 4 | D38: =D8 -> 3126 | E38: 55 | F38: 4005 | G38: 搜寻宠物 | H38: 9500,10000
A39: 40006 | B39: =B9 -> 6 | C39: =C9+3 -> 4 | D39: =D9 -> 3126 | E39: 55 | F39: 4006 | G39: 搜寻宠物 | H39: 9500,10000
A40: 40007 | B40: =B10 -> 7 | C40: =C10+3 -> 4 | D40: =D10 -> 3906 | E40: 55 | F40: 4007 | G40: 搜寻宠物 | H40: 9500,10000
A41: 40008 | B41: =B11 -> 8 | C41: =C11+3 -> 4 | D41: =D11 -> 3906 | E41: 55 | F41: 4008 | G41: 搜寻宠物 | H41: 9500,10000
A42: 40009 | B42: =B12 -> 9 | C42: =C12+3 -> 4 | D42: =D12 -> 4689 | E42: 55 | F42: 4009 | G42: 搜寻宠物 | H42: 9500,10000
A43: 40010 | B43: =B13 -> 10 | C43: =C13+3 -> 4 | D43: =D13 -> 4689 | E43: 55 | F43: 4010 | G43: 搜寻宠物 | H43: 9500,10000
A44: 40011 | B44: =B14 -> 11 | C44: =C14+3 -> 4 | D44: =D14 -> 5484 | E44: 55 | F44: 4011 | G44: 搜寻宠物 | H44: 9500,10000
...

Sheet Sheet2

Sheet Sheet3
