Workbook

Sheet Sheet1
A1: Id | B1: Hero | C1: SkillName_Note | D1: SkillName | E1: SkillLevel | F1: SkillDamage | G1: SkillGem | H1: Gold
A2: Int | B2: Int | C2: string | D2: string | E2: Int | F2: Int | G2: Int | H2: int
A3: 序ID | B3: 角色ID | C3: <c>角色技能名称 | D3: 角色技能名称 | E3: 技能等级 | F3: 技能伤害 | G3: 强化石消耗 | H3: 金币消耗
A4: 1001 | B4: 20001 | C4: 嘟里奥 | D4: Hero_Name_20001 | E4: 1 | F4: 16666.667 | G4: 0 | H4: 0
A5: 1002 | B5: 20001 | C5: 嘟里奥 | D5: Hero_Name_20001 | E5: 2 | F5: 374.66667 | G5: =VLOOKUP(E4:E203,[1]技能强化石!$A$14:$I$212,4,2) -> 2 | H5: =VLOOKUP(E4:E203,[1]技能强化石!$A$14:$I$212,9,2) -> 4000
A6: 1003 | B6: 20001 | C6: 嘟里奥 | D6: Hero_Name_20001 | E6: 3 | F6: 374.66667 | G6: =VLOOKUP(E5:E204,[1]技能强化石!$A$14:$I$212,4,2) -> 2 | H6: =VLOOKUP(E5:E204,[1]技能强化石!$A$14:$I$212,9,2) -> 8000
A7: 1004 | B7: 20001 | C7: 嘟里奥 | D7: Hero_Name_20001 | E7: 4 | F7: 374.66667 | G7: =VLOOKUP(E6:E205,[1]技能强化石!$A$14:$I$212,4,2) -> 2 | H7: =VLOOKUP(E6:E205,[1]技能强化石!$A$14:$I$212,9,2) -> 11000
A8: 1005 | B8: 20001 | C8: 嘟里奥 | D8: Hero_Name_20001 | E8: 5 | F8: 374.66667 | G8: =VLOOKUP(E7:E206,[1]技能强化石!$A$14:$I$212,4,2) -> 2 | H8: =VLOOKUP(E7:E206,[1]技能强化石!$A$14:$I$212,9,2) -> 15000
A9: 1006 | B9: 20001 | C9: 嘟里奥 | D9: Hero_Name_20001 | E9: 6 | F9: 374.66667 | G9: =VLOOKUP(E8:E207,[1]技能强化石!$A$14:$I$212,4,2) -> 2 | H9: =VLOOKUP(E8:E207,[1]技能强化石!$A$14:$I$212,9,2) -> 19000
A10: 1007 | B10: 20001 | C10: 嘟里奥 | D10: Hero_Name_20001 | E10: 7 | F10: 374.66667 | G10: =VLOOKUP(E9:E208,[1]技能强化石!$A$14:$I$212,4,2) -> 2 | H10: =VLOOKUP(E9:E208,[1]技能强化石!$A$14:$I$212,9,2) -> 23000
A11: 1008 | B11: 20001 | C11: 嘟里奥 | D11: Hero_Name_20001 | E11: 8 | F11: 374.66667 | G11: =VLOOKUP(E10:E209,[1]技能强化石!$A$14:$I$212,4,2) -> 2 | H11: =VLOOKUP(E10:E209,[1]技能强化石!$A$14:$I$212,9,2) -> 26000
A12: 1009 | B12: 20001 | C12: 嘟里奥 | D12: Hero_Name_20001 | E12: 9 | F12: 374.66667 | G12: =VLOOKUP(E11:E210,[1]技能强化石!$A$14:$I$212,4,2) -> 2 | H12: =VLOOKUP(E11:E210,[1]技能强化石!$A$14:$I$212,9,2) -> 30000
A13: 1010 | B13: 20001 | C13: 嘟里奥 | D13: Hero_Name_20001 | E13: 10 | F13: 374.66667 | G13: =VLOOKUP(E12:E211,[1]技能强化石!$A$14:$I$212,4,2) -> 2 | H13: =VLOOKUP(E12:E211,[1]技能强化石!$A$14:$I$212,9,2) -> 34000
A14: 1011 | B14: 20001 | C14: 嘟里奥 | D14: Hero_Name_20001 | E14: 11 | F14: 374.66667 | G14: =VLOOKUP(E13:E212,[1]技能强化石!$A$14:$I$212,4,2) -> 2 | H14: =VLOOKUP(E13:E212,[1]技能强化石!$A$14:$I$212,9,2) -> 38000
A15: 1012 | B15: 20001 | C15: 嘟里奥 | D15: Hero_Name_20001 | E15: 12 | F15: 374.66667 | G15: =VLOOKUP(E14:E213,[1]技能强化石!$A$14:$I$212,4,2) -> 2 | H15: =VLOOKUP(E14:E213,[1]技能强化石!$A$14:$I$212,9,2) -> 42000
A16: 1013 | B16: 20001 | C16: 嘟里奥 | D16: Hero_Name_20001 | E16: 13 | F16: 374.66667 | G16: =VLOOKUP(E15:E214,[1]技能强化石!$A$14:$I$212,4,2) -> 2 | H16: =VLOOKUP(E15:E214,[1]技能强化石!$A$14:$I$212,9,2) -> 45000
... A203: 1200 | B203: 20001 | C203: 嘟里奥 | D203: Hero_Name_20001 | E203: 200 | F203: 374.66667 | G203: =VLOOKUP(E202:E401,[1]技能强化石!$A$14:$I$212,4,2) -> 19 | H203: =VLOOKUP(E202:E401,[1]技能强化石!$A$14:$I$212,9,2) -> 751000
A204: 1201 | B204: 20011 | C204: 嘟小龙 | D204: Hero_Name_20011 | E204: 1 | F204: 62500 | G204: =G4 -> 0 | H204: =H4 -> 0
A205: 1202 | B205: 20011 | C205: 嘟小龙 | D205: Hero_Name_20011 | E205: 2 | F205: 1405 | G205: =G5 -> 2 | H205: =H5 -> 4000
A206: 1203 | B206: 20011 | C206: 嘟小龙 | D206: Hero_Name_20011 | E206: 3 | F206: 1405 | G206: =G6 -> 2 | H206: =H6 -> 8000
A207: 1204 | B207: 20011 | C207: 嘟小龙 | D207: Hero_Name_20011 | E207: 4 | F207: 1405 | G207: =G7 -> 2 | H207: =H7 -> 11000
A208: 1205 | B208: 20011 | C208: 嘟小龙 | D208: Hero_Name_20011 | E208: 5 | F208: 1405 | G208: =G8 -> 2 | H208: =H8 -> 15000
A209: 1206 | B209: 20011 | C209: 嘟小龙 | D209: Hero_Name_20011 | E209: 6 | F209: 1405 | G209: =G9 -> 2 | H209: =H9 -> 19000
A210: 1207 | B210: 20011 | C210: 嘟小龙 | D210: Hero_Name_20011 | E210: 7 | F210: 1405 | G210: =G10 -> 2 | H210: =H10 -> 23000
A211: 1208 | B211: 20011 | C211: 嘟小龙 | D211: Hero_Name_20011 | E211: 8 | F211: 1405 | G211: =G11 -> 2 | H211: =H11 -> 26000
A212: 1209 | B212: 20011 | C212: 嘟小龙 | D212: Hero_Name_20011 | E212: 9 | F212: 1405 | G212: =G12 -> 2 | H212: =H12 -> 30000
A213: 1210 | B213: 20011 | C213: 嘟小龙 | D213: Hero_Name_20011 | E213: 10 | F213: 1405 | G213: =G13 -> 2 | H213: =H13 -> 34000
A214: 1211 | B214: 20011 | C214: 嘟小龙 | D214: Hero_Name_20011 | E214: 11 | F214: 1405 | G214: =G14 -> 2 | H214: =H14 -> 38000
A215: 1212 | B215: 20011 | C215: 嘟小龙 | D215: Hero_Name_20011 | E215: 12 | F215: 1405 | G215: =G15 -> 2 | H215: =H15 -> 42000
... A403: 1400 | B403: 20011 | C403: 嘟小龙 | D403: Hero_Name_20011 | E403: 200 | F403: 1405 | G403: =G203 -> 19 | H403: =H203 -> 751000
A404: 1401 | B404: =B204+10 -> 20021 | C404: 哈利王子 | D404: Hero_Name_20021 | E404: 1 | F404: 33333.333 | G404: =G204 -> 0 | H404: =H204 -> 0
A405: 1402 | B405: =B205+10 -> 20021 | C405: 哈利王子 | D405: Hero_Name_20021 | E405: 2 | F405: 749.33333 | G405: =G205 -> 2 | H405: =H205 -> 4000
A406: 1403 | B406: =B206+10 -> 20021 | C406: 哈利王子 | D406: Hero_Name_20021 | E406: 3 | F406: 749.33333 | G406: =G206 -> 2 | H406: =H206 -> 8000
A407: 1404 | B407: =B207+10 -> 20021 | C407: 哈利王子 | D407: Hero_Name_20021 | E407: 4 | F407: 749.33333 | G407: =G207 -> 2 | H407: =H207 -> 11000
A408: 1405 | B408: =B208+10 -> 20021 | C408: 哈利王子 | D408: Hero_Name_20021 | E408: 5 | F408: 749.33333 | G408: =G208 -> 2 | H408: =H208 -> 15000
A409: 1406 | B409: =B209+10 -> 20021 | C409: 哈利王子 | D409: Hero_Name_20021 | E409: 6 | F409: 749.33333 | G409: =G209 -> 2 | H409: =H209 -> 19000
A410: 1407 | B410: =B210+10 -> 20021 | C410: 哈利王子 | D410: Hero_Name_20021 | E410: 7 | F410: 749.33333 | G410: =G210 -> 2 | H410: =H210 -> 23000
A411: 1408 | B411: =B211+10 -> 20021 | C411: 哈利王子 | D411: Hero_Name_20021 | E411: 8 | F411: 749.33333 | G411: =G211 -> 2 | H411: =H211 -> 26000
A412: 1409 | B412: =B212+10 -> 20021 | C412: 哈利王子 | D412: Hero_Name_20021 | E412: 9 | F412: 749.33333 | G412: =G212 -> 2 | H412: =H212 -> 30000
A413: 1410 | B413: =B213+10 -> 20021 | C413: 哈利王子 | D413: Hero_Name_20021 | E413: 10 | F413: 749.33333 | G413: =G213 -> 2 | H413: =H213 -> 34000
...

Sheet Sheet2

Sheet Sheet3
