Workbook

Sheet Sheet1
A1: Id | B1: ObjectType | C1: HeroType | D1: AttributesType | E1: AttributesID | F1: Doc | G1: Doc_Note | H1: SortID | I1: ShowID | J1: Remark_Note
A2: Int | B2: Int | C2: Int | D2: Int | E2: Int | F2: String | G2: String | H2: Int | I2: Int | J2: String
A3: 序ID | B3: 对象类型 | C3: 角色类型 | D3: 属性类型 | E3: 属性ID | F3: 属性面板描述 | G3: <C>属性面板描述 | H3: 排序ID | I3: 展示ID | J3: <c>备注属性名称
A4: 1001001 | B4: 1 | C4: 0 | D4: 1 | E4: =VLOOKUP(J4,Sheet2!A:C,3,FALSE) -> 4 | F4: ="AttrName_00"&E4 -> AttrName_004 | G4: =VLOOKUP(J4,Sheet2!A:C,2,FALSE) -> 生命 | H4: 2 | I4: 1 | J4: 生命值
A5: 1001002 | B5: 1 | C5: 0 | D5: 1 | E5: =VLOOKUP(J5,Sheet2!A:C,3,FALSE) -> 5 | F5: ="AttrName_00"&E5 -> AttrName_005 | G5: =VLOOKUP(J5,Sheet2!A:C,2,FALSE) -> 物御 | H5: 4 | I5: 1 | J5: 物理防御
A6: 1001003 | B6: 1 | C6: 0 | D6: 1 | E6: =VLOOKUP(J6,Sheet2!A:C,3,FALSE) -> 6 | F6: ="AttrName_00"&E6 -> AttrName_006 | G6: =VLOOKUP(J6,Sheet2!A:C,2,FALSE) -> 魔御 | H6: 6 | I6: 1 | J6: 魔法防御
A7: 1001004 | B7: 1 | C7: 0 | D7: 1 | E7: =VLOOKUP(J7,Sheet2!A:C,3,FALSE) -> 7 | F7: ="AttrName_00"&E7 -> AttrName_007 | G7: =VLOOKUP(J7,Sheet2!A:C,2,FALSE) -> 道御 | H7: 8 | I7: 1 | J7: 道术防御
A8: 1001005 | B8: 1 | C8: 0 | D8: 1 | E8: =VLOOKUP(J8,Sheet2!A:C,3,FALSE) -> 29 | F8: ="AttrName_0"&E8 -> AttrName_029 | G8: =VLOOKUP(J8,Sheet2!A:C,2,FALSE) -> 暴击 | H8: 5 | I8: 1 | J8: 暴击
A9: 1001006 | B9: 1 | C9: 0 | D9: 1 | E9: =VLOOKUP(J9,Sheet2!A:C,3,FALSE) -> 30 | F9: ="AttrName_0"&E9 -> AttrName_030 | G9: =VLOOKUP(J9,Sheet2!A:C,2,FALSE) -> 爆伤 | H9: 7 | I9: 1 | J9: 爆伤
A10: 1001007 | B10: 1 | C10: 0 | D10: 1 | E10: =VLOOKUP(J10,Sheet2!A:C,3,FALSE) -> 41 | F10: ="AttrName_0"&E10 -> AttrName_041 | G10: =VLOOKUP(J10,Sheet2!A:C,2,FALSE) -> 攻速 | H10: 3 | I10: 1 | J10: 攻速
A11: 1001008 | B11: 1 | C11: 0 | D11: 2 | E11: =VLOOKUP(J11,Sheet2!A:C,3,FALSE) -> 8 | F11: ="AttrName_00"&E11 -> AttrName_008 | G11: =VLOOKUP(J11,Sheet2!A:C,2,FALSE) -> 回复 | H11: 27 | I11: 1 | J11: 生命恢复
A12: 1001009 | B12: 1 | C12: 0 | D12: 2 | E12: 9 | F12: AttrName_009 | G12: 附加宠物伤害 | H12: 16 | I12: 1 | J12: 附加宠物伤害
A13: 1001010 | B13: 1 | C13: 0 | D13: 2 | E13: =VLOOKUP(J13,Sheet2!A:C,3,FALSE) -> 13 | F13: ="AttrName_0"&E13 -> AttrName_013 | G13: =VLOOKUP(J13,Sheet2!A:C,2,FALSE) -> 生命 | H13: 10 | I13: 1 | J13: 生命加成
A14: 1001011 | B14: 1 | C14: 0 | D14: 2 | E14: =VLOOKUP(J14,Sheet2!A:C,3,FALSE) -> 14 | F14: ="AttrName_0"&E14 -> AttrName_014 | G14: =VLOOKUP(J14,Sheet2!A:C,2,FALSE) -> 物防 | H14: 11 | I14: 2 | J14: 物防加成
A15: 1001012 | B15: 1 | C15: 0 | D15: 2 | E15: =VLOOKUP(J15,Sheet2!A:C,3,FALSE) -> 21 | F15: ="AttrName_0"&E15 -> AttrName_021 | G15: =VLOOKUP(J15,Sheet2!A:C,2,FALSE) -> 宠物伤害加成 | H15: 15 | I15: 1 | J15: 宠物伤害加成
A16: 1001013 | B16: 1 | C16: 0 | D16: 2 | E16: =VLOOKUP(J16,Sheet2!A:C,3,FALSE) -> 15 | F16: ="AttrName_0"&E16 -> AttrName_015 | G16: =VLOOKUP(J16,Sheet2!A:C,2,FALSE) -> 魔防 | H16: 12 | I16: 2 | J16: 魔防加成
A17: 1001014 | B17: 1 | C17: 0 | D17: 2 | E17: =VLOOKUP(J17,Sheet2!A:C,3,FALSE) -> 16 | F17: ="AttrName_0"&E17 -> AttrName_016 | G17: =VLOOKUP(J17,Sheet2!A:C,2,FALSE) -> 道防 | H17: 14 | I17: 2 | J17: 道防加成
A18: 1001015 | B18: 1 | C18: 0 | D18: 2 | E18: =VLOOKUP(J18,Sheet2!A:C,3,FALSE) -> 23 | F18: ="AttrName_0"&E18 -> AttrName_023 | G18: =VLOOKUP(J18,Sheet2!A:C,2,FALSE) -> 伤害倍率 | H18: 33 | I18: 2 | J18: 伤害倍率
A19: 1001016 | B19: 1 | C19: 0 | D19: 2 | E19: =VLOOKUP(J19,Sheet2!A:C,3,FALSE) -> 31 | F19: ="AttrName_0"&E19 -> AttrName_031 | G19: =VLOOKUP(J19,Sheet2!A:C,2,FALSE) -> BOSS伤害加成 | H19: 17 | I19: 2 | J19: BOSS伤害加成
A20: 1001017 | B20: 1 | C20: 0 | D20: 2 | E20: =VLOOKUP(J20,Sheet2!A:C,3,FALSE) -> 25 | F20: ="AttrName_0"&E20 -> AttrName_025 | G20: =VLOOKUP(J20,Sheet2!A:C,2,FALSE) -> 命中 | H20: 20 | I20: 1 | J20: 命中率
A21: 1001018 | B21: 1 | C21: 0 | D21: 2 | E21: =VLOOKUP(J21,Sheet2!A:C,3,FALSE) -> 32 | F21: ="AttrName_0"&E21 -> AttrName_032 | G21: =VLOOKUP(J21,Sheet2!A:C,2,FALSE) -> 小怪伤害加成 | H21: 19 | I21: 2 | J21: 小怪伤害加成
A22: 1001019 | B22: 1 | C22: 0 | D22: 2 | E22: =VLOOKUP(J22,Sheet2!A:C,3,FALSE) -> 28 | F22: ="AttrName_0"&E22 -> AttrName_028 | G22: =VLOOKUP(J22,Sheet2!A:C,2,FALSE) -> 无视防御 | H22: 22 | I22: 2 | J22: 无视防御
A23: 1001020 | B23: 1 | C23: 0 | D23: 2 | E23: =VLOOKUP(J23,Sheet2!A:C,3,FALSE) -> 36 | F23: ="AttrName_0"&E23 -> AttrName_036 | G23: =VLOOKUP(J23,Sheet2!A:C,2,FALSE) -> 技能伤害 | H23: 21 | I23: 2 | J23: 技能伤害
A24: 1001021 | B24: 1 | C24: 0 | D24: 2 | E24: =VLOOKUP(J24,Sheet2!A:C,3,FALSE) -> 33 | F24: ="AttrName_0"&E24 -> AttrName_033 | G24: =VLOOKUP(J24,Sheet2!A:C,2,FALSE) -> 减伤 | H24: 26 | I24: 2 | J24: 减伤
... A38: 1001035 | B38: 1 | C38: 0 | D38: 2 | E38: =VLOOKUP(J38,Sheet2!A:C,3,FALSE) -> 39 | F38: ="AttrName_0"&E38 -> AttrName_039 | G38: =VLOOKUP(J38,Sheet2!A:C,2,FALSE) -> 金币 | H38: 39 | I38: 2 | J38: 金币加成
A39: 1001036 | B39: 1 | C39: 1 | D39: 1 | E39: =VLOOKUP(J39,Sheet2!A:C,3,FALSE) -> 1 | F39: ="AttrName_00"&E39 -> AttrName_001 | G39: =VLOOKUP(J39,Sheet2!A:C,2,FALSE) -> 物理 | H39: 1 | I39: 1 | J39: 物理伤害
A40: 1001037 | B40: 1 | C40: 1 | D40: 2 | E40: =VLOOKUP(J40,Sheet2!A:C,3,FALSE) -> 10 | F40: ="AttrName_0"&E40 -> AttrName_010 | G40: =VLOOKUP(J40,Sheet2!A:C,2,FALSE) -> 物伤 | H40: 9 | I40: 1 | J40: 物伤加成
A41: 1001038 | B41: 1 | C41: 1 | D41: 2 | E41: =VLOOKUP(J41,Sheet2!A:C,3,FALSE) -> 17 | F41: ="AttrName_0"&E41 -> AttrName_017 | G41: =VLOOKUP(J41,Sheet2!A:C,2,FALSE) -> 地系伤害 | H41: 13 | I41: 1 | J41: 地系伤害加成
A42: 1001039 | B42: 1 | C42: 1 | D42: 2 | E42: =VLOOKUP(J42,Sheet2!A:C,3,FALSE) -> 37 | F42: AttrName_203 | G42: 物理次数加成 | H42: 23 | I42: 2 | J42: 技能次数加成
A43: 1001040 | B43: 1 | C43: 1 | D43: 2 | E43: =VLOOKUP(J43,Sheet2!A:C,3,FALSE) -> 38 | F43: AttrName_204 | G43: 物理次数 | H43: 24 | I43: 2 | J43: 技能次数
A44: 1001041 | B44: 1 | C44: 2 | D44: =D4 -> 1 | E44: =VLOOKUP(J44,Sheet2!A:C,3,FALSE) -> 1 | F44: ="AttrName_00"&E44 -> AttrName_001 | G44: =VLOOKUP(J44,Sheet2!A:C,2,FALSE) -> 物理 | H44: 1 | I44: =I4 -> 1 | J44: 物理伤害
A45: 1001042 | B45: 1 | C45: 2 | D45: 2 | E45: =VLOOKUP(J45,Sheet2!A:C,3,FALSE) -> 10 | F45: ="AttrName_0"&E45 -> AttrName_010 | G45: =VLOOKUP(J45,Sheet2!A:C,2,FALSE) -> 物伤 | H45: 9 | I45: 1 | J45: 物伤加成
A46: 1001043 | B46: 1 | C46: 2 | D46: =D40 -> 2 | E46: =VLOOKUP(J46,Sheet2!A:C,3,FALSE) -> 18 | F46: ="AttrName_0"&E46 -> AttrName_018 | G46: =VLOOKUP(J46,Sheet2!A:C,2,FALSE) -> 水系伤害 | H46: 13 | I46: =I40 -> 1 | J46: 水系伤害加成
A47: 1001044 | B47: 1 | C47: 2 | D47: =D26 -> 2 | E47: =VLOOKUP(J47,Sheet2!A:C,3,FALSE) -> 37 | F47: AttrName_203 | G47: 物理次数加成 | H47: 23 | I47: =I26 -> 2 | J47: 技能次数加成
A48: 1001045 | B48: 1 | C48: 2 | D48: =D36 -> 2 | E48: =VLOOKUP(J48,Sheet2!A:C,3,FALSE) -> 38 | F48: AttrName_204 | G48: 物理次数 | H48: 24 | I48: =I36 -> 2 | J48: 技能次数
A49: 1001046 | B49: 1 | C49: 3 | D49: =D8 -> 1 | E49: =VLOOKUP(J49,Sheet2!A:C,3,FALSE) -> 1 | F49: ="AttrName_00"&E49 -> AttrName_001 | G49: =VLOOKUP(J49,Sheet2!A:C,2,FALSE) -> 物理 | H49: 1 | I49: =$I$4 -> 1 | J49: 物理伤害
A50: 1001047 | B50: 1 | C50: 3 | D50: =D16 -> 2 | E50: =VLOOKUP(J50,Sheet2!A:C,3,FALSE) -> 19 | F50: ="AttrName_0"&E50 -> AttrName_019 | G50: =VLOOKUP(J50,Sheet2!A:C,2,FALSE) -> 火系伤害 | H50: 13 | I50: =$I$16 -> 2 | J50: 火系伤害加成
A51: 1001048 | B51: 1 | C51: 3 | D51: 2 | E51: =VLOOKUP(J51,Sheet2!A:C,3,FALSE) -> 10 | F51: ="AttrName_0"&E51 -> AttrName_010 | G51: =VLOOKUP(J51,Sheet2!A:C,2,FALSE) -> 物伤 | H51: 9 | I51: 1 | J51: 物伤加成
A52: 1001049 | B52: 1 | C52: 3 | D52: =D30 -> 2 | E52: =VLOOKUP(J52,Sheet2!A:C,3,FALSE) -> 37 | F52: AttrName_203 | G52: 物理次数加成 | H52: 23 | I52: =$I$27 -> 2 | J52: 技能次数加成
A53: 1001050 | B53: 1 | C53: 3 | D53: =D41 -> 2 | E53: =VLOOKUP(J53,Sheet2!A:C,3,FALSE) -> 38 | F53: AttrName_204 | G53: 物理次数 | H53: 24 | I53: =$I$48 -> 2 | J53: 技能次数
...

Sheet Sheet2
A1: 属性名称 | B1: 面板展示 | C1: 属性ID
A2: 物理伤害 | B2: 物理 | C2: 1
A3: 魔法伤害 | B3: 魔法 | C3: 2
A4: 道术伤害 | B4: 道术 | C4: 3
A5: 生命值 | B5: 生命 | C5: 4
A6: 物理防御 | B6: 物御 | C6: 5
A7: 魔法防御 | B7: 魔御 | C7: 6
A8: 道术防御 | B8: 道御 | C8: 7
A9: 生命恢复 | B9: 回复 | C9: 8
A10: 宠物伤害 | B10: 宠物伤害 | C10: 9
A11: 物伤加成 | B11: 物伤 | C11: 10
A12: 魔伤加成 | B12: 魔伤 | C12: 11
A13: 道伤加成 | B13: 道伤 | C13: 12
... A50: 击杀回复 | B50: 击杀回复 | C50: 49
A51: 主属性攻击 | C51: 101
A52: 主属性防御 | C52: 102

Sheet Sheet3
