Workbook

Sheet Sheet1
A1: Id | B1: HolyId | C1: Name | D1: Notes1 | E1: Type | F1: Lv | G1: Consume1 | H1: Consume2 | I1: Doc | J1: Notes2 | K1: Common | L1: ItemID
A2: Int | B2: Int | C2: String | D2: String | E2: Int | F2: Int | G2: Int | H2: Int | I2: String | J2: String | K2: String | L2: int
A3: 序ID | B3: 圣物ID | C3: 圣物名称 | D3: 名称备注 | E3: 圣物类型 | F3: 圣物等级 | G3: 消耗的圣物碎片 | H3: 消耗的钻石 | I3: 圣物描述 | J3: 描述备注 | K3: 圣物效果参数 | L3: 功能图标
A4: 7101 | B4: 101 | C4: ="Holy_Name_"&L4 -> Holy_Name_1060001 | D4: 克制狂暴圣物 | E4: 1 | F4: 1 | G4: 0 | H4: 0 | I4: ="Holy_Desc_"&L4 -> Holy_Desc_1060001 | J4: 怪物的暴击率与爆伤减少{0} | K4: =[1]圣物数值!$C2*10000 -> 180 | L4: 1060001
A5: 7102 | B5: 101 | C5: ="Holy_Name_"&L5 -> Holy_Name_1060001 | D5: 克制狂暴圣物 | E5: 1 | F5: 2 | G5: 1 | H5: 30 | I5: ="Holy_Desc_"&L5 -> Holy_Desc_1060001 | J5: 怪物的暴击率与爆伤减少{0} | K5: =[1]圣物数值!$C3*10000 -> 360 | L5: 1060001
A6: 7103 | B6: 101 | C6: ="Holy_Name_"&L6 -> Holy_Name_1060001 | D6: 克制狂暴圣物 | E6: 1 | F6: 3 | G6: 2 | H6: 50 | I6: ="Holy_Desc_"&L6 -> Holy_Desc_1060001 | J6: 怪物的暴击率与爆伤减少{0} | K6: =[1]圣物数值!$C4*10000 -> 540 | L6: 1060001
A7: 7104 | B7: 101 | C7: ="Holy_Name_"&L7 -> Holy_Name_1060001 | D7: 克制狂暴圣物 | E7: 1 | F7: 4 | G7: 4 | H7: 80 | I7: ="Holy_Desc_"&L7 -> Holy_Desc_1060001 | J7: 怪物的暴击率与爆伤减少{0} | K7: =[1]圣物数值!$C5*10000 -> 720 | L7: 1060001
A8: 7105 | B8: 101 | C8: ="Holy_Name_"&L8 -> Holy_Name_1060001 | D8: 克制狂暴圣物 | E8: 1 | F8: 5 | G8: 6 | H8: 110 | I8: ="Holy_Desc_"&L8 -> Holy_Desc_1060001 | J8: 怪物的暴击率与爆伤减少{0} | K8: =[1]圣物数值!$C6*10000 -> 900 | L8: 1060001
A9: 7106 | B9: 101 | C9: ="Holy_Name_"&L9 -> Holy_Name_1060001 | D9: 克制狂暴圣物 | E9: 1 | F9: 6 | G9: 7 | H9: 140 | I9: ="Holy_Desc_"&L9 -> Holy_Desc_1060001 | J9: 怪物的暴击率与爆伤减少{0} | K9: =[1]圣物数值!$C7*10000 -> 1080 | L9: 1060001
A10: 7107 | B10: 101 | C10: ="Holy_Name_"&L10 -> Holy_Name_1060001 | D10: 克制狂暴圣物 | E10: 1 | F10: 7 | G10: 9 | H10: 180 | I10: ="Holy_Desc_"&L10 -> Holy_Desc_1060001 | J10: 怪物的暴击率与爆伤减少{0} | K10: =[1]圣物数值!$C8*10000 -> 1260 | L10: 1060001
A11: 7108 | B11: 101 | C11: ="Holy_Name_"&L11 -> Holy_Name_1060001 | D11: 克制狂暴圣物 | E11: 1 | F11: 8 | G11: 10 | H11: 210 | I11: ="Holy_Desc_"&L11 -> Holy_Desc_1060001 | J11: 怪物的暴击率与爆伤减少{0} | K11: =[1]圣物数值!$C9*10000 -> 1440 | L11: 1060001
A12: 7109 | B12: 101 | C12: ="Holy_Name_"&L12 -> Holy_Name_1060001 | D12: 克制狂暴圣物 | E12: 1 | F12: 9 | G12: 12 | H12: 240 | I12: ="Holy_Desc_"&L12 -> Holy_Desc_1060001 | J12: 怪物的暴击率与爆伤减少{0} | K12: =[1]圣物数值!$C10*10000 -> 1620 | L12: 1060001
A13: 7110 | B13: 101 | C13: ="Holy_Name_"&L13 -> Holy_Name_1060001 | D13: 克制狂暴圣物 | E13: 1 | F13: 10 | G13: 14 | H13: 270 | I13: ="Holy_Desc_"&L13 -> Holy_Desc_1060001 | J13: 怪物的暴击率与爆伤减少{0} | K13: =[1]圣物数值!$C11*10000 -> 1800 | L13: 1060001
A14: 7111 | B14: 101 | C14: ="Holy_Name_"&L14 -> Holy_Name_1060001 | D14: 克制狂暴圣物 | E14: 1 | F14: 11 | G14: 15 | H14: 300 | I14: ="Holy_Desc_"&L14 -> Holy_Desc_1060001 | J14: 怪物的暴击率与爆伤减少{0} | K14: =[1]圣物数值!$C12*10000 -> 1980 | L14: 1060001
A15: 7112 | B15: 101 | C15: ="Holy_Name_"&L15 -> Holy_Name_1060001 | D15: 克制狂暴圣物 | E15: 1 | F15: 12 | G15: 17 | H15: 340 | I15: ="Holy_Desc_"&L15 -> Holy_Desc_1060001 | J15: 怪物的暴击率与爆伤减少{0} | K15: =[1]圣物数值!$C13*10000 -> 2160 | L15: 1060001
... A803: 7900 | B803: 116 | C803: ="Holy_Name_"&L803 -> Holy_Name_1060016 | D803: 克制致残圣物 | E803: 3 | F803: 50 | G803: 78 | H803: 1550 | I803: ="Holy_Desc_"&L803 -> Holy_Desc_1060016 | J803: 玩家攻速的降低比例减少{0} | K803: =[1]圣物数值!$C801*10000 -> 9000 | L803: 1060016

Sheet Sheet2
A1: 7101 | B1: ="29,"&Sheet1!K4&"|"&"30,"&Sheet1!K4 -> 29,180|30,180
A2: 7102 | B2: ="29,"&Sheet1!K5&"|"&"30,"&Sheet1!K5 -> 29,360|30,360
A3: 7103 | B3: ="29,"&Sheet1!K6&"|"&"30,"&Sheet1!K6 -> 29,540|30,540
A4: 7104 | B4: ="29,"&Sheet1!K7&"|"&"30,"&Sheet1!K7 -> 29,720|30,720
A5: 7105 | B5: ="29,"&Sheet1!K8&"|"&"30,"&Sheet1!K8 -> 29,900|30,900
A6: 7106 | B6: ="29,"&Sheet1!K9&"|"&"30,"&Sheet1!K9 -> 29,1080|30,1080
A7: 7107 | B7: ="29,"&Sheet1!K10&"|"&"30,"&Sheet1!K10 -> 29,1260|30,1260
A8: 7108 | B8: ="29,"&Sheet1!K11&"|"&"30,"&Sheet1!K11 -> 29,1440|30,1440
A9: 7109 | B9: ="29,"&Sheet1!K12&"|"&"30,"&Sheet1!K12 -> 29,1620|30,1620
A10: 7110 | B10: ="29,"&Sheet1!K13&"|"&"30,"&Sheet1!K13 -> 29,1800|30,1800
A11: 7111 | B11: ="29,"&Sheet1!K14&"|"&"30,"&Sheet1!K14 -> 29,1980|30,1980
A12: 7112 | B12: ="29,"&Sheet1!K15&"|"&"30,"&Sheet1!K15 -> 29,2160|30,2160
... A50: 7150 | B50: ="29,"&Sheet1!K53&"|"&"30,"&Sheet1!K53 -> 29,9000|30,9000
A51: 7151 | B51: ="41,"&Sheet1!K54 -> 41,150
A52: 7152 | B52: ="41,"&Sheet1!K55 -> 41,300
A53: 7153 | B53: ="41,"&Sheet1!K56 -> 41,450
A54: 7154 | B54: ="41,"&Sheet1!K57 -> 41,600
A55: 7155 | B55: ="41,"&Sheet1!K58 -> 41,750
A56: 7156 | B56: ="41,"&Sheet1!K59 -> 41,900
A57: 7157 | B57: ="41,"&Sheet1!K60 -> 41,1050
A58: 7158 | B58: ="41,"&Sheet1!K61 -> 41,1200
A59: 7159 | B59: ="41,"&Sheet1!K62 -> 41,1350
A60: 7160 | B60: ="41,"&Sheet1!K63 -> 41,1500
A61: 7161 | B61: ="41,"&Sheet1!K64 -> 41,1650
A62: 7162 | B62: ="41,"&Sheet1!K65 -> 41,1800
... A100: 7200 | B100: ="41,"&Sheet1!K103 -> 41,7500
A101: 7201 | B101: ="101,"&Sheet1!K104 -> 101,200
A102: 7202 | B102: ="101,"&Sheet1!K105 -> 101,400
A103: 7203 | B103: ="101,"&Sheet1!K106 -> 101,600
A104: 7204 | B104: ="101,"&Sheet1!K107 -> 101,800
A105: 7205 | B105: ="101,"&Sheet1!K108 -> 101,1000
A106: 7206 | B106: ="101,"&Sheet1!K109 -> 101,1200
A107: 7207 | B107: ="101,"&Sheet1!K110 -> 101,1400
A108: 7208 | B108: ="101,"&Sheet1!K111 -> 101,1600
A109: 7209 | B109: ="101,"&Sheet1!K112 -> 101,1800
A110: 7210 | B110: ="101,"&Sheet1!K113 -> 101,2000
A111: 7211 | B111: ="101,"&Sheet1!K114 -> 101,2200
A112: 7212 | B112: ="101,"&Sheet1!K115 -> 101,2400
... A150: 7250 | B150: ="101,"&Sheet1!K153 -> 101,10000
A151: 7251 | B151: ="28,"&Sheet1!K154 -> 28,200
...
