Workbook

Sheet Sheet1
A1: Id | B1: Name_Note | C1: Name | D1: Type | E1: Quality | F1: AttackSkillId | G1: SkillGroupId | H1: Story_Note | I1: Story | J1: IconPath | K1: FullBodyImage | L1: PetModel | M1: Inherit | N1: Floor | O1: Upper | P1: AtkSpeed | Q1: ModelScale | R1: PetQuotesId
A2: Int | B2: String | C2: String | D2: Int | E2: int | F2: Int | G2: Int | H2: String | I2: String | J2: String | K2: String | L2: String | M2: Int | N2: Int | O2: Int | P2: Int | Q2: Int | R2: Arrayint
A3: 唯一宠物id | B3: <c>宠物名字 | C3: 宠物名字 | D3: 宠物type | E3: 品质 | F3: 普通攻击id | G3: 技能组ID | H3: <c>宠物故事 | I3: 宠物故事 | J3: 头像 | K3: 宠物全身形象 | L3: 宠物战场模型 | M3: 继承属性比例 | N3: 成长率下限 | O3: 成长率上限 | P3: 攻速 | Q3: 模型缩放 | R3: 宠物语录ID
A4: 10060 | B4: 幻影猫 | C4: PetBasis_Name_10060 | D4: 3 | E4: 3 | F4: 1006001 | G4: 3 | H4: 幻影猫是诞生于虚空中的神秘存在，它的灵巧与隐秘使得它成为虚空中最难以捉摸的守护者。它常常栖息在幽暗的虚空裂隙中，凭借召唤虚空之眼的能力，将入侵者瞬间引入深不可测的痛苦。 | I4: PetBasis_Story_10060 | J4: 10060 | K4: 10060 | L4: Pet_10060 | M4: ='[1]宠物-升级数值'!$C$4*10000 -> 7000 | N4: ='[1]宠物-升级数值'!$K$4*10000 -> 20000 | O4: ='[1]宠物-升级数值'!$L$4*10000 -> 40000 | P4: 10000 | Q4: 80 | R4: 80|7|88|15|11|65|67|23|13|35|13|63|28|9
A5: 10090 | B5: 冰角鹿 | C5: PetBasis_Name_10090 | D5: 3 | E5: 6 | F5: 1009001 | G5: 3 | H5: 传说冰角鹿曾帮助一位迷路的旅行者找到了回家的路，从此被视为善良和希望的象征。 | I5: PetBasis_Story_10090 | J5: 10090 | K5: 10090 | L5: Pet_10090 | M5: ='[1]宠物-升级数值'!$C$7*10000 -> 30000 | N5: ='[1]宠物-升级数值'!$K$7*10000 -> 35000 | O5: ='[1]宠物-升级数值'!$L$7*10000 -> 80000 | P5: 10000 | Q5: 80 | R5: 9|86|81|24|26|56|99|67|91|64|80|23|73|99
A6: 10100 | B6: 下忍菇 | C6: PetBasis_Name_10100 | D6: 1 | E6: 1 | F6: 1010001 | G6: 1 | H6: 下忍菇刚刚踏上忍者之路，技能是偷偷种蘑菇，结果每次释放毒蘑菇时，敌人只会捏着鼻子逃跑。虽然毒气效果不明显，但下忍菇坚信：“再臭的蘑菇也能赢得胜利！” | I6: PetBasis_Story_10100 | J6: 10100 | K6: 10100 | L6: Pet_10100 | M6: ='[1]宠物-升级数值'!$C$2*10000 -> 3000 | N6: ='[1]宠物-升级数值'!$K$2*10000 -> 10000 | O6: ='[1]宠物-升级数值'!$L$2*10000 -> 20000 | P6: 10000 | Q6: 80 | R6: 94|26|13|75|14|83|18|55|24|57|51|71|47|27
A7: 10101 | B7: 上忍菇 | C7: PetBasis_Name_10101 | D7: 1 | E7: 5 | F7: 1010101 | G7: 1 | H7: 经过多次失败后，下忍菇进化成了上忍菇。现在它组织起“蘑菇派对”，放出大片毒蘑菇覆盖战场。敌人闻着蘑菇味四散逃窜，上忍菇却得意地指挥毒气狂欢。 | I7: PetBasis_Story_10101 | J7: 10101 | K7: 10101 | L7: Pet_10101 | M7: ='[1]宠物-升级数值'!$C$6*10000 -> 20000 | N7: ='[1]宠物-升级数值'!$K$6*10000 -> 30000 | O7: ='[1]宠物-升级数值'!$L$6*10000 -> 60000 | P7: 10000 | Q7: 80 | R7: 59|86|58|66|11|73|70|11|65|84|60|93|10|24
A8: 10110 | B8: 小树卫 | C8: PetBasis_Name_10110 | D8: 2 | E8: 1 | F8: 1011001 | G8: 2 | H8: 小树卫在一场森林大火中失去了亲人和伙伴，为了防止森林起火殃及无辜，从此肩负起守护森林的责任，日夜巡护，确保悲剧不再重演。 | I8: PetBasis_Story_10110 | J8: 10110 | K8: 10110 | L8: Pet_10110 | M8: ='[1]宠物-升级数值'!$C$2*10000 -> 3000 | N8: ='[1]宠物-升级数值'!$K$2*10000 -> 10000 | O8: ='[1]宠物-升级数值'!$L$2*10000 -> 20000 | P8: 10000 | Q8: 80 | R8: 57|29|82|23|73|23|41|14|57|30|46|44|21|65
A9: 10111 | B9: 树桩战士 | C9: PetBasis_Name_10111 | D9: 2 | E9: 5 | F9: 1011101 | G9: 2 | H9: 树桩战士曾是一棵大树，在伐木的暴行中留下斧凿的痕迹，现在，它保留着斧头，用以警醒自己。面对危险时，树桩战士会毫不留情地用其巨大的枝干作为武器击败并赶跑对方。 | I9: PetBasis_Story_10111 | J9: 10111 | K9: 10111 | L9: Pet_10111 | M9: ='[1]宠物-升级数值'!$C$6*10000 -> 20000 | N9: ='[1]宠物-升级数值'!$K$6*10000 -> 30000 | O9: ='[1]宠物-升级数值'!$L$6*10000 -> 60000 | P9: 10000 | Q9: 80 | R9: 57|29|82|23|73|23|41|14|57|30|46|44|21|65
A10: 10120 | B10: 藤蔓球 | C10: PetBasis_Name_10120 | D10: 3 | E10: 2 | F10: 1012001 | G10: 3 | H10: 藤蔓球自称是“分身大师”，每次一遇到敌人，它都会用自己的分身扑向对方。“一个不够？那就来十个！”藤蔓球最喜欢用多重分身发起攻击，让敌人以为自己被团团包围。虽然它的分身不太聪明，但每次都能带来连续不断的“藤蔓咬咬乐”，让敌人彻底晕头转向。 | I10: PetBasis_Story_10120 | J10: 10120 | K10: 10120 | L10: Pet_10120 | M10: ='[1]宠物-升级数值'!$C$3*10000 -> 5000 | N10: ='[1]宠物-升级数值'!$K$3*10000 -> 15000 | O10: ='[1]宠物-升级数值'!$L$3*10000 -> 30000 | P10: 10000 | Q10: 80 | R10: 54|59|84|37|30|45|94|72|55|80|47|14|40|44
A11: 10130 | B11: 小灯蜂 | C11: PetBasis_Name_10130 | D11: 1 | E11: 1 | F11: 1013001 | G11: 1 | H11: 宝宝蜂刚学会飞，发现自己腹部的灯泡特别好玩，一不小心就把敌人亮得晕头转向。每次它用灯泡一闪，敌人就开始抱头大叫：“谁开大灯啦？”宝宝蜂对此很自豪，经常说：“别怪我，我就是这么亮！” | I11: PetBasis_Story_10130 | J11: 10130 | K11: 10130 | L11: Pet_10130 | M11: ='[1]宠物-升级数值'!$C$2*10000 -> 3000 | N11: ='[1]宠物-升级数值'!$K$2*10000 -> 10000 | O11: ='[1]宠物-升级数值'!$L$2*10000 -> 20000 | P11: 10000 | Q11: 80 | R11: 34|6|73|35|32|62|56|75|88|15|39|76|29|49
A12: 10131 | B12: 灵灯蜂 | C12: PetBasis_Name_10131 | D12: 1 | E12: 5 | F12: 1013101 | G12: 1 | H12: 经过进化，宝宝蜂变成了灯泡蜂，灯泡也升级成了“超级高光”。它最喜欢干的事就是在战场上开着“大灯”狂闪，让所有敌人都感觉自己在参加闪光灯派对。灯泡蜂总是笑着说：“灯光师到位，接招吧！” | I12: PetBasis_Story_10131 | J12: 10131 | K12: 10131 | L12: Pet_10131 | M12: ='[1]宠物-升级数值'!$C$6*10000 -> 20000 | N12: ='[1]宠物-升级数值'!$K$6*10000 -> 30000 | O12: ='[1]宠物-升级数值'!$L$6*10000 -> 60000 | P12: 10000 | Q12: 80 | R12: 87|38|29|7|79|34|18|38|68|98|33|100|48|70
A13: 10140 | B13: 炽焰幼虎 | C13: PetBasis_Name_10140 | D13: 2 | E13: 3 | F13: 1014001 | G13: 2 | H13: 炽焰幼虎，出生于炽热的火山口，被火焰和岩浆孕育而生。从幼年起，它的爪子便带有炽热的火焰，随着每一次跳跃和撕裂，空气都会被其利爪灼烧。虽然体型尚小，但它的爆发力却不容小觑。 | I13: PetBasis_Story_10140 | J13: 10140 | K13: 10140 | L13: Pet_10140 | M13: ='[1]宠物-升级数值'!$C$4*10000 -> 7000 | N13: ='[1]宠物-升级数值'!$K$4*10000 -> 20000 | O13: ='[1]宠物-升级数值'!$L$4*10000 -> 40000 | P13: 10000 | Q13: 80 | R13: 34|6|73|35|32|62|56|75|88|15|39|76|29|49
A14: 10160 | B14: 尖叫鸡 | C14: PetBasis_Name_10160 | D14: 4 | E14: 2 | F14: 1016001 | G14: 4 | H14: 尖叫鸡本来是个不起眼的小鸡，直到它发现自己发出的尖叫声能让敌人耳朵怀疑人生。每次战斗，尖叫鸡都会发出那令人胆寒的尖锐音波，敌人听了不是抱头大叫，就是四处乱窜。惨叫鸡得意地说：“我这一嗓子，连我自己都吓！” | I14: PetBasis_Story_10160 | J14: 10160 | K14: 10160 | L14: Pet_10160 | M14: ='[1]宠物-升级数值'!$C$3*10000 -> 5000 | N14: ='[1]宠物-升级数值'!$K$3*10000 -> 15000 | O14: ='[1]宠物-升级数值'!$L$3*10000 -> 30000 | P14: 10000 | Q14: 80 | R14: 67|62|25|34|66|39|63|55|63|22|5|10|33|88
A15: 10161 | B15: 勇士鸡 | C15: PetBasis_Name_10161 | D15: 1 | E15: 4 | F15: 1016101 | G15: 1 | H15: 惨叫鸡进化成了勇士鸡，告别了尖叫，拿起了一把长枪！它现在的绝招是“鸡式闪电突刺”，挥舞着长枪以闪电般的速度冲向敌人 | I15: PetBasis_Story_10161 | J15: 10161 | K15: 10161 | L15: Pet_10161 | M15: ='[1]宠物-升级数值'!$C$5*10000 -> 10000 | N15: ='[1]宠物-升级数值'!$K$5*10000 -> 25000 | O15: ='[1]宠物-升级数值'!$L$5*10000 -> 50000 | P15: 10000 | Q15: 80 | R15: 67|62|25|34|66|39|63|55|63|22|5|10|33|88
A16: 10190 | B16: 奶拳兔 | C16: PetBasis_Name_10190 | D16: 1 | E16: 2 | F16: 1019001 | G16: 1 | H16: 奶拳兔看起来萌萌哒，挥着小拳头时，敌人还以为它在打招呼。可一旦被它冲过来“锤”了一下，敌人才发现这小拳头可不只是好看！每次出手后，奶拳兔还会回头眨巴着眼睛说：“萌只是我的伪装，疼才是我的真相！” | I16: PetBasis_Story_10190 | J16: 10190 | K16: 10190 | L16: Pet_10190 | M16: ='[1]宠物-升级数值'!$C$3*10000 -> 5000 | N16: ='[1]宠物-升级数值'!$K$3*10000 -> 15000 | O16: ='[1]宠物-升级数值'!$L$3*10000 -> 30000 | P16: 10000 | Q16: 80 | R16: 12|75|38|83|48|86|62|55|29|86|21|8|54|35
A17: 10191 | B17: 拳击兔 | C17: PetBasis_Name_10191 | D17: 1 | E17: 6 | F17: 1019101 | G17: 1 | H17: 进化后的拳击兔不再靠“萌”混迹战场，它像一阵狂风般冲向敌人，拳头像雨点一样快速落下。敌人只觉得眼前“咻咻”闪过几下，还没反应过来就已经被打成了一团。拳击兔笑着说：“速度决定一切，我就是风中拳手！” | I17: PetBasis_Story_10191 | J17: 10191 | K17: 10191 | L17: Pet_10191 | M17: ='[1]宠物-升级数值'!$C$7*10000 -> 30000 | N17: ='[1]宠物-升级数值'!$K$7*10000 -> 35000 | O17: ='[1]宠物-升级数值'!$L$7*10000 -> 80000 | P17: 10000 | Q17: 80 | R17: 12|75|38|83|48|86|62|55|29|86|21|8|54|35
A18: 10260 | B18: 幼翠龙 | C18: PetBasis_Name_10260 | D18: 2 | E18: 4 | F18: 1026001 | G18: 2 | H18: 沉眠在古老的龙岭中的幼龙。 | I18: PetBasis_Story_10260 | J18: 10260 | K18: 10260 | L18: Pet_10260 | M18: ='[1]宠物-升级数值'!$C$5*10000 -> 10000 | N18: ='[1]宠物-升级数值'!$K$5*10000 -> 25000 | O18: ='[1]宠物-升级数值'!$L$5*10000 -> 50000 | P18: 10000 | Q18: 80 | R18: 54|59|84|37|30|45|94|72|55|80|47|14|40|44
A19: 10301 | B19: 火药蟹 | C19: PetBasis_Name_10301 | D19: 2 | E19: 7 | F19: 1030101 | G19: 2 | H19: 进化后的火药蟹不再满足于扔小炸弹了，它开始玩起火药桶，还喜欢亲自“飞”到敌人阵地去引爆。每次引爆后，火药蟹都会站在爆炸中心，笑着说：“一桶下去，狂潮四起，谁能挡得住？”敌人每次看到它飞过来都瑟瑟发抖，但火药蟹却乐在其中：“我可是爆炸界的天才！” | I19: PetBasis_Story_10301 | J19: 10301 | K19: 10301 | L19: Pet_10301 | M19: ='[1]宠物-升级数值'!$C$8*10000 -> 50000 | N19: ='[1]宠物-升级数值'!$K$8*10000 -> 40000 | O19: ='[1]宠物-升级数值'!$L$8*10000 -> 100000 | P19: 10000 | Q19: 80 | R19: 33|49|91|82|48|82|26|9|87|34|91|82|64|39
A20: 10330 | B20: 蓬蓬羊 | C20: PetBasis_Name_10330 | D20: 3 | E20: 1 | F20: 1033001 | G20: 3 | H20: 蓬蓬羊平时看起来软萌可爱，但它的羊角隐藏着不可小觑的力量。每次轻轻晃头，就能释放出震荡波，把敌人统统击飞。蓬蓬羊总是轻描淡写地说：“没什么大不了，只是晃了晃头。”它用自己的方式守护着大地，轻松却强大。 | I20: PetBasis_Story_10330 | J20: 10330 | K20: 10330 | L20: Pet_10330 | M20: ='[1]宠物-升级数值'!$C$2*10000 -> 3000 | N20: ='[1]宠物-升级数值'!$K$2*10000 -> 10000 | O20: ='[1]宠物-升级数值'!$L$2*10000 -> 20000 | P20: 10000 | Q20: 80 | R20: 74|83|57|58|26|99|45|70|41|89|33|81|22|65
A21: 10331 | B21: 巨角羊 | C21: PetBasis_Name_10331 | D21: 3 | E21: 5 | F21: 1033101 | G21: 3 | H21: 进化后的巨角羊，力量稳如磐石。它的羊角能发出强力的冲击波，震撼全场。巨角羊性格沉稳，不爱张扬，但每次出手都能引起巨大的冲击，敌人只能在它面前瑟瑟发抖。它总是轻松地说：“只是随便一撞，效果出乎意料。” | I21: PetBasis_Story_10331 | J21: 10331 | K21: 10331 | L21: Pet_10331 | M21: ='[1]宠物-升级数值'!$C$6*10000 -> 20000 | N21: ='[1]宠物-升级数值'!$K$6*10000 -> 30000 | O21: ='[1]宠物-升级数值'!$L$6*10000 -> 60000 | P21: 10000 | Q21: 80 | R21: 74|83|57|58|26|99|45|70|41|89|33|81|22|65
A22: 10350 | B22: 迷眩蝙蝠 | C22: PetBasis_Name_10350 | D22: 4 | E22: 1 | F22: 1035001 | G22: 4 | H22: 迷眩蝙蝠看似不起眼，但它的尖啸声可不是闹着玩的。每次发出震耳欲聋的音波，敌人们都在空气中被震得东倒西歪。虽然它常常不好意思地说：“我只是想吓吓你们，没想到这么响！”可它那穿透空气的音波可是轻松撂倒敌人的绝招。 | I22: PetBasis_Story_10350 | J22: 10350 | K22: 10350 | L22: Pet_10350 | M22: ='[1]宠物-升级数值'!$C$2*10000 -> 3000 | N22: ='[1]宠物-升级数值'!$K$2*10000 -> 10000 | O22: ='[1]宠物-升级数值'!$L$2*10000 -> 20000 | P22: 10000 | Q22: 80 | R22: 28|7|85|46|40|49|14|52|1|71|22|90|66|11
A23: 10351 | B23: 夜影伯爵 | C23: PetBasis_Name_10351 | D23: 4 | E23: 5 | F23: 1035101 | G23: 4 | H23: 进化后的夜影伯爵掌握了更强的音波之力，它的尖叫声不再只是吓人，而是如刀锋般精准切割敌人。伯爵总是优雅地发出致命的音波，然后自信满满地说：“声音，也是一种艺术，你们承受得住吗？” | I23: PetBasis_Story_10351 | J23: 10351 | K23: 10351 | L23: Pet_10351 | M23: ='[1]宠物-升级数值'!$C$6*10000 -> 20000 | N23: ='[1]宠物-升级数值'!$K$6*10000 -> 30000 | O23: ='[1]宠物-升级数值'!$L$6*10000 -> 60000 | P23: 10000 | Q23: 80 | R23: 49|69|41|5|32|4|31|45|41|35|81|1|32|3
A24: 10410 | B24: 灯灵章鱼 | C24: PetBasis_Name_10410 | D24: 2 | E24: 2 | F24: 1041001 | G24: 2 | H24: 灯灵章鱼擅长在黑暗中释放出锐利的光波，光芒像利刃一样切割空气，冲击周围的敌人。它总是笑着说：“光明就是最好的武器！”在这耀眼的光芒下，敌人无处可逃。灯灵章鱼得意地补充：“在我的光芒下，黑暗无处藏身。” | I24: PetBasis_Story_10410 | J24: 10410 | K24: 10410 | L24: Pet_10410 | M24: ='[1]宠物-升级数值'!$C$3*10000 -> 5000 | N24: ='[1]宠物-升级数值'!$K$3*10000 -> 15000 | O24: ='[1]宠物-升级数值'!$L$3*10000 -> 30000 | P24: 10000 | Q24: 80 | R24: 3|39|46|90|61|56|27|35|48|87|49|27|97|88
A25: 10411 | B25: 潜灵章鱼 | C25: PetBasis_Name_10411 | D25: 2 | E25: 6 | F25: 1041101 | G25: 2 | H25: 进化后的潜灵章鱼，其光波力量已经无比强大，光芒刺眼得让敌人寸步难行。每当潜灵章鱼出现在战场，强光如探照灯般扫过一切，让敌人无处躲藏。它悠然自得地说：“别费力躲了，我的光会照亮每个角落。” | I25: PetBasis_Story_10411 | J25: 10411 | K25: 10411 | L25: Pet_10411 | M25: ='[1]宠物-升级数值'!$C$7*10000 -> 30000 | N25: ='[1]宠物-升级数值'!$K$7*10000 -> 35000 | O25: ='[1]宠物-升级数值'!$L$7*10000 -> 80000 | P25: 10000 | Q25: 80 | R25: 49|69|41|5|32|4|31|45|41|35|81|1|32|3
A26: 10450 | B26: 弹弓翼龙 | C26: PetBasis_Name_10450 | D26: 1 | E26: 4 | F26: 1045001 | G26: 1 | H26: 弹弓翼龙自认为是世界上最厉害的“弹弓选手”，每次都用弹弓把自己弹射出去，砸向敌人。敌人还没反应过来，就已经被砸飞了。弹弓翼龙总是得意地说：“谁说翼龙不会玩弹弓？看我这招‘龙飞弹’！” | I26: PetBasis_Story_10450 | J26: 10450 | K26: 10450 | L26: Pet_10450 | M26: ='[1]宠物-升级数值'!$C$5*10000 -> 10000 | N26: ='[1]宠物-升级数值'!$K$5*10000 -> 25000 | O26: ='[1]宠物-升级数值'!$L$5*10000 -> 50000 | P26: 10000 | Q26: 80 | R26: 65|24|52|31|16|14|13|30|18|51|14|5|51|35
A27: 10451 | B27: 火炮翼龙 | C27: PetBasis_Name_10451 | D27: 1 | E27: 7 | F27: 1045101 | G27: 1 | H27: 进化后的火炮翼龙直接升级，变成了天空中的火力支援队。它喜欢用炽热的炮弹轰击敌人，炮弹撕裂空气，爆炸声震耳欲聋。每次发射完，它都会笑着说：“这火炮，够热乎吧？下次再给你们来个双倍爆炸套餐！” | I27: PetBasis_Story_10451 | J27: 10451 | K27: 10451 | L27: Pet_10451 | M27: ='[1]宠物-升级数值'!$C$8*10000 -> 50000 | N27: ='[1]宠物-升级数值'!$K$8*10000 -> 40000 | O27: ='[1]宠物-升级数值'!$L$8*10000 -> 100000 | P27: 10000 | Q27: 70 | R27: 65|24|52|31|16|14|13|30|18|51|14|5|51|35
A28: 10470 | B28: 音波鳄 | C28: PetBasis_Name_10470 | D28: 4 | E28: 3 | F28: 1047001 | G28: 4 | H28: 音波鳄的秘密武器居然是一只麦克风！它用麦克风发出震撼的声波，每次大吼一声，音波就像利刃一样穿透敌人的防线。它挥舞着麦克风，一边说：“麦克风在手，谁敢不听我的声音？”每次敌人都被打得晕头转向，狼狈不堪 | I28: PetBasis_Story_10470 | J28: 10470 | K28: 10470 | L28: Pet_10470 | M28: ='[1]宠物-升级数值'!$C$4*10000 -> 7000 | N28: ='[1]宠物-升级数值'!$K$4*10000 -> 20000 | O28: ='[1]宠物-升级数值'!$L$4*10000 -> 40000 | P28: 10000 | Q28: 80 | R28: 12|75|38|83|48|86|62|55|29|86|21|8|54|35
A29: 10471 | B29: 音响鳄 | C29: PetBasis_Name_10471 | D29: 4 | E29: 6 | F29: 1047101 | G29: 4 | H29: 进化后的音响鳄成了真正的摇滚明星，它的麦克风不仅能放大声音，还能制造音波回响，让敌人们陷入混乱。每当音响鳄高举麦克风，发出巨大的音波攻击，它都会自豪地说：“准备好迎接我这‘震天动地’的表演吧！”然后敌人被震得七晕八素，它还补上一句：“音乐可以治愈，也可以摧毁！” | I29: PetBasis_Story_10471 | J29: 10471 | K29: 10471 | L29: Pet_10471 | M29: ='[1]宠物-升级数值'!$C$7*10000 -> 30000 | N29: ='[1]宠物-升级数值'!$K$7*10000 -> 35000 | O29: ='[1]宠物-升级数值'!$L$7*10000 -> 80000 | P29: 10000 | Q29: 70 | R29: 12|75|38|83|48|86|62|55|29|86|21|8|54|35
A30: 10500 | B30: 火灵猪 | C30: PetBasis_Name_10500 | D30: 1 | E30: 2 | F30: 1050001 | G30: 1 | H30: 火灵猪最骄傲的就是它那燃烧的尾巴，每次甩一甩，炽热的火焰就能瞬间点燃周围的敌人。它总是自豪地说：“我的尾巴不只是装饰，还是个小火把！”每当看到敌人被烧得跳脚，它就会开心地笑：“嘿嘿，烧烤时间到了！” | I30: PetBasis_Story_10500 | J30: 10500 | K30: 10500 | L30: Pet_10500 | M30: ='[1]宠物-升级数值'!$C$3*10000 -> 5000 | N30: ='[1]宠物-升级数值'!$K$3*10000 -> 15000 | O30: ='[1]宠物-升级数值'!$L$3*10000 -> 30000 | P30: 10000 | Q30: 80 | R30: 67|6|15|92|84|62|10|21|2|23|90|53|39|34
A31: 10520 | B31: 木宝蜥 | C31: PetBasis_Name_10520 | D31: 1 | E31: 3 | F31: 1052001 | G31: 1 | H31: 木宝蜥总是拿着一根小木棍，看起来像是准备去玩耍，但它的突进速度和挥棍力度却让敌人毫无防备。每次它冲向敌人，木棍挥舞得如风般迅猛，打得敌人晕头转向。别看是根普通木棍，但在木宝蜥手里，竟成了威力巨大的武器。 | I31: PetBasis_Story_10520 | J31: 10520 | K31: 10520 | L31: Pet_10520 | M31: ='[1]宠物-升级数值'!$C$4*10000 -> 7000 | N31: ='[1]宠物-升级数值'!$K$4*10000 -> 20000 | O31: ='[1]宠物-升级数值'!$L$4*10000 -> 40000 | P31: 10000 | Q31: 80 | R31: 12|75|38|83|48|86|62|55|29|86|21|8|54|35
A32: 10521 | B32: 戟手蜥 | C32: PetBasis_Name_10521 | D32: 1 | E32: 7 | F32: 1052101 | G32: 1 | H32: 进化后的戟手蜥，手中的大戟锋利无比，每次刺出时，戟刃都划破空气，带着致命的力量。它的攻击总是迅捷而精准，一戟刺出，敌人便被重创倒地。戟手蜥在战场上行如闪电，凭借它的戟刃，没人敢小看它的速度和力量。 | I32: PetBasis_Story_10521 | J32: 10521 | K32: 10521 | L32: Pet_10521 | M32: ='[1]宠物-升级数值'!$C$8*10000 -> 50000 | N32: ='[1]宠物-升级数值'!$K$8*10000 -> 40000 | O32: ='[1]宠物-升级数值'!$L$8*10000 -> 100000 | P32: 10000 | Q32: 70 | R32: 75|46|15|67|64|86|12|70|24|43|1|10|66|7
A33: 10530 | B33: 小财龙 | C33: PetBasis_Name_10530 | D33: 3 | E33: 4 | F33: 1053001 | G33: 3 | H33: 小财龙爱收藏各种宝物，但当它发起进攻时，这些珍宝就变成了它的武器。每次遇到敌人，它毫不犹豫地把自己的宝贝当作弹药，猛然丢出，精准砸向敌人。谁能想到，这只小龙竟然舍得把心爱的宝物拿来当武器？不过，别担心，它砸完总会再去捡回来的！ | I33: PetBasis_Story_10530 | J33: 10530 | K33: 10530 | L33: Pet_10530 | M33: ='[1]宠物-升级数值'!$C$5*10000 -> 10000 | N33: ='[1]宠物-升级数值'!$K$5*10000 -> 25000 | O33: ='[1]宠物-升级数值'!$L$5*10000 -> 50000 | P33: 10000 | Q33: 80 | R33: 12|75|38|83|48|86|62|55|29|86|21|8|54|35
A34: 10531 | B34: 财宝龙 | C34: PetBasis_Name_10531 | D34: 3 | E34: 7 | F34: 1053101 | G34: 3 | H34: 财宝龙对敌人毫不手软，尤其当它愤怒时，会直接甩出大量珍藏宝物。珠宝、金块、宝石纷飞，形成了一场令人眼花缭乱的“宝物风暴”，敌人被这些无情的珍宝打得东倒西歪。财宝龙不在乎损失，因为它知道，打完仗，它的宝藏只会更多。 | I34: PetBasis_Story_10531 | J34: 10531 | K34: 10531 | L34: Pet_10531 | M34: ='[1]宠物-升级数值'!$C$8*10000 -> 50000 | N34: ='[1]宠物-升级数值'!$K$8*10000 -> 40000 | O34: ='[1]宠物-升级数值'!$L$8*10000 -> 100000 | P34: 10000 | Q34: 70 | R34: 75|46|15|67|64|86|12|70|24|43|1|10|66|7
A35: 10560 | B35: 导弹鲨 | C35: PetBasis_Name_10560 | D35: 1 | E35: 3 | F35: 1056001 | G35: 1 | H35: 导弹鲨绝不是一条普通的鲨鱼，它能化身为导弹，瞬间冲入敌阵，引发剧烈的爆炸。看着一条鲨鱼在天上飞，然后“嘭”的一声，敌人被炸得四散而逃。 | I35: PetBasis_Story_10560 | J35: 10560 | K35: 10560 | L35: Pet_10560 | M35: ='[1]宠物-升级数值'!$C$4*10000 -> 7000 | N35: ='[1]宠物-升级数值'!$K$4*10000 -> 20000 | O35: ='[1]宠物-升级数值'!$L$4*10000 -> 40000 | P35: 10000 | Q35: 80 | R35: 67|84|28|94|70|56|76|81|41|4|48|39|50|95
A36: 10561 | B36: 鱼雷鲨 | C36: PetBasis_Name_10561 | D36: 1 | E36: 6 | F36: 1056101 | G36: 1 | H36: 鱼雷鲨，速度和力量更胜一筹。它化身为鱼雷，带着摧枯拉朽的威力从水中穿梭，横扫敌阵。鱼雷鲨每次进攻都像是一场无情的“水下风暴”，敌人根本无处可躲。 | I36: PetBasis_Story_10561 | J36: 10561 | K36: 10561 | L36: Pet_10561 | M36: ='[1]宠物-升级数值'!$C$7*10000 -> 30000 | N36: ='[1]宠物-升级数值'!$K$7*10000 -> 35000 | O36: ='[1]宠物-升级数值'!$L$7*10000 -> 80000 | P36: 10000 | Q36: 80 | R36: 57|29|82|23|73|23|41|14|57|30|46|44|21|65
A37: 10580 | B37: 蜜汁蜗牛 | C37: PetBasis_Name_10580 | D37: 4 | E37: 4 | F37: 1058001 | G37: 4 | H37: 蜜汁蜗牛虽然行动缓慢，但它的攻击方式可是让敌人头疼。它召唤出蜜汁蜂箱，瞬间蜂群四散而出，敌人们还没反应过来，就被密密麻麻的小蜂团团围住。别小看这只慢吞吞的蜗牛，它的蜂群可是“致命蜂暴”！ | I37: PetBasis_Story_10580 | J37: 10580 | K37: 10580 | L37: Pet_10580 | M37: ='[1]宠物-升级数值'!$C$5*10000 -> 10000 | N37: ='[1]宠物-升级数值'!$K$5*10000 -> 25000 | O37: ='[1]宠物-升级数值'!$L$5*10000 -> 50000 | P37: 10000 | Q37: 80 | R37: 12|75|38|83|48|86|62|55|29|86|21|8|54|35
A38: 10581 | B38: 堡垒蜗牛 | C38: PetBasis_Name_10581 | D38: 4 | E38: 7 | F38: 1058101 | G38: 4 | H38: 进化后的堡垒蜗牛，不仅壳子更坚固，它的蜜汁蜂箱也更加强大。大量的蜂群如同黑云般涌出，疯狂袭击敌人。无论敌人跑得多快，蜂群总能紧紧跟上，形成一场令人无从躲避的蜂群狂潮，堡垒蜗牛静静地“观战”，显得有些悠闲。 | I38: PetBasis_Story_10581 | J38: 10581 | K38: 10581 | L38: Pet_10581 | M38: ='[1]宠物-升级数值'!$C$8*10000 -> 50000 | N38: ='[1]宠物-升级数值'!$K$8*10000 -> 40000 | O38: ='[1]宠物-升级数值'!$L$8*10000 -> 100000 | P38: 10000 | Q38: 70 | R38: 12|75|38|83|48|86|62|55|29|86|21|8|54|35

Sheet Sheet3
A1: 唯一宠物id | B1: 技能ID | C1: 宠物名字 | E1: 技能名称 | F1: 技能描述（简述） | G1: 技能描述(详细) | H1: 故事
A2: 10010 | C2: 波波龟
A3: 10011 | C3: 海之波波
A4: 10012 | C4: 海翼龟
A5: 10020 | C5: 小火狐
A6: 10021 | C6: 炎之火狐
A7: 10022 | C7: 炎尾狐
A8: 10030 | C8: 钢甲鼬
A9: 10031 | C9: 钢铠鼬
A10: 10032 | C10: 钢铠王
A11: 10040 | C11: 沙漠蜥
A12: 10041 | C12: 沙漠巨蜥
A13: 10042 | C13: 沙漠龙王
... A16: 10052 | C16: 茂叶蛾
A17: 10060 | B17: 1006002 | C17: 幻影猫 | E17: 虚空波动 | F17: 幻影猫召唤虚空之眼，对周围敌人造成伤害 | G17: 幻影猫召唤虚空之眼，炽烈的能量波动席卷四周，令敌人瞬间陷入痛苦。 | H17: 幻影猫是诞生于虚空中的神秘存在，它的灵巧与隐秘使得它成为虚空中最难以捉摸的守护者。它常常栖息在幽暗的虚空裂隙中，凭借召唤虚空之眼的能力，将入侵者瞬间引入深不可测的痛苦。
A18: 10061 | B18: 1006002 | C18: 梦影猫 | E18: 虚空爆发 | F18: 梦影猫召唤强力虚空之眼，对周围敌人造成大量伤害 | G18: 梦影猫召唤出强力的虚空之眼，其无尽的力量爆发，重创所有周围的敌人。 | H18: 梦影猫，是虚空中力量更为强大的存在，作为幻影猫的进化形态，它能够掌控更强大的虚空力量。梦影猫生活在虚空的深层，远离凡世，但它的力量无时无刻不在影响着世界的秩序。
A19: 10062 | B19: 1006002 | C19: 虚梦猫 | E19: 虚空湮灭 | F19: 虚梦猫召唤最强的虚空之眼，对周围敌人造成巨量伤害 | G19: 虚梦猫召唤最强虚空之眼，天崩地裂般的巨量能量冲击席卷一切，令敌人无处遁形。 | H19: 作为虚空的终极守护者，虚梦猫的力量已达巅峰。它象征着虚空中的最强能量，连虚空本身都在它的控制之下。传说中，虚梦猫可以召唤出最强的虚空之眼，爆发出天崩地裂般的巨量能量冲击，席卷一切。
A20: 10070 | B20: 1007002 | C20: 行路草 | E20: 寄生种子 | F20: 行路草召唤草元素，向前方播下寄生种子，对周围敌人造成伤害 | G20: 行路草在大地上播下寄生种子，种子飞速生长，侵蚀周围的敌人并给予伤害。 | H20: 在广袤的森林深处，行路草是一种古老而神秘的植物生物。它的身体看似柔弱，却蕴藏着大自然的无穷力量。行路草喜欢安静地游走于大地之上，时而停下脚步，将寄生种子播撒在大地中。
A21: 10071 | B21: 1007002 | C21: 行路兽 | E21: 猛长寄生 | F21: 行路兽召唤草元素，向前方播下强力寄生种子，对周围敌人造成大量伤害 | G21: 行路兽引导草元素的强大力量，向前方释放强力寄生种子，种子疯狂生长，深深扎入敌人体内，造成大量的伤害。 | H21: 随着时间的推移，行路草进化为更强大的形态——行路兽。这一形态的行路兽拥有更为厚重的躯体和更强的力量，它对大地的掌控也更加深入。行路兽的行动更加沉稳，每一次踏足地面都仿佛唤醒了沉睡的草木与泥土。
A22: 10072
A23: 10090 | B23: 1009002 | C23: 冰角鹿 | E23: 冰角突刺 | F23: 冰角鹿利用自己的冰角召唤冰锥攻击前方区域，对前方多个目标造成冰冻伤害并持续效果。 | G23: 冰角鹿利用自己的冰角召唤冰锥攻击前方区域，对前方多个目标造成冰冻伤害并持续效果。 | H23: 传说冰角鹿曾帮助一位迷路的旅行者找到了回家的路，从此被视为善良和希望的象征。
A24: 10091 | B24: 1009002 | C24: 霜角鹿 | E24: 极寒冰锥 | F24: 霜角鹿利用冰冷的冰角召唤冰锥，向前方区域发射冰锥攻击 | G24: 霜角鹿利用冰冷的冰角召唤冰锥，向前方区域发射冰锥攻击，对前方多个目标造成冰冻伤害并持续效果。 | H24: 霜角鹿虽然外表威武，但内心却十分呆萌。有传说它们曾因为贪玩，误把自己埋在雪堆里，直到第二天才被找到。
A25: 10092
A26: 10100 | B26: 1010002 | C26: 下忍菇 | E26: 毒菇瘴气 | F26: 下忍菇释放多个毒蘑菇制造一定范围的毒气，对周围的敌人造成毒气伤害 | G26: 下忍菇释放出一连串毒蘑菇，在一定范围内制造毒气，对周围敌人造成毒气伤害 | H26: 下忍菇刚刚踏上忍者之路，技能是偷偷种蘑菇，结果每次释放毒蘑菇时，敌人只会捏着鼻子逃跑。虽然毒气效果不明显，但下忍菇坚信：“再臭的蘑菇也能赢得胜利！”
A27: 10101 | B27: 1010002 | C27: 上忍菇 | E27: 毒菇风暴 | F27: 上忍菇释放多个毒蘑菇制造大范围的毒气，对周围的敌人造成较大的毒气伤害。 | G27: 上忍菇释放大量毒蘑菇，扩散出大范围毒气，对周围敌人造成更强的毒气伤害 | H27: 经过多次失败后，下忍菇进化成了上忍菇。现在它组织起“蘑菇派对”，放出大片毒蘑菇覆盖战场。敌人闻着蘑菇味四散逃窜，上忍菇却得意地指挥毒气狂欢。
A28: 10102 | B28: 1010202 | C28: 影忍菇 | E28: 菇影连环斩 | F28: 影忍菇使用奥义，向前突击，对周围的敌人造成大范围的斩击。 | G28: 影忍菇施展奥义，向前快速突击，伴随凌厉的斩击，对大范围内的敌人造成致命伤害 | H28: 上忍菇最终进化成了影忍菇，已抛弃毒蘑菇，靠奥义“神速斩击”解决问题。它以极快速度冲刺，敌人还没反应过来，就已经被它无声无息地“斩成蘑菇片”了。
A29: 10110 | B29: 1011002 | C29: 小树卫 | E29: 树灵召唤 | F29: 小树卫使用元素之力召唤树灵，对前方敌人造成伤害 | G29: 小树卫唤醒元素之力，召唤树灵猛然现身，强大的树灵对前方敌人造成毁灭性打击。 | H29: 小树卫在一场森林大火中失去了亲人和伙伴，为了防止森林起火殃及无辜，从此肩负起守护森林的责任，日夜巡护，确保悲剧不再重演。
A30: 10111 | B30: 1011002 | C30: 树桩战士 | E30: 巨树灵降临 | F30: 树桩战士使用元素之力召唤更强大的树灵，对前方敌人造成大量伤害 | G30: 树桩战士召唤出更强大的树灵，巨树灵爆发的力量如风暴般席卷前方的敌人，造成大量伤害。 | H30: 树桩战士曾是一棵大树，在伐木的暴行中留下斧凿的痕迹，现在，它保留着斧头，用以警醒自己。面对危险时，树桩战士会毫不留情地用其巨大的枝干作为武器击败并赶跑对方。
A31: 10112
A32: 10120 | B32: 1012002 | C32: 藤蔓球 | E32: 噬影分身 | F32: 藤蔓球释放多个分身，向目标发动连续吞噬攻击，每个分身都会造成伤害，使目标承受多重伤害。 | G32: 藤蔓球释放多个分身，向目标发动连续吞噬攻击，每个分身都会造成伤害，使目标承受多重伤害。 | H32: 藤蔓球自称是“分身大师”，每次一遇到敌人，它都会用自己的分身扑向对方。“一个不够？那就来十个！”藤蔓球最喜欢用多重分身发起攻击，让敌人以为自己被团团包围。虽然它的分身不太聪明，但每次都能带来连续不断的“藤蔓咬咬乐”，让敌人彻底晕头转向。
A33: 10121 | B33: 1012002 | C33: 尖牙蔓 | E33: 蔓影啃噬 | F33: 尖牙蔓释放多个蔓草分身，对敌人进行持续的啃噬攻击，每个分身都会造成大量伤害，使目标受到多重伤害的打击。 | G33: 尖牙蔓释放多个蔓草分身，对敌人进行持续的啃噬攻击，每个分身都会造成大量伤害，使目标受到多重伤害的打击。 | H33: 尖牙蔓是藤蔓界的“啃咬专家”，它的口头禅是：“没有什么是咬不动的，咬多了自然就破！”每当战斗打响，它会召唤出无数的蔓草分身，进行疯狂的啃咬攻击。敌人常常在尖牙蔓的连环“咬咬”中毫无招架之力，甚至怀疑自己来到了巨型食肉植物的世界。尖牙蔓总是得意地说：“咬你一口不够，那就来无数口！”
A34: 10122 | B34: 1012202 | C34: 三头巨蔓 | E34: 幻影侵袭 | F34: 三头巨蔓释放毒气，制造出让敌人感受到花草地幻觉的效果，同时从幻觉中释放触手进行吞噬攻击，造成多次伤害。 | G34: 三头巨蔓释放毒气，制造出让敌人感受到花草地幻觉的效果，同时从幻觉中释放触手进行吞噬攻击，造成多次伤害。 | H34: 三头巨蔓是个不走寻常路的怪物，喜欢用幻觉来迷惑敌人。它通过释放毒气，让敌人以为自己置身于美丽的花草地，但等到对方刚想躺下享受时，三头巨蔓的触手突然从幻觉中冒出来，开始“悄悄”进行吞噬攻击。三头巨蔓喜欢说：“让你看看什么是真正的美景……不过最后，你会被吞掉哦！”
A35: 10130 | B35: 1013002 | C35: 小灯蜂 | E35: 耀眼闪光 | F35: 宝宝蜂用腹部的灯泡发出刺眼光芒，令范围内的敌人受到伤害。 | G35: 宝宝蜂用腹部的灯泡发出刺眼光芒，令范围内的敌人受到伤害。 | H35: 宝宝蜂刚学会飞，发现自己腹部的灯泡特别好玩，一不小心就把敌人亮得晕头转向。每次它用灯泡一闪，敌人就开始抱头大叫：“谁开大灯啦？”宝宝蜂对此很自豪，经常说：“别怪我，我就是这么亮！”
A36: 10131 | B36: 1013002 | C36: 灵灯蜂 | E36: 光晕禁锢 | F36: 灯泡蜂利用腹部的灯泡发出刺眼光芒，对大范围的敌人造成伤害。 | G36: 灯泡蜂利用腹部的灯泡发出刺眼光芒，对大范围的敌人造成伤害。 | H36: 经过进化，宝宝蜂变成了灯泡蜂，灯泡也升级成了“超级高光”。它最喜欢干的事就是在战场上开着“大灯”狂闪，让所有敌人都感觉自己在参加闪光灯派对。灯泡蜂总是笑着说：“灯光师到位，接招吧！”
A37: 10132
A38: 10140 | B38: 1014002 | C38: 炽焰幼虎 | E38: 炽焰利爪 | F38: 炽焰幼虎向前跃出使用爪击，对周围敌人造成伤害 | G38: 炽焰幼虎一跃而起，利爪划破空气，猛烈撕裂敌人，带来炽热的伤害。 | H38: 炽焰幼虎，出生于炽热的火山口，被火焰和岩浆孕育而生。从幼年起，它的爪子便带有炽热的火焰，随着每一次跳跃和撕裂，空气都会被其利爪灼烧。虽然体型尚小，但它的爆发力却不容小觑。
A39: 10141 | B39: 1014002 | C39: 炽焰虎 | E39: 雷霆爪击 | F39: 炽焰虎向前猛扑使用强力爪击，对周围敌人造成较大伤害 | G39: 炽焰虎如雷霆般猛扑而至，强力的爪击狠狠撕裂敌人，造成巨大的伤害。 | H39: 随着时间的推移，炽焰幼虎成长为强大的炽焰虎。它的力量宛如雷霆般不可抵挡，每一次攻击都如猛兽般迅猛而精准。炽焰虎的爪击已变得极为强大，撕裂敌人的同时带来炽热的灼烧效果。
A40: 10142
A41: 10150 | B41: 1015002 | C41: 惊吓魔盒 | E41: 魔盒爆裂 | F41: 惊吓魔盒祭出魔盒，炸裂效果对周围敌人造成伤害 | G41: 惊吓魔盒祭出神秘魔盒，伴随一声巨响，魔盒爆裂，敌人瞬间被冲击波吞没。 | H41: 惊吓魔盒喜欢藏在角落，等敌人靠近时突然打开它的神秘魔盒，伴随着巨大的“砰”声，把敌人吓得魂飞魄散。每次魔盒爆裂后，它都会得意地说：“惊不惊喜？意不意外？
A42: 10151 | B42: 1015002 | C42: 小丑魔盒 | E42: 魔盒震荡 | F42: 小丑魔盒祭出威力更为强大的魔盒，炸裂效果对周围敌人造成大量伤害 | G42: 小丑魔盒释放出极具破坏力的魔盒，爆炸产生的震撼波动席卷四周，令敌人无处可逃。 | H42: 进化后的小丑魔盒对“惊吓”已经不满足了，它追求的是轰轰烈烈的场面！每次释放魔盒，小丑魔盒都会站在远处狂笑：“震撼吧，震撼吧！”爆炸波席卷整个战场，敌人都被震得怀疑人生，它却开心地喊着：“看，我可是爆炸艺术家！”
...

Sheet Sheet2
H1: Id | I1: Name_Note | L1: Name | M1: Type | N1: Quality | O1: AttackSkillId | P1: SkillGroupId | Q1: Story_Note | R1: Story | S1: IconPath | T1: FullBodyImage | U1: PetModel | V1: Inherit | W1: Floor | X1: Upper | Y1: AtkSpeed | Z1: ModelScale | AA1: PetQuotesId
H2: Int | I2: String | L2: String | M2: Int | N2: int | O2: Int | P2: Int | Q2: String | R2: String | S2: String | T2: String | U2: String | V2: Int | W2: Int | X2: Int | Y2: Int | Z2: Int | AA2: Arrayint
H3: 唯一宠物id | I3: <c>宠物名字 | J3: 使用情况 | K3: 宠物类型 | L3: 宠物名字 | M3: 宠物type | N3: 品质 | O3: 普通攻击id | P3: 技能组ID | Q3: <c>宠物故事 | R3: 宠物故事 | S3: 头像 | T3: 宠物全身形象 | U3: 宠物战场模型 | V3: 继承属性比例 | W3: 成长率下限 | X3: 成长率上限 | Y3: 攻速 | Z3: 模型缩放 | AA3: 宠物语录ID
H4: 10060 | I4: 幻影猫 | L4: PetBasis_Name_10060 | M4: 1 | N4: 1 | O4: 1006001 | P4: 1 | Q4: 幻影猫是诞生于虚空中的神秘存在，它的灵巧与隐秘使得它成为虚空中最难以捉摸的守护者。它常常栖息在幽暗的虚空裂隙中，凭借召唤虚空之眼的能力，将入侵者瞬间引入深不可测的痛苦。 | R4: PetBasis_Story_10060 | S4: 10060 | T4: 10060 | U4: Pet_10060 | V4: 6000 | W4: 1000 | X4: 30000 | Y4: 6000 | Z4: 80 | AA4: 80|7|88|15|11|65|67|23|13|35|13|63|28|9
H5: 10061 | I5: 梦影猫 | L5: PetBasis_Name_10061 | M5: 1 | N5: 3 | O5: 1006101 | P5: 1 | Q5: 梦影猫，是虚空中力量更为强大的存在，作为幻影猫的进化形态，它能够掌控更强大的虚空力量。梦影猫生活在虚空的深层，远离凡世，但它的力量无时无刻不在影响着世界的秩序。 | R5: PetBasis_Story_10061 | S5: 10061 | T5: 10061 | U5: Pet_10061 | V5: 10000 | W5: 1000 | X5: 30000 | Y5: 10000 | Z5: 80 | AA5: 96|38|74|25|84|89|52|33|66|98|35|28|9|91
H6: 10062 | I6: 虚梦猫 | L6: PetBasis_Name_10062 | M6: 1 | N6: 5 | O6: 1006201 | P6: 1 | Q6: 作为虚空的终极守护者，虚梦猫的力量已达巅峰。它象征着虚空中的最强能量，连虚空本身都在它的控制之下。传说中，虚梦猫可以召唤出最强的虚空之眼，爆发出天崩地裂般的巨量能量冲击，席卷一切。 | R6: PetBasis_Story_10062 | S6: 10062 | T6: 10062 | U6: Pet_10062 | V6: 15000 | W6: 1000 | X6: 30000 | Y6: 15000 | Z6: 70 | AA6: 53|67|7|57|68|17|61|98|69|75|66|28|58|22
H7: 10070 | I7: 行路草 | L7: PetBasis_Name_10070 | M7: 1 | N7: 2 | O7: 1007001 | P7: 1 | Q7: 在广袤的森林深处，行路草是一种古老而神秘的植物生物。它的身体看似柔弱，却蕴藏着大自然的无穷力量。行路草喜欢安静地游走于大地之上，时而停下脚步，将寄生种子播撒在大地中。 | R7: PetBasis_Story_10070 | S7: 10070 | T7: 10070 | U7: Pet_10070 | V7: 8000 | W7: 1000 | X7: 30000 | Y7: 8000 | Z7: 80 | AA7: 94|26|13|75|14|83|18|55|24|57|51|71|47|27
H8: 10071 | I8: 行路兽 | L8: PetBasis_Name_10071 | M8: 1 | N8: 5 | O8: 1007101 | P8: 1 | Q8: 随着时间的推移，行路草进化为更强大的形态——行路兽。这一形态的行路兽拥有更为厚重的躯体和更强的力量，它对大地的掌控也更加深入。行路兽的行动更加沉稳，每一次踏足地面都仿佛唤醒了沉睡的草木与泥土。 | R8: PetBasis_Story_10071 | S8: 10071 | T8: 10071 | U8: Pet_10071 | V8: 15000 | W8: 1000 | X8: 30000 | Y8: 15000 | Z8: 70 | AA8: 94|26|13|75|14|83|18|55|24|57|51|71|47|27
H9: 10090 | I9: 冰角鹿 | L9: PetBasis_Name_10090 | M9: 1 | N9: 3 | O9: 1009001 | P9: 1 | Q9: 传说冰角鹿曾帮助一位迷路的旅行者找到了回家的路，从此被视为善良和希望的象征。 | R9: PetBasis_Story_10090 | S9: 10090 | T9: 10090 | U9: Pet_10090 | V9: 10000 | W9: 1000 | X9: 30000 | Y9: 10000 | Z9: 80 | AA9: 9|86|81|24|26|56|99|67|91|64|80|23|73|99
H10: 10091 | I10: 霜角鹿 | L10: PetBasis_Name_10091 | M10: 1 | N10: 4 | O10: 1009101 | P10: 1 | Q10: 霜角鹿虽然外表威武，但内心却十分呆萌。有传说它们曾因为贪玩，误把自己埋在雪堆里，直到第二天才被找到。 | R10: PetBasis_Story_10091 | S10: 10091 | T10: 10091 | U10: Pet_10091 | V10: 12000 | W10: 1000 | X10: 30000 | Y10: 12000 | Z10: 80 | AA10: 87|31|1|38|82|18|84|90|96|92|12|71|24|90
H11: 10100 | I11: 下忍菇 | J11: 1 | K11: 伤害-单体 | L11: PetBasis_Name_10100 | M11: 1 | N11: 2 | O11: 1010001 | P11: 1 | Q11: 下忍菇刚刚踏上忍者之路，技能是偷偷种蘑菇，结果每次释放毒蘑菇时，敌人只会捏着鼻子逃跑。虽然毒气效果不明显，但下忍菇坚信：“再臭的蘑菇也能赢得胜利！” | R11: PetBasis_Story_10100 | S11: 10100 | T11: 10100 | U11: Pet_10100 | V11: 8000 | W11: 1000 | X11: 30000 | Y11: 8000 | Z11: 80 | AA11: 94|26|13|75|14|83|18|55|24|57|51|71|47|27
H12: 10101 | I12: 上忍菇 | L12: PetBasis_Name_10101 | M12: 1 | N12: 4 | O12: 1010101 | P12: 1 | Q12: 经过多次失败后，下忍菇进化成了上忍菇。现在它组织起“蘑菇派对”，放出大片毒蘑菇覆盖战场。敌人闻着蘑菇味四散逃窜，上忍菇却得意地指挥毒气狂欢。 | R12: PetBasis_Story_10101 | S12: 10101 | T12: 10101 | U12: Pet_10101 | V12: 12000 | W12: 1000 | X12: 30000 | Y12: 12000 | Z12: 80 | AA12: 59|86|58|66|11|73|70|11|65|84|60|93|10|24
H13: 10102 | I13: 影忍菇 | L13: PetBasis_Name_10102 | M13: 1 | N13: 6 | O13: 1010201 | P13: 1 | Q13: 上忍菇最终进化成了影忍菇，已抛弃毒蘑菇，靠奥义“神速斩击”解决问题。它以极快速度冲刺，敌人还没反应过来，就已经被它无声无息地“斩成蘑菇片”了。 | R13: PetBasis_Story_10102 | S13: 10102 | T13: 10102 | U13: Pet_10102 | V13: 20000 | W13: 1000 | X13: 30000 | Y13: 20000 | Z13: 70 | AA13: 95|13|87|11|18|75|3|40|77|61|61|58|95|73
H14: 10110 | I14: 小树卫 | J14: 1 | K14: 防御 | L14: PetBasis_Name_10110 | M14: 1 | N14: 3 | O14: 1011001 | P14: 1 | Q14: 小树卫在一场森林大火中失去了亲人和伙伴，为了防止森林起火殃及无辜，从此肩负起守护森林的责任，日夜巡护，确保悲剧不再重演。 | R14: PetBasis_Story_10110 | S14: 10110 | T14: 10110 | U14: Pet_10110 | V14: 10000 | W14: 1000 | X14: 30000 | Y14: 10000 | Z14: 80 | AA14: 57|29|82|23|73|23|41|14|57|30|46|44|21|65
H15: 10111 | I15: 树桩战士 | L15: PetBasis_Name_10111 | M15: 1 | N15: 4 | O15: 1011101 | P15: 1 | Q15: 树桩战士曾是一棵大树，在伐木的暴行中留下斧凿的痕迹，现在，它保留着斧头，用以警醒自己。面对危险时，树桩战士会毫不留情地用其巨大的枝干作为武器击败并赶跑对方。 | R15: PetBasis_Story_10111 | S15: 10111 | T15: 10111 | U15: Pet_10111 | V15: 12000 | W15: 1000 | X15: 30000 | Y15: 12000 | Z15: 80 | AA15: 57|29|82|23|73|23|41|14|57|30|46|44|21|65
H16: 10120 | I16: 藤蔓球 | L16: PetBasis_Name_10120 | M16: 1 | N16: 2 | O16: 1012001 | P16: 1 | Q16: 藤蔓球自称是“分身大师”，每次一遇到敌人，它都会用自己的分身扑向对方。“一个不够？那就来十个！”藤蔓球最喜欢用多重分身发起攻击，让敌人以为自己被团团包围。虽然它的分身不太聪明，但每次都能带来连续不断的“藤蔓咬咬乐”，让敌人彻底晕头转向。 | R16: PetBasis_Story_10120 | S16: 10120 | T16: 10120 | U16: Pet_10120 | V16: 8000 | W16: 1000 | X16: 30000 | Y16: 8000 | Z16: 80 | AA16: 54|59|84|37|30|45|94|72|55|80|47|14|40|44
H17: 10121 | I17: 尖牙蔓 | L17: PetBasis_Name_10121 | M17: 1 | N17: 5 | O17: 1012101 | P17: 1 | Q17: 尖牙蔓是藤蔓界的“啃咬专家”，它的口头禅是：“没有什么是咬不动的，咬多了自然就破！”每当战斗打响，它会召唤出无数的蔓草分身，进行疯狂的啃咬攻击。敌人常常在尖牙蔓的连环“咬咬”中毫无招架之力，甚至怀疑自己来到了巨型食肉植物的世界。尖牙蔓总是得意地说：“咬你一口不够，那就来无数口！” | R17: PetBasis_Story_10121 | S17: 10121 | T17: 10121 | U17: Pet_10121 | V17: 15000 | W17: 1000 | X17: 30000 | Y17: 15000 | Z17: 70 | AA17: 95|13|87|11|18|75|3|40|77|61|61|58|95|73
H18: 10122 | I18: 三头巨蔓 | L18: PetBasis_Name_10122 | M18: 1 | N18: 6 | O18: 1012201 | P18: 1 | Q18: 三头巨蔓是个不走寻常路的怪物，喜欢用幻觉来迷惑敌人。它通过释放毒气，让敌人以为自己置身于美丽的花草地，但等到对方刚想躺下享受时，三头巨蔓的触手突然从幻觉中冒出来，开始“悄悄”进行吞噬攻击。三头巨蔓喜欢说：“让你看看什么是真正的美景……不过最后，你会被吞掉哦！” | R18: PetBasis_Story_10122 | S18: 10122 | T18: 10122 | U18: Pet_10122 | V18: 20000 | W18: 1000 | X18: 30000 | Y18: 20000 | Z18: 70 | AA18: 95|13|87|11|18|75|3|40|77|61|61|58|95|73
H19: 10130 | I19: 小灯蜂 | J19: 1 | K19: 伤害-群体 | L19: PetBasis_Name_10130 | M19: 1 | N19: 1 | O19: 1013001 | P19: 1 | Q19: 宝宝蜂刚学会飞，发现自己腹部的灯泡特别好玩，一不小心就把敌人亮得晕头转向。每次它用灯泡一闪，敌人就开始抱头大叫：“谁开大灯啦？”宝宝蜂对此很自豪，经常说：“别怪我，我就是这么亮！” | R19: PetBasis_Story_10130 | S19: 10130 | T19: 10130 | U19: Pet_10130 | V19: 6000 | W19: 1000 | X19: 30000 | Y19: 6000 | Z19: 80 | AA19: 34|6|73|35|32|62|56|75|88|15|39|76|29|49
H20: 10131 | I20: 灵灯蜂 | L20: PetBasis_Name_10131 | M20: 1 | N20: 3 | O20: 1013101 | P20: 1 | Q20: 经过进化，宝宝蜂变成了灯泡蜂，灯泡也升级成了“超级高光”。它最喜欢干的事就是在战场上开着“大灯”狂闪，让所有敌人都感觉自己在参加闪光灯派对。灯泡蜂总是笑着说：“灯光师到位，接招吧！” | R20: PetBasis_Story_10131 | S20: 10131 | T20: 10131 | U20: Pet_10131 | V20: 10000 | W20: 1000 | X20: 30000 | Y20: 10000 | Z20: 80 | AA20: 87|38|29|7|79|34|18|38|68|98|33|100|48|70
H21: 10140 | I21: 炽焰幼虎 | L21: PetBasis_Name_10140 | M21: 1 | N21: 3 | O21: 1014001 | P21: 1 | Q21: 炽焰幼虎，出生于炽热的火山口，被火焰和岩浆孕育而生。从幼年起，它的爪子便带有炽热的火焰，随着每一次跳跃和撕裂，空气都会被其利爪灼烧。虽然体型尚小，但它的爆发力却不容小觑。 | R21: PetBasis_Story_10140 | S21: 10140 | T21: 10140 | U21: Pet_10140 | V21: 10000 | W21: 1000 | X21: 30000 | Y21: 10000 | Z21: 80 | AA21: 34|6|73|35|32|62|56|75|88|15|39|76|29|49
H22: 10141 | I22: 炽焰虎 | L22: PetBasis_Name_10141 | M22: 1 | N22: 6 | O22: 1014101 | P22: 1 | Q22: 随着时间的推移，炽焰幼虎成长为强大的炽焰虎。它的力量宛如雷霆般不可抵挡，每一次攻击都如猛兽般迅猛而精准。炽焰虎的爪击已变得极为强大，撕裂敌人的同时带来炽热的灼烧效果。 | R22: PetBasis_Story_10141 | S22: 10141 | T22: 10141 | U22: Pet_10141 | V22: 20000 | W22: 1000 | X22: 30000 | Y22: 20000 | Z22: 70 | AA22: 94|26|13|75|14|83|18|55|24|57|51|71|47|27
H23: 10150 | I23: 惊吓魔盒 | L23: PetBasis_Name_10150 | M23: 1 | N23: 2 | O23: 1015001 | P23: 1 | Q23: 惊吓魔盒喜欢藏在角落，等敌人靠近时突然打开它的神秘魔盒，伴随着巨大的“砰”声，把敌人吓得魂飞魄散。每次魔盒爆裂后，它都会得意地说：“惊不惊喜？意不意外？ | R23: PetBasis_Story_10150 | S23: 10150 | T23: 10150 | U23: Pet_10150 | V23: 8000 | W23: 1000 | X23: 30000 | Y23: 8000 | Z23: 80 | AA23: 6|47|93|97|89|56|67|37|14|74|47|47|2|6
H24: 10151 | I24: 小丑魔盒 | L24: PetBasis_Name_10151 | M24: 1 | N24: 6 | O24: 1015101 | P24: 1 | Q24: 进化后的小丑魔盒对“惊吓”已经不满足了，它追求的是轰轰烈烈的场面！每次释放魔盒，小丑魔盒都会站在远处狂笑：“震撼吧，震撼吧！”爆炸波席卷整个战场，敌人都被震得怀疑人生，它却开心地喊着：“看，我可是爆炸艺术家！” | R24: PetBasis_Story_10151 | S24: 10151 | T24: 10151 | U24: Pet_10151 | V24: 20000 | W24: 1000 | X24: 30000 | Y24: 20000 | Z24: 70 | AA24: 99|46|56|52|15|19|92|94|62|95|70|61|98|86
H25: 10160 | I25: 尖叫鸡 | L25: PetBasis_Name_10160 | M25: 1 | N25: 3 | O25: 1016001 | P25: 1 | Q25: 尖叫鸡本来是个不起眼的小鸡，直到它发现自己发出的尖叫声能让敌人耳朵怀疑人生。每次战斗，尖叫鸡都会发出那令人胆寒的尖锐音波，敌人听了不是抱头大叫，就是四处乱窜。惨叫鸡得意地说：“我这一嗓子，连我自己都吓！” | R25: PetBasis_Story_10160 | S25: 10160 | T25: 10160 | U25: Pet_10160 | V25: 10000 | W25: 1000 | X25: 30000 | Y25: 10000 | Z25: 80 | AA25: 67|62|25|34|66|39|63|55|63|22|5|10|33|88
H26: 10161 | I26: 勇士鸡 | L26: PetBasis_Name_10161 | M26: 1 | N26: 4 | O26: 1016101 | P26: 1 | Q26: 惨叫鸡进化成了勇士鸡，告别了尖叫，拿起了一把长枪！它现在的绝招是“鸡式闪电突刺”，挥舞着长枪以闪电般的速度冲向敌人 | R26: PetBasis_Story_10161 | S26: 10161 | T26: 10161 | U26: Pet_10161 | V26: 12000 | W26: 1000 | X26: 30000 | Y26: 12000 | Z26: 80 | AA26: 67|62|25|34|66|39|63|55|63|22|5|10|33|88
H27: 10170 | I27: 鼹鼠幼崽 | L27: PetBasis_Name_10170 | M27: 1 | N27: 3 | O27: 1017001 | P27: 1 | Q27: 鼹鼠幼崽是个小小的冒险家，它总喜欢瞬间消失在地面上，再从地底突然出现，给敌人来个意想不到的“地底惊喜”。每次出击，它都会带来强烈的冲击波，让周围的敌人措手不及。一次，它在追逐闪电虫时意外发现了“地下突袭”的诀窍，成为了战场上的捉迷藏高手。 | R27: PetBasis_Story_10170 | S27: 10170 | T27: 10170 | U27: Pet_10170 | V27: 10000 | W27: 1000 | X27: 30000 | Y27: 10000 | Z27: 80 | AA27: 12|75|38|83|48|86|62|55|29|86|21|8|54|35
H28: 10171 | I28: 鼹鼠矿工 | L28: PetBasis_Name_10171 | M28: 1 | N28: 4 | O28: 1017101 | P28: 1 | Q28: 进化后的鼹鼠矿工担负起了守护大地的使命，平时喜欢潜伏在地下，默默观察战局，关键时刻从地底猛然冲出，用无比强大的冲力击溃敌人。据说，它曾成功拯救一座村庄免受巨石崩塌，只因它“感觉大地在呼唤”。 | R28: PetBasis_Story_10171 | S28: 10171 | T28: 10171 | U28: Pet_10171 | V28: 12000 | W28: 1000 | X28: 30000 | Y28: 12000 | Z28: 80 | AA28: 12|75|38|83|48|86|62|55|29|86|21|8|54|35
H29: 10180 | I29: 受伤小软 | L29: PetBasis_Name_10180 | M29: 1 | N29: 3 | O29: 1018001 | P29: 1 | Q29: 受伤小软看起来软软糯糯，但一旦受伤，它就像“醉拳大师”一样，左摇右摆地冲进敌人堆里，甩出毒液四处乱飞。敌人本以为它会摔倒，结果却被毒液腐蚀得嗷嗷叫。小软还得意洋洋地说：“我晃得不是身体，是战术！”据说它一次不小心把毒液洒自己身上，结果却意外领悟了这招“摇摆毒液术”。 | R29: PetBasis_Story_10180 | S29: 10180 | T29: 10180 | U29: Pet_10180 | V29: 10000 | W29: 1000 | X29: 30000 | Y29: 10000 | Z29: 80 | AA29: 9|48|16|43|58|20|56|86|22|52|64|2|53|45
H30: 10181 | I30: 战斗小软 | L30: PetBasis_Name_10181 | M30: 1 | N30: 6 | O30: 1018001 | P30: 1 | Q30: 进化后的战斗小软彻底告别了摇晃战术，改成了“剑术派”。它手持一把闪闪发光的大剑，每次冲刺都带着“剑光雷霆”的霸气。传闻有一次它冲得太猛，剑光亮瞎了自己，差点扎进草堆里。尽管如此，它依然自信满满：“只要我速度够快，敌人看都看不清我！” | R30: PetBasis_Story_10181 | S30: 10181 | T30: 10181 | U30: Pet_10181 | V30: 20000 | W30: 1000 | X30: 30000 | Y30: 20000 | Z30: 70 | AA30: 12|75|38|83|48|86|62|55|29|86|21|8|54|35
H31: 10182 | I31: 软软国王 | L31: PetBasis_Name_10182 | M31: 1 | N31: 7 | O31: 1018001 | P31: 1 | Q31: 进化后的战斗小软彻底告别了摇晃战术，改成了“剑术派”。它手持一把闪闪发光的大剑，每次冲刺都带着“剑光雷霆”的霸气。传闻有一次它冲得太猛，剑光亮瞎了自己，差点扎进草堆里。尽管如此，它依然自信满满：“只要我速度够快，敌人看都看不清我！” | R31: PetBasis_Story_10182 | S31: 10182 | T31: 10182 | U31: Pet_10182 | V31: 30000 | W31: 1000 | X31: 30000 | Y31: 30000 | Z31: 70 | AA31: 12|75|38|83|48|86|62|55|29|86|21|8|54|35
H32: 10190 | I32: 奶拳兔 | L32: PetBasis_Name_10190 | M32: 1 | N32: 1 | O32: 1019001 | P32: 1 | Q32: 奶拳兔看起来萌萌哒，挥着小拳头时，敌人还以为它在打招呼。可一旦被它冲过来“锤”了一下，敌人才发现这小拳头可不只是好看！每次出手后，奶拳兔还会回头眨巴着眼睛说：“萌只是我的伪装，疼才是我的真相！” | R32: PetBasis_Story_10190 | S32: 10190 | T32: 10190 | U32: Pet_10190 | V32: 6000 | W32: 1000 | X32: 30000 | Y32: 6000 | Z32: 80 | AA32: 12|75|38|83|48|86|62|55|29|86|21|8|54|35
H33: 10191 | I33: 拳击兔 | L33: PetBasis_Name_10191 | M33: 1 | N33: 3 | O33: 1019101 | P33: =P4+1 -> 2 | Q33: 进化后的拳击兔不再靠“萌”混迹战场，它像一阵狂风般冲向敌人，拳头像雨点一样快速落下。敌人只觉得眼前“咻咻”闪过几下，还没反应过来就已经被打成了一团。拳击兔笑着说：“速度决定一切，我就是风中拳手！” | R33: PetBasis_Story_10191 | S33: 10191 | T33: 10191 | U33: Pet_10191 | V33: 10000 | W33: 1000 | X33: 30000 | Y33: 10000 | Z33: 80 | AA33: 12|75|38|83|48|86|62|55|29|86|21|8|54|35
H34: 10192 | I34: 拳王兔 | L34: PetBasis_Name_10192 | M34: 1 | N34: 7 | O34: 1019201 | P34: =P5+1 -> 2 | Q34: 拳王兔早已登上拳击界宝座，每次出拳都是全力以赴，力量雷霆万钧。一拳挥出，敌人仿佛经历了一场“地震”般的冲击，全场瞬间被清空。拳王兔挥挥手说：“不需要多，干净利落一拳搞定！” | R34: PetBasis_Story_10192 | S34: 10192 | T34: 10192 | U34: Pet_10192 | V34: 30000 | W34: 1000 | X34: 30000 | Y34: 30000 | Z34: 70 | AA34: 12|75|38|83|48|86|62|55|29|86|21|8|54|35
H35: 10210 | I35: 角斗娃 | L35: PetBasis_Name_10210 | M35: 1 | N35: 3 | O35: 1021001 | P35: =P6+1 -> 2 | Q35: 角斗娃抱着它心爱的橄榄球，冲锋起来那叫一个猛烈，像是一头小型“推土机”。每次冲撞，敌人就像被卷进了“山崩地裂”的场面，通通被撞飞。它最喜欢在撞飞敌人后喊：“谁敢挡路就别怪我不客气！” | R35: PetBasis_Story_10210 | S35: 10210 | T35: 10210 | U35: Pet_10210 | V35: 10000 | W35: 1000 | X35: 30000 | Y35: 10000 | Z35: 80 | AA35: 76|89|90|19|9|8|65|13|10|11|5|20|91|5
H36: 10211 | I36: 巨角斗牛 | L36: PetBasis_Name_10211 | M36: 1 | N36: 6 | O36: 1021101 | P36: =P7+1 -> 2 | Q36: 进化后的巨角斗牛，抱着橄榄球一冲起来就像移动的“破坏机器”。它的强力冲撞足以让敌人感受到“天崩地裂”的威力，周围的敌人瞬间被碾压成灰。一次，它冲得太猛，直接把敌方撞得七零八落，还一脸淡定地说：“抱歉，我只是在练习我的冲刺！” | R36: PetBasis_Story_10211 | S36: 10211 | T36: 10211 | U36: Pet_10211 | V36: 20000 | W36: 1000 | X36: 30000 | Y36: 20000 | Z36: 70 | AA36: 85|28|43|46|47|95|65|100|3|8|27|92|26|69
H37: 10220 | I37: 重锤兽 | L37: PetBasis_Name_10220 | M37: 1 | N37: 1 | O37: 1022001 | P37: =P8+1 -> 2 | Q37: 重锤兽从小就有个梦想——掌控大地的力量。每次它召唤地突刺时，都会一脸严肃地说：“让大地来帮我打！”虽然看起来憨憨的，但它的地突刺可不是闹着玩的，敌人一不小心就被重击得飞上天。它总是骄傲地拍拍地面：“你们的末日由我和大地决定！” | R37: PetBasis_Story_10220 | S37: 10220 | T37: 10220 | U37: Pet_10220 | V37: 6000 | W37: 1000 | X37: 30000 | Y37: 6000 | Z37: 80 | AA37: 76|89|90|19|9|8|65|13|10|11|5|20|91|5
H38: 10221 | I38: 重锤巨兽 | L38: PetBasis_Name_10221 | M38: 1 | N38: 4 | O38: 1022101 | P38: =P9+1 -> 2 | Q38: 进化后的重锤巨兽，已经完全掌控了大地和元素的力量。每次召唤大量地突刺时，敌人都感觉像经历了一场“天灾”。一次，它召唤的突刺把敌人碾成了平地，还自言自语地说：“这就是我为你们准备的大地之礼！” | R38: PetBasis_Story_10221 | S38: 10221 | T38: 10221 | U38: Pet_10221 | V38: 12000 | W38: 1000 | X38: 30000 | Y38: 12000 | Z38: 80 | AA38: 85|28|43|46|47|95|65|100|3|8|27|92|26|69
H39: 10230 | I39: 小烛灵 | L39: PetBasis_Name_10230 | M39: 1 | N39: 3 | O39: 1023001 | P39: =P10+1 -> 2 | Q39: 别看小烛灵个头小，它可是火枪神射手！每次把烛火化作火枪，都会自信地说：“闪开，我的子弹可是又快又准！”敌人总是被这看似不起眼的小火苗吓得四处逃窜，可小烛灵一边射击一边自豪地喊：“打得准，不赖我，是火枪太厉害！” | R39: PetBasis_Story_10230 | S39: 10230 | T39: 10230 | U39: Pet_10230 | V39: 10000 | W39: 1000 | X39: 30000 | Y39: 10000 | Z39: 80 | AA39: 54|59|84|37|30|45|94|72|55|80|47|14|40|44
H40: 10231 | I40: 烛灵枪手 | L40: PetBasis_Name_10231 | M40: 1 | N40: 5 | O40: 1023101 | P40: =P11+1 -> 2 | Q40: 进化后的烛灵枪手，已经不满足一把火枪了，它能同时幻化出无数火枪，简直就是一个移动火力库！连珠般的火力让敌人无处可逃。一次，它射得太欢快，差点把自己的影子也给打了，还笑着说：“不好意思，我的火枪不认人，只认目标！” | R40: PetBasis_Story_10231 | S40: 10231 | T40: 10231 | U40: Pet_10231 | V40: 15000 | W40: 1000 | X40: 30000 | Y40: 15000 | Z40: 70 | AA40: 12|75|38|83|48|86|62|55|29|86|21|8|54|35
...

Sheet Sheet5
A1: 编号 | B1: 品质
A2: 10182 | B2: 不朽 | C2: 7 | D2: =VLOOKUP(A:A,Sheet6!A:B,2,FALSE) -> 软软国王
A3: 10192 | B3: 不朽 | C3: 7 | D3: =VLOOKUP(A:A,Sheet6!A:B,2,FALSE) -> 拳王兔
A4: 10272 | B4: 不朽 | C4: 7 | D4: =VLOOKUP(A:A,Sheet6!A:B,2,FALSE) -> 熔岩王
A5: 10622 | B5: 不朽 | C5: 7 | D5: =VLOOKUP(A:A,Sheet6!A:B,2,FALSE) -> 船长海盗鲨
A6: 10352 | B6: 不朽 | C6: 7 | D6: =VLOOKUP(A:A,Sheet6!A:B,2,FALSE) -> 夜影公爵
A7: 10392 | B7: 不朽 | C7: 7 | D7: =VLOOKUP(A:A,Sheet6!A:B,2,FALSE) -> 壶灵王
A8: 10422 | B8: 不朽 | C8: 7 | D8: =VLOOKUP(A:A,Sheet6!A:B,2,FALSE) -> 三头犬神
A9: 10512 | B9: 不朽 | C9: 7 | D9: =VLOOKUP(A:A,Sheet6!A:B,2,FALSE) -> 机械暴龙
A10: 10522 | B10: 不朽 | C10: 7 | D10: =VLOOKUP(A:A,Sheet6!A:B,2,FALSE) -> 骑士蜥
A11: 10562 | B11: 不朽 | C11: 7 | D11: =VLOOKUP(A:A,Sheet6!A:B,2,FALSE) -> 核弹鲨
A12: 10582 | B12: 不朽 | C12: 7 | D12: =VLOOKUP(A:A,Sheet6!A:B,2,FALSE) -> 城堡蝸牛
A13: 10332 | B13: 神话 | C13: 6 | D13: =VLOOKUP(A:A,Sheet6!A:B,2,FALSE) -> 炽焰羊
... A96: 10190 | B96: 普通 | C96: 1 | D96: =VLOOKUP(A:A,Sheet6!A:B,2,FALSE) -> 奶拳兔

Sheet Sheet6
A1: id | B1: Name | C1: PetModel | D1: 宠物模型 | E1: IconPath | F1: 头像图标 | G1: FullBodyImage | H1: 宠物立绘 | I1: path | K1: path | O1: skillIcon | P1: skillIcon | Q1: skillIcon | R1: skillIcon | S1: skillIcon | T1: skillIcon
A2: int | B2: string | C2: String | D2: 在战斗中用的 | E2: string | F2: 命名需要按照图标的名称 | G2: string | H2: 命名需要按照图标的名称 | I2: string | K2: string | O2: string | P2: string | Q2: string | R2: string | S2: string | T2: string
A3: 唯一宠物id | B3: 宠物名字 | C3: 模型资源：索引宠物全身形象资源 注：动作绑定在模型中 | D3: 需要放在工程ExternalRes中Model | E3: 头像 | F3: 需要放在工程ExternalRes中Pet的PetIcon文件中 | G3: 宠物全身形象 | H3: 需要放在工程ExternalRes中Pet的PetBody文件中 | I3: attack | J3: 攻击前摇时间 | K3: skill | L3: 动作时间 | M3: 技能前摇时间 | N3: 伤害时间节点 | O3: 技能图标 | P3: 被动技能1 | Q3: 被动技能2 | R3: 被动技能3 | S3: 被动技能4 | T3: 被动技能5
A4: 10012 | B4: 海翼龟 | C4: Pet_10012 | D4: 完成 | E4: 10012 | F4: 完成 | G4: 10012 | I4: skill_1001001 | J4: 0.5 | K4: skill_1001002 | L4: 1.67 | M4: 0.4 | N4: 0.45 | O4: 1001202 | P4: 1001203 | Q4: 1001204 | R4: 1001205 | S4: 1001206 | T4: 1001207
A5: 10032 | B5: 钢铠王 | C5: Pet_10032 | D5: 完成 | E5: 10032 | F5: 完成 | G5: 10032 | I5: skill_1003001 | J5: 0.4 | K5: skill_1003002 | L5: 1 | M5: 0.5 | N5: 0.25~1 | O5: 1003202 | P5: 1003203 | Q5: 1003204 | R5: 1003205 | S5: 1003206 | T5: 1003207
A6: 10042 | B6: 沙漠龙王 | C6: Pet_10042 | D6: 完成 | E6: 10042 | F6: 完成 | G6: 10042 | I6: skill_1004001 | J6: 0.4 | K6: skill_1004002 | L6: 1.5 | M6: 0.4 | N6: 1~3 | O6: 1004202 | P6: 1004203 | Q6: 1004204 | R6: 1004205 | S6: 1004206 | T6: 1004207
A7: 10060 | B7: 幻影猫 | C7: Pet_10060 | D7: 完成 | E7: 10060 | F7: 完成 | G7: 10060 | H7: 完成 | I7: skill_1006001 | J7: 0.33 | K7: skill_1006002 | L7: 1.33 | M7: 0.6 | N7: 0.55 | O7: 1006002 | P7: 1006003 | Q7: 1006004 | R7: 1006005 | S7: 1006006 | T7: 1006007
A8: 10061 | B8: 梦影猫 | C8: Pet_10061 | D8: 完成 | E8: 10061 | F8: 完成 | G8: 10061 | H8: 完成 | I8: skill_1006001 | J8: 0.4 | K8: skill_1006102 | L8: 1.67 | M8: 0.5 | N8: 1 | O8: 1006102 | P8: 1006103 | Q8: 1006104 | R8: 1006105 | S8: 1006106 | T8: 1006107
A9: 10062 | B9: 虚梦猫 | C9: Pet_10062 | D9: 完成 | E9: 10062 | F9: 完成 | G9: 10062 | H9: 完成 | I9: skill_1006001 | J9: 0.5 | K9: skill_1006202 | L9: 1.67 | M9: 0.6 | N9: 0.4~0.85 | O9: 1006202 | P9: 1006203 | Q9: 1006204 | R9: 1006205 | S9: 1006206 | T9: 1006207
A10: 10070 | B10: 行路草 | C10: Pet_10070 | D10: 9.3提交 | E10: 10070 | G10: 10070 | I10: skill_1007001 | J10: 0.3 | K10: skill_1007002 | L10: 3.4 | M10: 0.9 | N10: 0.5 | O10: 1007002 | P10: 1007003 | Q10: 1007004 | R10: 1007005 | S10: 1007006 | T10: 1007007
A11: 10071 | B11: 行路兽 | C11: Pet_10071 | D11: 9.13提交 | E11: 10071 | F11: 9.10提交 | G11: 10071 | H11: 9.10提交 | I11: skill_1007001 | J11: 0.4 | K11: skill_1007102 | L11: 2.8 | M11: 1 | N11: 0.5 | O11: 1007102 | P11: 1007103 | Q11: 1007104 | R11: 1007105 | S11: 1007106 | T11: 1007107
A12: 10090 | B12: 冰角鹿 | C12: Pet_10090 | D12: 7.17修改 | E12: 10090 | F12: 6.18提交 | G12: 10090 | H12: 6.18提交 | I12: skill_1009001 | J12: 0.4 | K12: skill_1009002 | L12: 2.7 | M12: 0.5 | N12: 0.42~1.6 | O12: 1009002 | P12: 1009003 | Q12: 1009004 | R12: 1009005 | S12: 1009006 | T12: 1009007
A13: 10091 | B13: 霜角鹿 | C13: Pet_10091 | D13: 7.17修改 | E13: 10091 | F13: 6.18提交 | G13: 10091 | H13: 6.18提交 | I13: skill_1009001 | J13: 0.5 | K13: skill_1009102 | L13: 3.2 | M13: 0.7 | N13: 0.42~1.6 | O13: 1009102 | P13: 1009103 | Q13: 1009104 | R13: 1009105 | S13: 1009106 | T13: 1009107
A14: 10100 | B14: 下忍菇 | C14: Pet_10100 | D14: 7.17修改 | E14: 10100 | F14: 6.18提交 | G14: 10100 | H14: 6.18提交 | I14: skill_1010001 | J14: 0.4 | K14: skill_1010002 | L14: 2.33 | M14: 0.6 | N14: 0.6 | O14: 1010002 | P14: 1010003 | Q14: 1010004 | R14: 1010005 | S14: 1010006 | T14: 1010007
A15: 10101 | B15: 上忍菇 | C15: Pet_10101 | D15: 7.17修改 | E15: 10101 | F15: 6.18提交 | G15: 10101 | H15: 6.18提交 | I15: skill_1010001 | J15: 0.4 | K15: skill_1010102 | L15: 2.7 | M15: 0.5_anim | N15: 1.3,1.43 | O15: 1010102 | P15: 1010103 | Q15: 1010104 | R15: 1010105 | S15: 1010106 | T15: 1010107
A16: 10102 | B16: 影忍菇 | C16: Pet_10102 | D16: 9.3提交 | E16: 10102 | G16: 10102 | I16: skill_1010001 | J16: 0.4 | K16: skill_1010202 | L16: 3 | M16: 1.1_anim | N16: 0.2~1.4 | O16: 1010202 | P16: 1010203 | Q16: 1010204 | R16: 1010205 | S16: 1010206 | T16: 1010207
A17: 10110 | B17: 小树卫 | C17: Pet_10110 | D17: 8.20提交 | E17: 10110 | F17: 8.6提交 | G17: 10110 | H17: 8.6提交 | I17: skill_1011001 | J17: 0.4 | K17: skill_1011002 | L17: 3.5 | M17: 0.3_anim | N17: 1,1.2,2,2.2 | O17: 1011002 | P17: 1011003 | Q17: 1011004 | R17: 1011005 | S17: 1011006 | T17: 1011007
A18: 10111 | B18: 树桩战士 | C18: Pet_10111 | D18: 8.20提交 | E18: 10111 | F18: 8.6提交 | G18: 10111 | H18: 8.6提交 | I18: skill_1011101 | J18: 0.4 | K18: skill_1011102 | L18: 3.7 | M18: 0.5_anim | N18: 1,1.2,2,2.2 | O18: 1011102 | P18: 1011103 | Q18: 1011104 | R18: 1011105 | S18: 1011106 | T18: 1011107
A19: 10120 | B19: 藤蔓球 | C19: Pet_10120 | D19: 7.17修改 | E19: 10120 | F19: 9.10提交 | G19: 10120 | H19: 9.10提交 | I19: skill_1012001 | J19: 0.3 | K19: skill_1012002 | L19: 3 | M19: 0.7 | N19: 0.7，0.75，0.85，0.95，1.05 | O19: 1012002 | P19: 1012003 | Q19: 1012004 | R19: 1012005 | S19: 1012006 | T19: 1012007
A20: 10121 | B20: 尖牙蔓 | C20: Pet_10121 | D20: 7.17修改 | E20: 10121 | F20: 9.10提交 | G20: 10121 | H20: 9.10提交 | I20: skill_1012001 | J20: 0.3 | K20: skill_1012102 | L20: 3 | M20: 0.7 | N20: 0.7，0.75，0.85，0.95，1.05 | O20: 1012102 | P20: 1012103 | Q20: 1012104 | R20: 1012105 | S20: 1012106 | T20: 1012107
A21: 10122 | B21: 三头巨蔓 | C21: Pet_10122 | D21: 8.6提交 | E21: 10122 | G21: 10122 | I21: skill_1012001 | J21: 0.4 | K21: skill_1012202 | L21: 2.7 | M21: 0_anim | N21: 0.35~2.25 | O21: 1012202 | P21: 1012203 | Q21: 1012204 | R21: 1012205 | S21: 1012206 | T21: 1012207
A22: 10130 | B22: 小灯蜂 | C22: Pet_10130 | D22: 7.17修改 | E22: 10130 | F22: 6.18提交 | G22: 10130 | H22: 6.18提交 | I22: skill_1013001 | J22: 0.5 | K22: skill_1013002 | L22: 2.7 | M22: 0.5 | N22: 0.4~1.55 | O22: 1013002 | P22: 1013003 | Q22: 1013004 | R22: 1013005 | S22: 1013006 | T22: 1013007
A23: 10131 | B23: 灵灯蜂 | C23: Pet_10131 | D23: 7.17修改 | E23: 10131 | F23: 6.18提交 | G23: 10131 | H23: 6.18提交 | I23: skill_1013001 | J23: 0.4 | K23: skill_1013102 | L23: 2.7 | M23: 0.6 | N23: 0.4~1.55 | O23: 1013102 | P23: 1013103 | Q23: 1013104 | R23: 1013105 | S23: 1013106 | T23: 1013107
A24: 10140 | B24: 炽焰幼虎 | C24: Pet_10140 | D24: 8.21提交 | E24: 10140 | F24: 8.13提交 | G24: 10140 | H24: 8.13提交 | I24: skill_1014001 | J24: 0.4 | K24: skill_1014002 | L24: 2.9 | M24: 0.6_amin | N24: 0.45 | O24: 1014002 | P24: 1014003 | Q24: 1014004 | R24: 1014005 | S24: 1014006 | T24: 1014007
A25: 10141 | B25: 炽焰虎 | C25: Pet_10141 | D25: 8.21提交 | E25: 10141 | G25: 10141 | H25: 8.13提交 | I25: skill_1014001 | J25: 0.4 | K25: skill_1014102 | L25: 2.3 | M25: 0.7_anim | N25: 1 | O25: 1014102 | P25: 1014103 | Q25: 1014104 | R25: 1014105 | S25: 1014106 | T25: 1014107
A26: 10150 | B26: 惊吓魔盒 | C26: Pet_10150 | D26: 7.17修改 | E26: 10150 | G26: 10150 | I26: skill_1015001 | J26: 0.4 | K26: skill_1015002 | L26: 1.8 | M26: 0.3_anim | N26: 0.85 | O26: 1015002 | P26: 1015003 | Q26: 1015004 | R26: 1015005 | S26: 1015006 | T26: 1015007
A27: 10151 | B27: 小丑魔盒 | C27: Pet_10151 | D27: 7.17修改 | E27: 10151 | G27: 10151 | I27: skill_1015001 | J27: 0.4 | K27: skill_1015102 | L27: 2.7 | M27: 1.1_anim | N27: 0.85 | O27: 1015102 | P27: 1015103 | Q27: 1015104 | R27: 1015105 | S27: 1015106 | T27: 1015107
A28: 10160 | B28: 尖叫鸡 | C28: Pet_10160 | D28: 7.31提交 | E28: 10160 | F28: 6.18提交 | G28: 10160 | H28: 6.18提交 | I28: skill_1016001 | J28: 0.4 | K28: skill_1016002 | L28: 2.4 | M28: 0.7 | N28: 0.5~2 | O28: 1016002 | P28: 1016003 | Q28: 1016004 | R28: 1016005 | S28: 1016006 | T28: 1016007
A29: 10161 | B29: 勇士鸡 | C29: Pet_10161 | D29: 7.17修改 | E29: 10161 | F29: 6.18提交 | G29: 10161 | H29: 6.18提交 | I29: skill_1016001 | J29: 0.4 | K29: skill_1016102 | L29: 1.7 | M29: 0.6_amin | N29: 0.65 | O29: 1016102 | P29: 1016103 | Q29: 1016104 | R29: 1016105 | S29: 1016106 | T29: 1016107
A30: 10170 | B30: 鼹鼠幼崽 | C30: Pet_10170 | D30: 8.28提交 | E30: 10170 | F30: 9.10提交 | G30: 10170 | H30: 9.10提交 | I30: skill_1017001 | J30: 0.3 | K30: skill_1017002 | L30: 3.1 | M30: 2_anim | N30: 0.1 | O30: 1017002 | P30: 1017003 | Q30: 1017004 | R30: 1017005 | S30: 1017006 | T30: 1017007
A31: 10171 | B31: 鼹鼠矿工 | C31: Pet_10171 | D31: 8.28提交 | E31: 10171 | G31: 10171 | I31: skill_1017001 | J31: 0.3 | K31: skill_1017102 | L31: 3.1 | M31: 2_anim | N31: 0.1 | O31: 1017102 | P31: 1017103 | Q31: 1017104 | R31: 1017105 | S31: 1017106 | T31: 1017107
A32: 10180 | B32: 受伤小软 | C32: Pet_10180 | D32: 7.17修改 | E32: 10180 | F32: 7.2提交 | G32: 10180 | H32: 7.2提交 | I32: skill_1018001 | J32: 0.4 | K32: skill_1018002 | L32: 2.5 | M32: 0.7 | N32: 0.4~1.5 | O32: 1018002 | P32: 1018003 | Q32: 1018004 | R32: 1018005 | S32: 1018006 | T32: 1018007
A33: 10181 | B33: 战斗小软 | C33: Pet_10181 | D33: 9.3提交 | E33: 10181 | F33: 7.2提交 | G33: 10181 | H33: 7.2提交 | I33: skill_1018001 | J33: 0.4 | K33: skill_1018102 | L33: 2.7 | M33: 0.9_anim | N33: 0.4~1.5 | O33: 1018102 | P33: 1018103 | Q33: 1018104 | R33: 1018105 | S33: 1018106 | T33: 1018107
A34: 10182 | B34: 软软国王 | C34: Pet_10182 | E34: 10182 | G34: 10182 | I34: skill_1018001 | J34: 0.4 | K34: skill_1018202 | L34: 2.7 | M34: 0.8_anim | N34: 1~1.7 | O34: 1018202 | P34: 1018203 | Q34: 1018204 | R34: 1018205 | S34: 1018206 | T34: 1018207
A35: 10190 | B35: 奶拳兔 | C35: Pet_10190 | D35: 8.6提交 | E35: 10190 | G35: 10190 | I35: skill_1019001 | J35: 0.4 | K35: skill_1019002 | L35: 2 | M35: 0_anim | N35: 1,1.1.15,1.35,1.6 | O35: 1019002 | P35: 1019003 | Q35: 1019004 | R35: 1019005 | S35: 1019006 | T35: 1019007
A36: 10191 | B36: 拳击兔 | C36: Pet_10191 | D36: 8.6修改 | E36: 10191 | G36: 10191 | I36: skill_1019001 | J36: 0.4 | K36: skill_1019102 | L36: 2.7 | M36: 0.5_anim | N36: 0.3,0.7~1.65 | O36: 1019102 | P36: 1019103 | Q36: 1019104 | R36: 1019105 | S36: 1019106 | T36: 1019107
A37: 10192 | B37: 拳王兔 | C37: Pet_10192 | D37: 8.6修改 | E37: 10192 | F37: 9.10提交 | G37: 10192 | H37: 9.10提交 | I37: skill_1019001 | J37: 0.4 | K37: skill_1019202 | L37: 3 | M37: 1.7 | N37: 0.15 | O37: 1019202 | P37: 1019203 | Q37: 1019204 | R37: 1019205 | S37: 1019206 | T37: 1019207
A38: 10210 | B38: 角斗娃 | C38: Pet_10210 | D38: 9.3提交 | E38: 10210 | F38: 8.13提交 | G38: 10210 | H38: 8.13提交 | I38: skill_1021001 | J38: 0.4 | K38: skill_1021002 | L38: 2.9 | M38: 1.1 | N38: 0.35~0.65 | O38: 1021002 | P38: 1021003 | Q38: 1021004 | R38: 1021005 | S38: 1021006 | T38: 1021007
A39: 10211 | B39: 巨角斗牛 | C39: Pet_10211 | D39: 9.3提交 | E39: 10211 | F39: 8.13提交 | G39: 10211 | H39: 8.13提交 | I39: skill_1021001 | J39: 0.4 | K39: skill_1021102 | L39: 3 | M39: 0.4_anim | N39: 0.35~0.65 | O39: 1021102 | P39: 1021103 | Q39: 1021104 | R39: 1021105 | S39: 1021106 | T39: 1021107
A40: 10220 | B40: 重锤兽 | C40: Pet_10220 | D40: 7.17修改 | E40: 10220 | F40: 完成 | G40: 10220 | H40: 完成 | I40: skill_1022001 | J40: 0.4 | K40: skill_1022002 | L40: 1.7 | M40: 0.6 | N40: 0.2 | O40: 1022002 | P40: 1022003 | Q40: 1022004 | R40: 1022005 | S40: 1022006 | T40: 1022007
...

Sheet 未使用
A1: 10060 | B1: 幻影猫 | E1: PetBasis_Name_10060 | F1: 1 | H1: 1006001 | I1: 1 | J1: 幻影猫是诞生于虚空中的神秘存在，它的灵巧与隐秘使得它成为虚空中最难以捉摸的守护者。它常常栖息在幽暗的虚空裂隙中，凭借召唤虚空之眼的能力，将入侵者瞬间引入深不可测的痛苦。 | K1: PetBasis_Story_10060 | L1: 10060 | M1: 10060 | N1: Pet_10060 | O1: 6000 | P1: 1000 | Q1: 30000 | R1: 6000 | S1: 80 | T1: 80|7|88|15|11|65|67|23|13|35|13|63|28|9
A2: 10061 | B2: 梦影猫 | E2: PetBasis_Name_10061 | F2: 1 | H2: 1006101 | I2: 1 | J2: 梦影猫，是虚空中力量更为强大的存在，作为幻影猫的进化形态，它能够掌控更强大的虚空力量。梦影猫生活在虚空的深层，远离凡世，但它的力量无时无刻不在影响着世界的秩序。 | K2: PetBasis_Story_10061 | L2: 10061 | M2: 10061 | N2: Pet_10061 | O2: 10000 | P2: 1000 | Q2: 30000 | R2: 10000 | S2: 80 | T2: 96|38|74|25|84|89|52|33|66|98|35|28|9|91
A3: 10062 | B3: 虚梦猫 | E3: PetBasis_Name_10062 | F3: 1 | H3: 1006201 | I3: 1 | J3: 作为虚空的终极守护者，虚梦猫的力量已达巅峰。它象征着虚空中的最强能量，连虚空本身都在它的控制之下。传说中，虚梦猫可以召唤出最强的虚空之眼，爆发出天崩地裂般的巨量能量冲击，席卷一切。 | K3: PetBasis_Story_10062 | L3: 10062 | M3: 10062 | N3: Pet_10062 | O3: 15000 | P3: 1000 | Q3: 30000 | R3: 15000 | S3: 70 | T3: 53|67|7|57|68|17|61|98|69|75|66|28|58|22
A4: 10070 | B4: 行路草 | E4: PetBasis_Name_10070 | F4: 1 | H4: 1007001 | I4: 1 | J4: 在广袤的森林深处，行路草是一种古老而神秘的植物生物。它的身体看似柔弱，却蕴藏着大自然的无穷力量。行路草喜欢安静地游走于大地之上，时而停下脚步，将寄生种子播撒在大地中。 | K4: PetBasis_Story_10070 | L4: 10070 | M4: 10070 | N4: Pet_10070 | O4: 8000 | P4: 1000 | Q4: 30000 | R4: 8000 | S4: 80 | T4: 94|26|13|75|14|83|18|55|24|57|51|71|47|27
A5: 10071 | B5: 行路兽 | E5: PetBasis_Name_10071 | F5: 1 | H5: 1007101 | I5: 1 | J5: 随着时间的推移，行路草进化为更强大的形态——行路兽。这一形态的行路兽拥有更为厚重的躯体和更强的力量，它对大地的掌控也更加深入。行路兽的行动更加沉稳，每一次踏足地面都仿佛唤醒了沉睡的草木与泥土。 | K5: PetBasis_Story_10071 | L5: 10071 | M5: 10071 | N5: Pet_10071 | O5: 15000 | P5: 1000 | Q5: 30000 | R5: 15000 | S5: 70 | T5: 94|26|13|75|14|83|18|55|24|57|51|71|47|27
A6: 10090 | B6: 冰角鹿 | E6: PetBasis_Name_10090 | F6: 1 | H6: 1009001 | I6: 1 | J6: 传说冰角鹿曾帮助一位迷路的旅行者找到了回家的路，从此被视为善良和希望的象征。 | K6: PetBasis_Story_10090 | L6: 10090 | M6: 10090 | N6: Pet_10090 | O6: 10000 | P6: 1000 | Q6: 30000 | R6: 10000 | S6: 80 | T6: 9|86|81|24|26|56|99|67|91|64|80|23|73|99
A7: 10091 | B7: 霜角鹿 | E7: PetBasis_Name_10091 | F7: 1 | H7: 1009101 | I7: 1 | J7: 霜角鹿虽然外表威武，但内心却十分呆萌。有传说它们曾因为贪玩，误把自己埋在雪堆里，直到第二天才被找到。 | K7: PetBasis_Story_10091 | L7: 10091 | M7: 10091 | N7: Pet_10091 | O7: 12000 | P7: 1000 | Q7: 30000 | R7: 12000 | S7: 80 | T7: 87|31|1|38|82|18|84|90|96|92|12|71|24|90
A8: 10102 | B8: 影忍菇 | E8: PetBasis_Name_10102 | F8: 1 | H8: 1010201 | I8: 1 | J8: 上忍菇最终进化成了影忍菇，已抛弃毒蘑菇，靠奥义“神速斩击”解决问题。它以极快速度冲刺，敌人还没反应过来，就已经被它无声无息地“斩成蘑菇片”了。 | K8: PetBasis_Story_10102 | L8: 10102 | M8: 10102 | N8: Pet_10102 | O8: 20000 | P8: 1000 | Q8: 30000 | R8: 20000 | S8: 70 | T8: 95|13|87|11|18|75|3|40|77|61|61|58|95|73
A9: 10121 | B9: 尖牙蔓 | E9: PetBasis_Name_10121 | F9: 1 | H9: 1012101 | I9: 1 | J9: 尖牙蔓是藤蔓界的“啃咬专家”，它的口头禅是：“没有什么是咬不动的，咬多了自然就破！”每当战斗打响，它会召唤出无数的蔓草分身，进行疯狂的啃咬攻击。敌人常常在尖牙蔓的连环“咬咬”中毫无招架之力，甚至怀疑自己来到了巨型食肉植物的世界。尖牙蔓总是得意地说：“咬你一口不够，那就来无数口！” | K9: PetBasis_Story_10121 | L9: 10121 | M9: 10121 | N9: Pet_10121 | O9: 15000 | P9: 1000 | Q9: 30000 | R9: 15000 | S9: 70 | T9: 95|13|87|11|18|75|3|40|77|61|61|58|95|73
A10: 10122 | B10: 三头巨蔓 | E10: PetBasis_Name_10122 | F10: 1 | H10: 1012201 | I10: 1 | J10: 三头巨蔓是个不走寻常路的怪物，喜欢用幻觉来迷惑敌人。它通过释放毒气，让敌人以为自己置身于美丽的花草地，但等到对方刚想躺下享受时，三头巨蔓的触手突然从幻觉中冒出来，开始“悄悄”进行吞噬攻击。三头巨蔓喜欢说：“让你看看什么是真正的美景……不过最后，你会被吞掉哦！” | K10: PetBasis_Story_10122 | L10: 10122 | M10: 10122 | N10: Pet_10122 | O10: 20000 | P10: 1000 | Q10: 30000 | R10: 20000 | S10: 70 | T10: 95|13|87|11|18|75|3|40|77|61|61|58|95|73
A11: 10141 | B11: 炽焰虎 | E11: PetBasis_Name_10141 | F11: 1 | H11: 1014101 | I11: 1 | J11: 随着时间的推移，炽焰幼虎成长为强大的炽焰虎。它的力量宛如雷霆般不可抵挡，每一次攻击都如猛兽般迅猛而精准。炽焰虎的爪击已变得极为强大，撕裂敌人的同时带来炽热的灼烧效果。 | K11: PetBasis_Story_10141 | L11: 10141 | M11: 10141 | N11: Pet_10141 | O11: 20000 | P11: 1000 | Q11: 30000 | R11: 20000 | S11: 70 | T11: 94|26|13|75|14|83|18|55|24|57|51|71|47|27
A12: 10150 | B12: 惊吓魔盒 | E12: PetBasis_Name_10150 | F12: 1 | H12: 1015001 | I12: 1 | J12: 惊吓魔盒喜欢藏在角落，等敌人靠近时突然打开它的神秘魔盒，伴随着巨大的“砰”声，把敌人吓得魂飞魄散。每次魔盒爆裂后，它都会得意地说：“惊不惊喜？意不意外？ | K12: PetBasis_Story_10150 | L12: 10150 | M12: 10150 | N12: Pet_10150 | O12: 8000 | P12: 1000 | Q12: 30000 | R12: 8000 | S12: 80 | T12: 6|47|93|97|89|56|67|37|14|74|47|47|2|6
... A62: 10622 | B62: 船长海盗鲨 | E62: PetBasis_Name_10622 | F62: 1 | H62: 1062201 | I62: 4 | J62: 大副海盗鲨已经成为海上战斗的老手，它掌控着更强的水之力。每当它隐匿于水下，紧接着以更强的力量破水而出，激起狂浪，敌人根本无法逃脱这致命的袭击。 | K62: PetBasis_Story_10622 | L62: 10622 | M62: 10622 | N62: Pet_10622 | O62: 30000 | P62: 1000 | Q62: 30000 | R62: 30000 | S62: 70 | T62: 47|20|34|4|59|39|37|87|99|67|13|31|17|26
