Workbook

Sheet Sheet1
A1: Id | B1: Chapter | C1: LevelId | D1: Name_Note | E1: Name | F1: MonsterData | G1: Node | H1: FirstReward | I1: Gold | J1: LoreRate | K1: Drop | L1: EquipLevel | M1: SuggestionStr | N1: UnlockType | O1: Level
A2: Int | B2: Int | C2: Int | D2: String | E2: String | F2: Int | G2: Int | H2: String | I2: String | J2: Int | K2: String | L2: Int | M2: String | N2: Int | O2: String
A3: 序ID | B3: 章节ID | C3: 关卡ID | D3: <c>关卡名称 | E3: 关卡名称 | F3: 关卡刷怪数据 | G3: 关卡节点 | H3: 关卡首通奖励 | I3: 金币掉落数量 | J3: 传承装备掉落概率 | K3: 关卡掉落 | L3: 装备等级 | M3: 推荐战斗力 | N3: 隐藏解锁条件 | O3: Unlock
A4: 101010011 | B4: 1 | C4: 1001 | D4: 1001 | E4: Stage_Name_1 | F4: 10011 | G4: 1 | H4: 0 | I4: =ROUND(VLOOKUP(C:C,[1]关卡难度!$C:$P,14,FALSE)*0.5,0) -> 78 | J4: 0 | K4: 0 | L4: 10 | M4: 100 | N4: 0 | O4: 0
A5: 101010012 | B5: 1 | C5: 1001 | D5: 1001 | E5: Stage_Name_1 | F5: 10012 | G5: 2 | H5: 0 | I5: =ROUND(VLOOKUP(C:C,[1]关卡难度!$C:$P,14,FALSE)*0.5,0) -> 78 | J5: 0 | K5: 0 | L5: 10 | M5: 100 | N5: 0 | O5: 0
A6: 101010013 | B6: 1 | C6: 1001 | D6: 1001 | E6: Stage_Name_1 | F6: 10013 | G6: 3 | H6: 0 | I6: =ROUND(VLOOKUP(C:C,[1]关卡难度!$C:$P,14,FALSE)*0.5,0) -> 78 | J6: 0 | K6: 0 | L6: 10 | M6: 100 | N6: 0 | O6: 0
A7: 101010014 | B7: 1 | C7: 1001 | D7: 1001 | E7: Stage_Name_1 | F7: 10014 | G7: 4 | H7: 0 | I7: =ROUND(VLOOKUP(C:C,[1]关卡难度!$C:$P,14,FALSE)*0.5,0) -> 78 | J7: 0 | K7: 0 | L7: 10 | M7: 100 | N7: 0 | O7: 0
A8: 101010015 | B8: 1 | C8: 1001 | D8: 1001 | E8: Stage_Name_1 | F8: 10015 | G8: 5 | H8: 10000001,3|1000,100|1021001,1 | I8: =ROUND(VLOOKUP(C:C,[1]关卡难度!$C:$P,14,FALSE)*0.5,0) -> 78 | J8: 0 | K8: 1001 | L8: 10 | M8: 100 | N8: 0 | O8: 0
A9: 101010021 | B9: 1 | C9: 1002 | D9: 1002 | E9: Stage_Name_1 | F9: 10021 | G9: 1 | H9: 0 | I9: =ROUND(VLOOKUP(C:C,[1]关卡难度!$C:$P,14,FALSE)*0.5,0) -> 89 | J9: 0 | K9: =K4 -> 0 | L9: 10 | M9: 200 | N9: 0 | O9: 0
A10: 101010022 | B10: 1 | C10: 1002 | D10: 1002 | E10: Stage_Name_1 | F10: 10022 | G10: 2 | H10: 0 | I10: =ROUND(VLOOKUP(C:C,[1]关卡难度!$C:$P,14,FALSE)*0.5,0) -> 89 | J10: 0 | K10: =K5 -> 0 | L10: 10 | M10: 200 | N10: 0 | O10: 0
A11: 101010023 | B11: 1 | C11: 1002 | D11: 1002 | E11: Stage_Name_1 | F11: 10023 | G11: 3 | H11: 0 | I11: =ROUND(VLOOKUP(C:C,[1]关卡难度!$C:$P,14,FALSE)*0.5,0) -> 89 | J11: 0 | K11: =K6 -> 0 | L11: 10 | M11: 200 | N11: 0 | O11: 0
A12: 101010024 | B12: 1 | C12: 1002 | D12: 1002 | E12: Stage_Name_1 | F12: 10024 | G12: 4 | H12: 0 | I12: =ROUND(VLOOKUP(C:C,[1]关卡难度!$C:$P,14,FALSE)*0.5,0) -> 89 | J12: 0 | K12: =K7 -> 0 | L12: 10 | M12: 200 | N12: 0 | O12: 0
A13: 101010025 | B13: 1 | C13: 1002 | D13: 1002 | E13: Stage_Name_1 | F13: 10025 | G13: 5 | H13: 10000001,3|1000,100|1023001,1 | I13: =ROUND(VLOOKUP(C:C,[1]关卡难度!$C:$P,14,FALSE)*0.5,0) -> 89 | J13: 0 | K13: =K8 -> 1001 | L13: 10 | M13: 500 | N13: 0 | O13: 0
A14: 101010031 | B14: 1 | C14: 1003 | D14: 1003 | E14: Stage_Name_1 | F14: 10031 | G14: 1 | H14: 0 | I14: =ROUND(VLOOKUP(C:C,[1]关卡难度!$C:$P,14,FALSE)*0.5,0) -> 94 | J14: 0 | K14: =K9 -> 0 | L14: 10 | M14: 800 | N14: 0 | O14: 0
A15: 101010032 | B15: 1 | C15: 1003 | D15: 1003 | E15: Stage_Name_1 | F15: 10032 | G15: 2 | H15: 0 | I15: =ROUND(VLOOKUP(C:C,[1]关卡难度!$C:$P,14,FALSE)*0.5,0) -> 94 | J15: 0 | K15: =K10 -> 0 | L15: 10 | M15: 800 | N15: 0 | O15: 0
A16: 101010033 | B16: 1 | C16: 1003 | D16: 1003 | E16: Stage_Name_1 | F16: 10033 | G16: 3 | H16: 0 | I16: =ROUND(VLOOKUP(C:C,[1]关卡难度!$C:$P,14,FALSE)*0.5,0) -> 94 | J16: 0 | K16: =K11 -> 0 | L16: 10 | M16: 800 | N16: 0 | O16: 0
A17: 101010034 | B17: 1 | C17: 1003 | D17: 1003 | E17: Stage_Name_1 | F17: 10034 | G17: 4 | H17: 0 | I17: =ROUND(VLOOKUP(C:C,[1]关卡难度!$C:$P,14,FALSE)*0.5,0) -> 94 | J17: 0 | K17: =K12 -> 0 | L17: 10 | M17: 800 | N17: 0 | O17: 0
A18: 101010035 | B18: 1 | C18: 1003 | D18: 1003 | E18: Stage_Name_1 | F18: 10035 | G18: 5 | H18: 10000001,3|1000,100|1022001,1 | I18: =ROUND(VLOOKUP(C:C,[1]关卡难度!$C:$P,14,FALSE)*0.5,0) -> 94 | J18: 0 | K18: =K13 -> 1001 | L18: 10 | M18: 1700 | N18: 0 | O18: 0
A19: 101010041 | B19: 1 | C19: 1004 | D19: 1004 | E19: Stage_Name_1 | F19: 10041 | G19: 1 | H19: 0 | I19: =ROUND(VLOOKUP(C:C,[1]关卡难度!$C:$P,14,FALSE)*0.5,0) -> 98 | J19: 0 | K19: =K14 -> 0 | L19: 10 | M19: 1600 | N19: 0 | O19: 0
A20: 101010042 | B20: 1 | C20: 1004 | D20: 1004 | E20: Stage_Name_1 | F20: 10042 | G20: 2 | H20: 0 | I20: =ROUND(VLOOKUP(C:C,[1]关卡难度!$C:$P,14,FALSE)*0.5,0) -> 98 | J20: 0 | K20: =K15 -> 0 | L20: 10 | M20: 1600 | N20: 0 | O20: 0
A21: 101010043 | B21: 1 | C21: 1004 | D21: 1004 | E21: Stage_Name_1 | F21: 10043 | G21: 3 | H21: 0 | I21: =ROUND(VLOOKUP(C:C,[1]关卡难度!$C:$P,14,FALSE)*0.5,0) -> 98 | J21: 0 | K21: =K16 -> 0 | L21: 10 | M21: 1600 | N21: 0 | O21: 0
A22: 101010044 | B22: 1 | C22: 1004 | D22: 1004 | E22: Stage_Name_1 | F22: 10044 | G22: 4 | H22: 0 | I22: =ROUND(VLOOKUP(C:C,[1]关卡难度!$C:$P,14,FALSE)*0.5,0) -> 98 | J22: 0 | K22: =K17 -> 0 | L22: 10 | M22: 1600 | N22: 0 | O22: 0
A23: 101010045 | B23: 1 | C23: 1004 | D23: 1004 | E23: Stage_Name_1 | F23: 10045 | G23: 5 | H23: 10000001,3|1000,100|1024001,1 | I23: =ROUND(VLOOKUP(C:C,[1]关卡难度!$C:$P,14,FALSE)*0.5,0) -> 98 | J23: 0 | K23: =K18 -> 1001 | L23: 10 | M23: 3200 | N23: 0 | O23: 0
A24: 101010051 | B24: 1 | C24: 1005 | D24: 1005 | E24: Stage_Name_1 | F24: 10051 | G24: 1 | H24: 0 | I24: =ROUND(VLOOKUP(C:C,[1]关卡难度!$C:$P,14,FALSE)*0.5,0) -> 103 | J24: 0 | K24: =K19 -> 0 | L24: 10 | M24: 2600 | N24: 0 | O24: 0
A25: 101010052 | B25: 1 | C25: 1005 | D25: 1005 | E25: Stage_Name_1 | F25: 10052 | G25: 2 | H25: 0 | I25: =ROUND(VLOOKUP(C:C,[1]关卡难度!$C:$P,14,FALSE)*0.5,0) -> 103 | J25: 0 | K25: =K20 -> 0 | L25: 10 | M25: 2600 | N25: 0 | O25: 0
A26: 101010053 | B26: 1 | C26: 1005 | D26: 1005 | E26: Stage_Name_1 | F26: 10053 | G26: 3 | H26: 0 | I26: =ROUND(VLOOKUP(C:C,[1]关卡难度!$C:$P,14,FALSE)*0.5,0) -> 103 | J26: =J21 -> 0 | K26: =K21 -> 0 | L26: 10 | M26: 2600 | N26: 0 | O26: 0
A27: 101010054 | B27: 1 | C27: 1005 | D27: 1005 | E27: Stage_Name_1 | F27: 10054 | G27: 4 | H27: 0 | I27: =ROUND(VLOOKUP(C:C,[1]关卡难度!$C:$P,14,FALSE)*0.5,0) -> 103 | J27: =J22 -> 0 | K27: =K22 -> 0 | L27: 10 | M27: 2600 | N27: 0 | O27: 0
A28: 101010055 | B28: 1 | C28: 1005 | D28: 1005 | E28: Stage_Name_1 | F28: 10055 | G28: 5 | H28: 10000001,3|1000,100|5003,1 | I28: =ROUND(VLOOKUP(C:C,[1]关卡难度!$C:$P,14,FALSE)*0.5,0) -> 103 | J28: 2000 | K28: =K23+1 -> 1002 | L28: 10 | M28: 5200 | N28: 0 | O28: 0
A29: 101010061 | B29: 1 | C29: 1006 | D29: 1006 | E29: Stage_Name_1 | F29: 10061 | G29: 1 | H29: 0 | I29: =ROUND(VLOOKUP(C:C,[1]关卡难度!$C:$P,14,FALSE)*0.5,0) -> 117 | J29: =J24 -> 0 | K29: =K24 -> 0 | L29: 20 | M29: 6700 | N29: 0 | O29: 0
A30: 101010062 | B30: 1 | C30: 1006 | D30: 1006 | E30: Stage_Name_1 | F30: 10062 | G30: 2 | H30: 0 | I30: =ROUND(VLOOKUP(C:C,[1]关卡难度!$C:$P,14,FALSE)*0.5,0) -> 117 | J30: =J25 -> 0 | K30: =K25 -> 0 | L30: 20 | M30: 6700 | N30: 0 | O30: 0
A31: 101010063 | B31: 1 | C31: 1006 | D31: 1006 | E31: Stage_Name_1 | F31: 10063 | G31: 3 | H31: 0 | I31: =ROUND(VLOOKUP(C:C,[1]关卡难度!$C:$P,14,FALSE)*0.5,0) -> 117 | J31: =J26 -> 0 | K31: =K26 -> 0 | L31: 20 | M31: 6700 | N31: 0 | O31: 0
A32: 101010064 | B32: 1 | C32: 1006 | D32: 1006 | E32: Stage_Name_1 | F32: 10064 | G32: 4 | H32: 0 | I32: =ROUND(VLOOKUP(C:C,[1]关卡难度!$C:$P,14,FALSE)*0.5,0) -> 117 | J32: =J27 -> 0 | K32: =K27 -> 0 | L32: 20 | M32: 6700 | N32: 0 | O32: 0
A33: 101010065 | B33: 1 | C33: 1006 | D33: 1006 | E33: Stage_Name_1 | F33: 10065 | G33: 5 | H33: 10000001,3|1000,100|5003,1 | I33: =ROUND(VLOOKUP(C:C,[1]关卡难度!$C:$P,14,FALSE)*0.5,0) -> 117 | J33: =J28 -> 2000 | K33: =K28 -> 1002 | L33: 20 | M33: 13500 | N33: 0 | O33: 0
A34: 101010071 | B34: 1 | C34: 1007 | D34: 1007 | E34: Stage_Name_1 | F34: 10071 | G34: 1 | H34: 0 | I34: =ROUND(VLOOKUP(C:C,[1]关卡难度!$C:$P,14,FALSE)*0.5,0) -> 123 | J34: =J29 -> 0 | K34: =K29 -> 0 | L34: 20 | M34: 11000 | N34: 0 | O34: 0
A35: 101010072 | B35: 1 | C35: 1007 | D35: 1007 | E35: Stage_Name_1 | F35: 10072 | G35: 2 | H35: 0 | I35: =ROUND(VLOOKUP(C:C,[1]关卡难度!$C:$P,14,FALSE)*0.5,0) -> 123 | J35: =J30 -> 0 | K35: =K30 -> 0 | L35: 20 | M35: 11000 | N35: 0 | O35: 0
A36: 101010073 | B36: 1 | C36: 1007 | D36: 1007 | E36: Stage_Name_1 | F36: 10073 | G36: 3 | H36: 0 | I36: =ROUND(VLOOKUP(C:C,[1]关卡难度!$C:$P,14,FALSE)*0.5,0) -> 123 | J36: =J31 -> 0 | K36: =K31 -> 0 | L36: 20 | M36: 11000 | N36: 0 | O36: 0
A37: 101010074 | B37: 1 | C37: 1007 | D37: 1007 | E37: Stage_Name_1 | F37: 10074 | G37: 4 | H37: 0 | I37: =ROUND(VLOOKUP(C:C,[1]关卡难度!$C:$P,14,FALSE)*0.5,0) -> 123 | J37: =J32 -> 0 | K37: =K32 -> 0 | L37: 20 | M37: 11000 | N37: 0 | O37: 0
A38: 101010075 | B38: 1 | C38: 1007 | D38: 1007 | E38: Stage_Name_1 | F38: 10075 | G38: 5 | H38: 10000001,3|1000,100|5003,1 | I38: =ROUND(VLOOKUP(C:C,[1]关卡难度!$C:$P,14,FALSE)*0.5,0) -> 123 | J38: =J33 -> 2000 | K38: =K33 -> 1002 | L38: 20 | M38: 22000 | N38: 0 | O38: 0
A39: 101010081 | B39: 1 | C39: 1008 | D39: 1008 | E39: Stage_Name_1 | F39: 10081 | G39: 1 | H39: 0 | I39: =ROUND(VLOOKUP(C:C,[1]关卡难度!$C:$P,14,FALSE)*0.5,0) -> 129 | J39: =J34 -> 0 | K39: =K34 -> 0 | L39: 20 | M39: 15800 | N39: 0 | O39: 0
A40: 101010082 | B40: 1 | C40: 1008 | D40: 1008 | E40: Stage_Name_1 | F40: 10082 | G40: 2 | H40: 0 | I40: =ROUND(VLOOKUP(C:C,[1]关卡难度!$C:$P,14,FALSE)*0.5,0) -> 129 | J40: =J35 -> 0 | K40: =K35 -> 0 | L40: 20 | M40: 15800 | N40: 0 | O40: 0
...

Sheet Sheet2
A1: Id | B1: Chapter | C1: LevelId | D1: Name | E1: Node | F1: MonsterData | G1: MonsterHp | H1: MonsterAtk | I1: FirstReward | J1: Gold | K1: RuneRate | L1: Drop | M1: EquipLevel | N1: SuggestionStr
A2: Int | B2: Int | C2: Int | D2: String | E2: Int | F2: Int | G2: String | H2: String | I2: String | J2: String | K2: Int | L2: String | M2: Int | N2: String
A3: 序ID | B3: 章节ID | C3: 关卡ID | D3: 关卡名称 | E3: 关卡节点 | F3: 关卡刷怪数据 | G3: 怪物生命 | H3: 怪物攻击力 | I3: 关卡首通奖励 | J3: 金币掉落数量 | K3: 符石掉落概率 | L3: 关卡掉落 | M3: 装备等级 | N3: 推荐战斗力
A4: 1000001 | B4: 1000 | C4: 1001 | D4: LV.1原野森林 1-1 | E4: 1 | F4: 10011 | G4: 50 | H4: 1 | I4: 0 | J4: 200 | K4: 0 | L4: 0 | M4: 1 | N4: =ROUND(G4*1+H4*3/5,0) -> 51
A5: 1000002 | B5: 1000 | C5: 1001 | D5: LV.1原野森林 1-1 | E5: 2 | F5: 10012 | G5: 80 | H5: 1 | I5: 0 | J5: 200 | K5: 0 | L5: 0 | M5: 1 | N5: =ROUND(G5*1+H5*3/5,0) -> 81
A6: 1000003 | B6: 1000 | C6: 1001 | D6: LV.1原野森林 1-1 | E6: 3 | F6: 10013 | G6: 100 | H6: 2 | I6: 0 | J6: 200 | K6: 0 | L6: 0 | M6: 1 | N6: =ROUND(G6*1+H6*3/5,0) -> 101
A7: 1000004 | B7: 1000 | C7: 1001 | D7: LV.1原野森林 1-1 | E7: 4 | F7: 10014 | G7: 140 | H7: 2 | I7: 0 | J7: 200 | K7: 0 | L7: 0 | M7: 1 | N7: =ROUND(G7*1+H7*3/5,0) -> 141
A8: 1000005 | B8: 1000 | C8: 1001 | D8: LV.1原野森林 1-1 | E8: 5 | F8: 10015 | G8: 850 | H8: 2 | I8: 10000001,3|1000,100 | J8: 200 | K8: 0 | L8: 10000001,1,5000 | M8: 1 | N8: =ROUND(G8*1+H8*3/5,0) -> 851
A9: 1000006 | B9: 1000 | C9: 1002 | D9: LV.1原野森林 1-2 | E9: 1 | F9: 10021 | G9: 200 | H9: 4 | I9: 0 | J9: 210 | K9: 0 | L9: 0 | M9: =M4+1 -> 2 | N9: =ROUND(G9*1+H9*3/5,0) -> 202
A10: 1000007 | B10: 1000 | C10: 1002 | D10: LV.1原野森林 1-2 | E10: 2 | F10: 10022 | G10: 230 | H10: 4 | I10: 0 | J10: 210 | K10: 0 | L10: 0 | M10: =M5+1 -> 2 | N10: =ROUND(G10*1+H10*3/5,0) -> 232
A11: 1000008 | B11: 1000 | C11: 1002 | D11: LV.1原野森林 1-2 | E11: 3 | F11: 10023 | G11: 260 | H11: 5 | I11: 0 | J11: 210 | K11: 0 | L11: 0 | M11: =M6+1 -> 2 | N11: =ROUND(G11*1+H11*3/5,0) -> 263
A12: 1000009 | B12: 1000 | C12: 1002 | D12: LV.1原野森林 1-2 | E12: 4 | F12: 10024 | G12: 290 | H12: 6 | I12: 0 | J12: 210 | K12: 0 | L12: 0 | M12: =M7+1 -> 2 | N12: =ROUND(G12*1+H12*3/5,0) -> 294
A13: 1000010 | B13: 1000 | C13: 1002 | D13: LV.1原野森林 1-2 | E13: 5 | F13: 10025 | G13: 1600 | H13: 10 | I13: 10000001,3|1000,100 | J13: 210 | K13: 0 | L13: 10000001,1,5000 | M13: =M8+1 -> 2 | N13: =ROUND(G13*1+H13*3/5,0) -> 1606
A14: 1000011 | B14: 1000 | C14: 1003 | D14: LV.1原野森林 1-3 | E14: 1 | F14: 10031 | G14: 350 | H14: 7 | I14: 0 | J14: 220 | K14: 0 | L14: 0 | M14: =M9+1 -> 3 | N14: =ROUND(G14*1+H14*3/5,0) -> 354
A15: 1000012 | B15: 1000 | C15: 1003 | D15: LV.1原野森林 1-3 | E15: 2 | F15: 10032 | G15: 380 | H15: 7 | I15: 0 | J15: 220 | K15: 0 | L15: 0 | M15: =M10+1 -> 3 | N15: =ROUND(G15*1+H15*3/5,0) -> 384
A16: 1000013 | B16: 1000 | C16: 1003 | D16: LV.1原野森林 1-3 | E16: 3 | F16: 10033 | G16: 410 | H16: 8 | I16: 0 | J16: 220 | K16: 0 | L16: 0 | M16: =M11+1 -> 3 | N16: =ROUND(G16*1+H16*3/5,0) -> 415
A17: 1000014 | B17: 1000 | C17: 1003 | D17: LV.1原野森林 1-3 | E17: 4 | F17: 10034 | G17: 440 | H17: 9 | I17: 0 | J17: 220 | K17: 0 | L17: 0 | M17: =M12+1 -> 3 | N17: =ROUND(G17*1+H17*3/5,0) -> 445
A18: 1000015 | B18: 1000 | C18: 1003 | D18: LV.1原野森林 1-3 | E18: 5 | F18: 10035 | G18: 2350 | H18: 20 | I18: 10000001,3|1000,100 | J18: 220 | K18: 0 | L18: 10000001,1,5000 | M18: =M13+1 -> 3 | N18: =ROUND(G18*1+H18*3/5,0) -> 2362
A19: 1000016 | B19: 1000 | C19: 1004 | D19: LV.1原野森林 1-4 | E19: 1 | F19: 10041 | G19: 500 | H19: 10 | I19: 0 | J19: 230 | K19: 0 | L19: 0 | M19: =M14+1 -> 4 | N19: =ROUND(G19*1+H19*3/5,0) -> 506
A20: 1000017 | B20: 1000 | C20: 1004 | D20: LV.1原野森林 1-4 | E20: 2 | F20: 10042 | G20: 530 | H20: 10 | I20: 0 | J20: 230 | K20: 0 | L20: 0 | M20: =M15+1 -> 4 | N20: =ROUND(G20*1+H20*3/5,0) -> 536
A21: 1000018 | B21: 1000 | C21: 1004 | D21: LV.1原野森林 1-4 | E21: 3 | F21: 10043 | G21: 560 | H21: 10 | I21: 0 | J21: 230 | K21: 0 | L21: 0 | M21: =M16+1 -> 4 | N21: =ROUND(G21*1+H21*3/5,0) -> 566
A22: 1000019 | B22: 1000 | C22: 1004 | D22: LV.1原野森林 1-4 | E22: 4 | F22: 10044 | G22: 590 | H22: 10 | I22: 0 | J22: 230 | K22: 0 | L22: 0 | M22: =M17+1 -> 4 | N22: =ROUND(G22*1+H22*3/5,0) -> 596
A23: 1000020 | B23: 1000 | C23: 1004 | D23: LV.1原野森林 1-4 | E23: 5 | F23: 10045 | G23: 3100 | H23: 30 | I23: 10000001,3|1000,100 | J23: 230 | K23: 0 | L23: 10000001,1,5000 | M23: =M18+1 -> 4 | N23: =ROUND(G23*1+H23*3/5,0) -> 3118
A24: 1000021 | B24: 1000 | C24: 1005 | D24: LV.1原野森林 1-5 | E24: 1 | F24: 10051 | G24: 650 | H24: 10 | I24: 0 | J24: 240 | K24: 0 | L24: 0 | M24: =M19+1 -> 5 | N24: =ROUND(G24*1+H24*3/5,0) -> 656
A25: 1000022 | B25: 1000 | C25: 1005 | D25: LV.1原野森林 1-5 | E25: 2 | F25: 10052 | G25: 680 | H25: 10 | I25: 0 | J25: 240 | K25: 0 | L25: 0 | M25: =M20+1 -> 5 | N25: =ROUND(G25*1+H25*3/5,0) -> 686
A26: 1000023 | B26: 1000 | C26: 1005 | D26: LV.1原野森林 1-5 | E26: 3 | F26: 10053 | G26: 710 | H26: 10 | I26: 0 | J26: 240 | K26: 0 | L26: 0 | M26: =M21+1 -> 5 | N26: =ROUND(G26*1+H26*3/5,0) -> 716
A27: 1000024 | B27: 1000 | C27: 1005 | D27: LV.1原野森林 1-5 | E27: 4 | F27: 10054 | G27: 740 | H27: 10 | I27: 0 | J27: 240 | K27: 0 | L27: 0 | M27: =M22+1 -> 5 | N27: =ROUND(G27*1+H27*3/5,0) -> 746
A28: 1000025 | B28: 1000 | C28: 1005 | D28: LV.1原野森林 1-5 | E28: 5 | F28: 10055 | G28: 3850 | H28: 40 | I28: 10000001,3|1000,100 | J28: 240 | K28: 0 | L28: 10000001,1,5000 | M28: =M23+1 -> 5 | N28: =ROUND(G28*1+H28*3/5,0) -> 3874
A29: 1000026 | B29: 1000 | C29: 1006 | D29: LV.1原野森林 1-6 | E29: 1 | F29: 10061 | G29: 800 | H29: 10 | I29: 0 | J29: 250 | K29: 0 | L29: 0 | M29: =M24+1 -> 6 | N29: =ROUND(G29*1+H29*3/5,0) -> 806
A30: 1000027 | B30: 1000 | C30: 1006 | D30: LV.1原野森林 1-6 | E30: 2 | F30: 10062 | G30: 830 | H30: 10 | I30: 0 | J30: 250 | K30: 0 | L30: 0 | M30: =M25+1 -> 6 | N30: =ROUND(G30*1+H30*3/5,0) -> 836
A31: 1000028 | B31: 1000 | C31: 1006 | D31: LV.1原野森林 1-6 | E31: 3 | F31: 10063 | G31: 860 | H31: 10 | I31: 0 | J31: 250 | K31: 0 | L31: 0 | M31: =M26+1 -> 6 | N31: =ROUND(G31*1+H31*3/5,0) -> 866
A32: 1000029 | B32: 1000 | C32: 1006 | D32: LV.1原野森林 1-6 | E32: 4 | F32: 10064 | G32: 890 | H32: 10 | I32: 0 | J32: 250 | K32: 0 | L32: 0 | M32: =M27+1 -> 6 | N32: =ROUND(G32*1+H32*3/5,0) -> 896
A33: 1000030 | B33: 1000 | C33: 1006 | D33: LV.1原野森林 1-6 | E33: 5 | F33: 10065 | G33: 4600 | H33: 50 | I33: 10000001,3|1000,100 | J33: 250 | K33: 0 | L33: 10000001,1,5000 | M33: =M28+1 -> 6 | N33: =ROUND(G33*1+H33*3/5,0) -> 4630
A34: 1000031 | B34: 2000 | C34: 2001 | D34: LV.1熔炉火山 2-1 | E34: 1 | F34: 20011 | G34: 2060 | H34: 15 | I34: 0 | J34: 280 | K34: 0 | L34: 0 | M34: =M29+1 -> 7 | N34: =ROUND(G34*1+H34*3/5,0) -> 2069
A35: 1000032 | B35: 2000 | C35: 2001 | D35: LV.1熔炉火山 2-1 | E35: 2 | F35: 20012 | G35: 2360 | H35: 15 | I35: 0 | J35: 280 | K35: 0 | L35: 0 | M35: =M30+1 -> 7 | N35: =ROUND(G35*1+H35*3/5,0) -> 2369
A36: 1000033 | B36: 2000 | C36: 2001 | D36: LV.1熔炉火山 2-1 | E36: 3 | F36: 20013 | G36: 2660 | H36: 15 | I36: 0 | J36: 280 | K36: 0 | L36: 0 | M36: =M31+1 -> 7 | N36: =ROUND(G36*1+H36*3/5,0) -> 2669
A37: 1000034 | B37: 2000 | C37: 2001 | D37: LV.1熔炉火山 2-1 | E37: 4 | F37: 20014 | G37: 2960 | H37: 15 | I37: 0 | J37: 280 | K37: 0 | L37: 0 | M37: =M32+1 -> 7 | N37: =ROUND(G37*1+H37*3/5,0) -> 2969
A38: 1000035 | B38: 2000 | C38: 2001 | D38: LV.1熔炉火山 2-1 | E38: 5 | F38: 20015 | G38: 21300 | H38: 60 | I38: 10000001,3|1000,100 | J38: 280 | K38: 0 | L38: 10000001,1,5000 | M38: =M33+1 -> 7 | N38: =ROUND(G38*1+H38*3/5,0) -> 21336
A39: 1000036 | B39: 2000 | C39: 2002 | D39: LV.1熔炉火山 2-2 | E39: 1 | F39: 20021 | G39: 3560 | H39: 15 | I39: 0 | J39: 310 | K39: 0 | L39: 0 | M39: =M34+1 -> 8 | N39: =ROUND(G39*1+H39*3/5,0) -> 3569
A40: 1000037 | B40: 2000 | C40: 2002 | D40: LV.1熔炉火山 2-2 | E40: 2 | F40: 20022 | G40: 3860 | H40: 15 | I40: 0 | J40: 310 | K40: 0 | L40: 0 | M40: =M35+1 -> 8 | N40: =ROUND(G40*1+H40*3/5,0) -> 3869
...

Sheet Sheet3
C9: 1 | D9: LV. | E9: 1 | F9: 原野森林 | K9: 1-1
C10: 2 | D10: LV. | E10: 1 | F10: 熔炉火山 | K10: 1-2
C11: 3 | D11: LV. | E11: 1 | F11: 砾石沙漠 | K11: 1-3
C12: 4 | D12: LV. | E12: 1 | F12: 埋骨高地 | K12: 1-4
C13: 5 | D13: LV. | E13: 1 | F13: 失落之都 | K13: 1-5
C14: 6 | D14: LV. | E14: 1 | F14: 极地冰原 | K14: 1-6
C15: 7 | D15: LV. | E15: =E9+1 -> 2 | F15: =F9 -> 原野森林 | K15: 2-1
C16: 8 | D16: LV. | E16: =E10+1 -> 2 | F16: =F10 -> 熔炉火山 | K16: 2-2
C17: 9 | D17: LV. | E17: =E11+1 -> 2 | F17: =F11 -> 砾石沙漠 | K17: 2-3
C18: 10 | D18: LV. | E18: =E12+1 -> 2 | F18: =F12 -> 埋骨高地 | K18: 2-4
C19: 11 | D19: LV. | E19: =E13+1 -> 2 | F19: =F13 -> 失落之都 | K19: 2-5
C20: 12 | D20: LV. | E20: =E14+1 -> 2 | F20: =F14 -> 极地冰原 | K20: 2-6
C21: 13 | D21: LV. | E21: =E15+1 -> 3 | F21: =F15 -> 原野森林
C22: 14 | D22: LV. | E22: =E16+1 -> 3 | F22: =F16 -> 熔炉火山
C23: 15 | D23: LV. | E23: =E17+1 -> 3 | F23: =F17 -> 砾石沙漠
C24: 16 | D24: LV. | E24: =E18+1 -> 3 | F24: =F18 -> 埋骨高地
C25: 17 | D25: LV. | E25: =E19+1 -> 3 | F25: =F19 -> 失落之都
C26: 18 | D26: LV. | E26: =E20+1 -> 3 | F26: =F20 -> 极地冰原
C27: 19 | D27: LV. | E27: =E21+1 -> 4 | F27: =F21 -> 原野森林
C28: 20 | D28: LV. | E28: =E22+1 -> 4 | F28: =F22 -> 熔炉火山
C29: 21 | D29: LV. | E29: =E23+1 -> 4 | F29: =F23 -> 砾石沙漠
C30: 22 | D30: LV. | E30: =E24+1 -> 4 | F30: =F24 -> 埋骨高地
C31: 23 | D31: LV. | E31: =E25+1 -> 4 | F31: =F25 -> 失落之都
C32: 24 | D32: LV. | E32: =E26+1 -> 4 | F32: =F26 -> 极地冰原
... C308: 300 | D308: LV. | E308: =E302+1 -> 50 | F308: =F302 -> 极地冰原
