Workbook

Sheet Sheet1
A1: Id | B1: Chapter | C1: LevelId | D1: Name_Note | E1: Node | F1: MonsterData | G1: HarmType | H1: EntryNumber | I1: EntryGroup | J1: PhysicalAtk | K1: MagicAtk | L1: SorceryAtk | M1: PhysicalDef | N1: MagicDef | O1: SorceryDef | P1: Hp | Q1: Reply | R1: Note1
A2: Int | B2: Int | C2: Int | D2: String | E2: Int | F2: Int | G2: Int | H2: Int | I2: Int | J2: String | K2: String | L2: String | M2: String | N2: String | O2: String | P2: String | Q2: String | R2: String
A3: 序ID | B3: 章节ID | C3: 关卡ID | D3: <c>关卡名称 | E3: 关卡节点 | F3: 关卡刷怪数据 | G3: 伤害类型 | H3: 词条数量 | I3: 词条组 | J3: 物理伤害 | K3: 魔法伤害 | L3: 道术伤害 | M3: 物理防御 | N3: 魔法防御 | O3: 道术防御 | P3: 生命值 | Q3: 生命恢复 | R3: <c>关卡系数
A4: =[1]Sheet1!A4 -> 101010011 | B4: 1 | C4: =[1]Sheet1!C4 -> 1001 | D4: =[1]Sheet1!D4 -> 1001 | E4: 1 | F4: 10011 | G4: 1 | H4: 0 | I4: 4 | J4: =VLOOKUP($A:$A,[2]关卡难度!$A:$M,13,2)*R4 -> 1 | K4: =J4 -> 1 | L4: =K4 -> 1 | M4: 0 | N4: =M4 -> 0 | O4: =M4 -> 0 | P4: =VLOOKUP($A:$A,[2]关卡难度!$A:$M,11,2)*R4 -> 35 | Q4: 0 | R4: 1
A5: =[1]Sheet1!A5 -> 101010012 | B5: 1 | C5: =[1]Sheet1!C5 -> 1001 | D5: =[1]Sheet1!D5 -> 1001 | E5: 2 | F5: 10012 | G5: 1 | H5: 0 | I5: 4 | J5: =VLOOKUP($A:$A,[2]关卡难度!$A:$M,13,2)*R5 -> 1 | K5: =J5 -> 1 | L5: =K5 -> 1 | M5: 0 | N5: =M5 -> 0 | O5: =M5 -> 0 | P5: =VLOOKUP($A:$A,[2]关卡难度!$A:$M,11,2)*R5 -> 35 | Q5: 0 | R5: 1
A6: =[1]Sheet1!A6 -> 101010013 | B6: 1 | C6: =[1]Sheet1!C6 -> 1001 | D6: =[1]Sheet1!D6 -> 1001 | E6: 3 | F6: 10013 | G6: 1 | H6: 0 | I6: 4 | J6: =VLOOKUP($A:$A,[2]关卡难度!$A:$M,13,2)*R6 -> 1 | K6: =J6 -> 1 | L6: =K6 -> 1 | M6: 0 | N6: =M6 -> 0 | O6: =M6 -> 0 | P6: =VLOOKUP($A:$A,[2]关卡难度!$A:$M,11,2)*R6 -> 35 | Q6: 0 | R6: 1
A7: =[1]Sheet1!A7 -> 101010014 | B7: 1 | C7: =[1]Sheet1!C7 -> 1001 | D7: =[1]Sheet1!D7 -> 1001 | E7: 4 | F7: 10014 | G7: 1 | H7: 0 | I7: 4 | J7: =VLOOKUP($A:$A,[2]关卡难度!$A:$M,13,2)*R7 -> 1 | K7: =J7 -> 1 | L7: =K7 -> 1 | M7: 0 | N7: =M7 -> 0 | O7: =M7 -> 0 | P7: =VLOOKUP($A:$A,[2]关卡难度!$A:$M,11,2)*R7 -> 35 | Q7: 0 | R7: 1
A8: =[1]Sheet1!A8 -> 101010015 | B8: 1 | C8: =[1]Sheet1!C8 -> 1001 | D8: =[1]Sheet1!D8 -> 1001 | E8: 5 | F8: 10015 | G8: 1 | H8: 0 | I8: 4 | J8: =VLOOKUP($A:$A,[2]关卡难度!$A:$M,13,2)*R8 -> 2 | K8: =J8 -> 2 | L8: =K8 -> 2 | M8: 0 | N8: =M8 -> 0 | O8: =M8 -> 0 | P8: =VLOOKUP($A:$A,[2]关卡难度!$A:$M,11,2)*R8 -> 70 | Q8: 0 | R8: 2
A9: =[1]Sheet1!A9 -> 101010021 | B9: 1 | C9: =[1]Sheet1!C9 -> 1002 | D9: =[1]Sheet1!D9 -> 1002 | E9: 1 | F9: 10021 | G9: 2 | H9: 0 | I9: 4 | J9: =VLOOKUP($A:$A,[2]关卡难度!$A:$M,13,2)*R9 -> 1 | K9: =J9 -> 1 | L9: =K9 -> 1 | M9: 0 | N9: =M9 -> 0 | O9: =M9 -> 0 | P9: =VLOOKUP($A:$A,[2]关卡难度!$A:$M,11,2)*R9 -> 242 | Q9: 0 | R9: =R4 -> 1
A10: =[1]Sheet1!A10 -> 101010022 | B10: 1 | C10: =[1]Sheet1!C10 -> 1002 | D10: =[1]Sheet1!D10 -> 1002 | E10: 2 | F10: 10022 | G10: 2 | H10: 0 | I10: 4 | J10: =VLOOKUP($A:$A,[2]关卡难度!$A:$M,13,2)*R10 -> 1 | K10: =J10 -> 1 | L10: =K10 -> 1 | M10: 0 | N10: =M10 -> 0 | O10: =M10 -> 0 | P10: =VLOOKUP($A:$A,[2]关卡难度!$A:$M,11,2)*R10 -> 242 | Q10: 0 | R10: =R5 -> 1
A11: =[1]Sheet1!A11 -> 101010023 | B11: 1 | C11: =[1]Sheet1!C11 -> 1002 | D11: =[1]Sheet1!D11 -> 1002 | E11: 3 | F11: 10023 | G11: 2 | H11: 0 | I11: 4 | J11: =VLOOKUP($A:$A,[2]关卡难度!$A:$M,13,2)*R11 -> 1 | K11: =J11 -> 1 | L11: =K11 -> 1 | M11: 0 | N11: =M11 -> 0 | O11: =M11 -> 0 | P11: =VLOOKUP($A:$A,[2]关卡难度!$A:$M,11,2)*R11 -> 242 | Q11: 0 | R11: =R6 -> 1
A12: =[1]Sheet1!A12 -> 101010024 | B12: 1 | C12: =[1]Sheet1!C12 -> 1002 | D12: =[1]Sheet1!D12 -> 1002 | E12: 4 | F12: 10024 | G12: 2 | H12: 0 | I12: 4 | J12: =VLOOKUP($A:$A,[2]关卡难度!$A:$M,13,2)*R12 -> 1 | K12: =J12 -> 1 | L12: =K12 -> 1 | M12: 0 | N12: =M12 -> 0 | O12: =M12 -> 0 | P12: =VLOOKUP($A:$A,[2]关卡难度!$A:$M,11,2)*R12 -> 242 | Q12: 0 | R12: =R7 -> 1
A13: =[1]Sheet1!A13 -> 101010025 | B13: 1 | C13: =[1]Sheet1!C13 -> 1002 | D13: =[1]Sheet1!D13 -> 1002 | E13: 5 | F13: 10025 | G13: 2 | H13: 0 | I13: 4 | J13: =VLOOKUP($A:$A,[2]关卡难度!$A:$M,13,2)*R13 -> 2 | K13: =J13 -> 2 | L13: =K13 -> 2 | M13: 0 | N13: =M13 -> 0 | O13: =M13 -> 0 | P13: =VLOOKUP($A:$A,[2]关卡难度!$A:$M,11,2)*R13 -> 484 | Q13: 0 | R13: 2
A14: =[1]Sheet1!A14 -> 101010031 | B14: 1 | C14: =[1]Sheet1!C14 -> 1003 | D14: =[1]Sheet1!D14 -> 1003 | E14: 1 | F14: 10031 | G14: 3 | H14: 0 | I14: 4 | J14: =VLOOKUP($A:$A,[2]关卡难度!$A:$M,13,2)*R14 -> 36 | K14: =J14 -> 36 | L14: =K14 -> 36 | M14: 0 | N14: =M14 -> 0 | O14: =M14 -> 0 | P14: =VLOOKUP($A:$A,[2]关卡难度!$A:$M,11,2)*R14 -> 726 | Q14: 0 | R14: =R9 -> 1
A15: =[1]Sheet1!A15 -> 101010032 | B15: 1 | C15: =[1]Sheet1!C15 -> 1003 | D15: =[1]Sheet1!D15 -> 1003 | E15: 2 | F15: 10032 | G15: 3 | H15: 0 | I15: 4 | J15: =VLOOKUP($A:$A,[2]关卡难度!$A:$M,13,2)*R15 -> 36 | K15: =J15 -> 36 | L15: =K15 -> 36 | M15: 0 | N15: =M15 -> 0 | O15: =M15 -> 0 | P15: =VLOOKUP($A:$A,[2]关卡难度!$A:$M,11,2)*R15 -> 726 | Q15: 0 | R15: =R10 -> 1
A16: =[1]Sheet1!A16 -> 101010033 | B16: 1 | C16: =[1]Sheet1!C16 -> 1003 | D16: =[1]Sheet1!D16 -> 1003 | E16: 3 | F16: 10033 | G16: 3 | H16: 0 | I16: 4 | J16: =VLOOKUP($A:$A,[2]关卡难度!$A:$M,13,2)*R16 -> 36 | K16: =J16 -> 36 | L16: =K16 -> 36 | M16: 0 | N16: =M16 -> 0 | O16: =M16 -> 0 | P16: =VLOOKUP($A:$A,[2]关卡难度!$A:$M,11,2)*R16 -> 726 | Q16: 0 | R16: =R11 -> 1
A17: =[1]Sheet1!A17 -> 101010034 | B17: 1 | C17: =[1]Sheet1!C17 -> 1003 | D17: =[1]Sheet1!D17 -> 1003 | E17: 4 | F17: 10034 | G17: 3 | H17: 0 | I17: 4 | J17: =VLOOKUP($A:$A,[2]关卡难度!$A:$M,13,2)*R17 -> 36 | K17: =J17 -> 36 | L17: =K17 -> 36 | M17: 0 | N17: =M17 -> 0 | O17: =M17 -> 0 | P17: =VLOOKUP($A:$A,[2]关卡难度!$A:$M,11,2)*R17 -> 726 | Q17: 0 | R17: =R12 -> 1
A18: =[1]Sheet1!A18 -> 101010035 | B18: 1 | C18: =[1]Sheet1!C18 -> 1003 | D18: =[1]Sheet1!D18 -> 1003 | E18: 5 | F18: 10035 | G18: 3 | H18: 0 | I18: 4 | J18: =VLOOKUP($A:$A,[2]关卡难度!$A:$M,13,2)*R18 -> 72 | K18: =J18 -> 72 | L18: =K18 -> 72 | M18: 0 | N18: =M18 -> 0 | O18: =M18 -> 0 | P18: =VLOOKUP($A:$A,[2]关卡难度!$A:$M,11,2)*R18 -> 1452 | Q18: 0 | R18: 2
A19: =[1]Sheet1!A19 -> 101010041 | B19: 1 | C19: =[1]Sheet1!C19 -> 1004 | D19: =[1]Sheet1!D19 -> 1004 | E19: 1 | F19: 10041 | G19: =G4 -> 1 | H19: 0 | I19: 4 | J19: =VLOOKUP($A:$A,[2]关卡难度!$A:$M,13,2)*R19 -> 69 | K19: =J19 -> 69 | L19: =K19 -> 69 | M19: 0 | N19: =M19 -> 0 | O19: =M19 -> 0 | P19: =VLOOKUP($A:$A,[2]关卡难度!$A:$M,11,2)*R19 -> 1377 | Q19: 0 | R19: =R14 -> 1
A20: =[1]Sheet1!A20 -> 101010042 | B20: 1 | C20: =[1]Sheet1!C20 -> 1004 | D20: =[1]Sheet1!D20 -> 1004 | E20: 2 | F20: 10042 | G20: =G5 -> 1 | H20: 0 | I20: 4 | J20: =VLOOKUP($A:$A,[2]关卡难度!$A:$M,13,2)*R20 -> 69 | K20: =J20 -> 69 | L20: =K20 -> 69 | M20: 0 | N20: =M20 -> 0 | O20: =M20 -> 0 | P20: =VLOOKUP($A:$A,[2]关卡难度!$A:$M,11,2)*R20 -> 1377 | Q20: 0 | R20: =R15 -> 1
A21: =[1]Sheet1!A21 -> 101010043 | B21: 1 | C21: =[1]Sheet1!C21 -> 1004 | D21: =[1]Sheet1!D21 -> 1004 | E21: 3 | F21: 10043 | G21: =G6 -> 1 | H21: 0 | I21: 4 | J21: =VLOOKUP($A:$A,[2]关卡难度!$A:$M,13,2)*R21 -> 69 | K21: =J21 -> 69 | L21: =K21 -> 69 | M21: 0 | N21: =M21 -> 0 | O21: =M21 -> 0 | P21: =VLOOKUP($A:$A,[2]关卡难度!$A:$M,11,2)*R21 -> 1377 | Q21: 0 | R21: =R16 -> 1
A22: =[1]Sheet1!A22 -> 101010044 | B22: 1 | C22: =[1]Sheet1!C22 -> 1004 | D22: =[1]Sheet1!D22 -> 1004 | E22: 4 | F22: 10044 | G22: =G7 -> 1 | H22: 0 | I22: 4 | J22: =VLOOKUP($A:$A,[2]关卡难度!$A:$M,13,2)*R22 -> 69 | K22: =J22 -> 69 | L22: =K22 -> 69 | M22: 0 | N22: =M22 -> 0 | O22: =M22 -> 0 | P22: =VLOOKUP($A:$A,[2]关卡难度!$A:$M,11,2)*R22 -> 1377 | Q22: 0 | R22: =R17 -> 1
A23: =[1]Sheet1!A23 -> 101010045 | B23: 1 | C23: =[1]Sheet1!C23 -> 1004 | D23: =[1]Sheet1!D23 -> 1004 | E23: 5 | F23: 10045 | G23: =G8 -> 1 | H23: 0 | I23: 4 | J23: =VLOOKUP($A:$A,[2]关卡难度!$A:$M,13,2)*R23 -> 138 | K23: =J23 -> 138 | L23: =K23 -> 138 | M23: 0 | N23: =M23 -> 0 | O23: =M23 -> 0 | P23: =VLOOKUP($A:$A,[2]关卡难度!$A:$M,11,2)*R23 -> 2754 | Q23: 0 | R23: =R18 -> 2
A24: =[1]Sheet1!A24 -> 101010051 | B24: 1 | C24: =[1]Sheet1!C24 -> 1005 | D24: =[1]Sheet1!D24 -> 1005 | E24: 1 | F24: 10051 | G24: =G9 -> 2 | H24: 0 | I24: 4 | J24: =VLOOKUP($A:$A,[2]关卡难度!$A:$M,13,2)*R24 -> 113 | K24: =J24 -> 113 | L24: =K24 -> 113 | M24: 0 | N24: =M24 -> 0 | O24: =M24 -> 0 | P24: =VLOOKUP($A:$A,[2]关卡难度!$A:$M,11,2)*R24 -> 2277 | Q24: 0 | R24: =R19 -> 1
A25: =[1]Sheet1!A25 -> 101010052 | B25: 1 | C25: =[1]Sheet1!C25 -> 1005 | D25: =[1]Sheet1!D25 -> 1005 | E25: 2 | F25: 10052 | G25: =G10 -> 2 | H25: 0 | I25: 4 | J25: =VLOOKUP($A:$A,[2]关卡难度!$A:$M,13,2)*R25 -> 113 | K25: =J25 -> 113 | L25: =K25 -> 113 | M25: 0 | N25: =M25 -> 0 | O25: =M25 -> 0 | P25: =VLOOKUP($A:$A,[2]关卡难度!$A:$M,11,2)*R25 -> 2277 | Q25: 0 | R25: =R20 -> 1
A26: =[1]Sheet1!A26 -> 101010053 | B26: 1 | C26: =[1]Sheet1!C26 -> 1005 | D26: =[1]Sheet1!D26 -> 1005 | E26: 3 | F26: 10053 | G26: =G11 -> 2 | H26: 0 | I26: 4 | J26: =VLOOKUP($A:$A,[2]关卡难度!$A:$M,13,2)*R26 -> 113 | K26: =J26 -> 113 | L26: =K26 -> 113 | M26: 0 | N26: =M26 -> 0 | O26: =M26 -> 0 | P26: =VLOOKUP($A:$A,[2]关卡难度!$A:$M,11,2)*R26 -> 2277 | Q26: 0 | R26: =R21 -> 1
A27: =[1]Sheet1!A27 -> 101010054 | B27: 1 | C27: =[1]Sheet1!C27 -> 1005 | D27: =[1]Sheet1!D27 -> 1005 | E27: 4 | F27: 10054 | G27: =G12 -> 2 | H27: 0 | I27: 4 | J27: =VLOOKUP($A:$A,[2]关卡难度!$A:$M,13,2)*R27 -> 113 | K27: =J27 -> 113 | L27: =K27 -> 113 | M27: 0 | N27: =M27 -> 0 | O27: =M27 -> 0 | P27: =VLOOKUP($A:$A,[2]关卡难度!$A:$M,11,2)*R27 -> 2277 | Q27: 0 | R27: =R22 -> 1
A28: =[1]Sheet1!A28 -> 101010055 | B28: 1 | C28: =[1]Sheet1!C28 -> 1005 | D28: =[1]Sheet1!D28 -> 1005 | E28: 5 | F28: 10055 | G28: =G13 -> 2 | H28: 0 | I28: 4 | J28: =VLOOKUP($A:$A,[2]关卡难度!$A:$M,13,2)*R28 -> 226 | K28: =J28 -> 226 | L28: =K28 -> 226 | M28: 0 | N28: =M28 -> 0 | O28: =M28 -> 0 | P28: =VLOOKUP($A:$A,[2]关卡难度!$A:$M,11,2)*R28 -> 4554 | Q28: 0 | R28: =R23 -> 2
A29: =[1]Sheet1!A29 -> 101010061 | B29: 1 | C29: =[1]Sheet1!C29 -> 1006 | D29: =[1]Sheet1!D29 -> 1006 | E29: 1 | F29: =F24+10 -> 10061 | G29: =G14 -> 3 | H29: 0 | I29: 4 | J29: =VLOOKUP($A:$A,[2]关卡难度!$A:$M,13,2)*R29 -> 258 | K29: =J29 -> 258 | L29: =K29 -> 258 | M29: 0 | N29: =M29 -> 0 | O29: =M29 -> 0 | P29: =VLOOKUP($A:$A,[2]关卡难度!$A:$M,11,2)*R29 -> 5958 | Q29: 0 | R29: =R24 -> 1
A30: =[1]Sheet1!A30 -> 101010062 | B30: 1 | C30: =[1]Sheet1!C30 -> 1006 | D30: =[1]Sheet1!D30 -> 1006 | E30: 2 | F30: =F25+10 -> 10062 | G30: =G15 -> 3 | H30: 0 | I30: 4 | J30: =VLOOKUP($A:$A,[2]关卡难度!$A:$M,13,2)*R30 -> 258 | K30: =J30 -> 258 | L30: =K30 -> 258 | M30: 0 | N30: =M30 -> 0 | O30: =M30 -> 0 | P30: =VLOOKUP($A:$A,[2]关卡难度!$A:$M,11,2)*R30 -> 5958 | Q30: 0 | R30: =R25 -> 1
A31: =[1]Sheet1!A31 -> 101010063 | B31: 1 | C31: =[1]Sheet1!C31 -> 1006 | D31: =[1]Sheet1!D31 -> 1006 | E31: 3 | F31: =F26+10 -> 10063 | G31: =G16 -> 3 | H31: 0 | I31: 4 | J31: =VLOOKUP($A:$A,[2]关卡难度!$A:$M,13,2)*R31 -> 258 | K31: =J31 -> 258 | L31: =K31 -> 258 | M31: 0 | N31: =M31 -> 0 | O31: =M31 -> 0 | P31: =VLOOKUP($A:$A,[2]关卡难度!$A:$M,11,2)*R31 -> 5958 | Q31: 0 | R31: =R26 -> 1
A32: =[1]Sheet1!A32 -> 101010064 | B32: 1 | C32: =[1]Sheet1!C32 -> 1006 | D32: =[1]Sheet1!D32 -> 1006 | E32: 4 | F32: =F27+10 -> 10064 | G32: =G17 -> 3 | H32: 0 | I32: 4 | J32: =VLOOKUP($A:$A,[2]关卡难度!$A:$M,13,2)*R32 -> 258 | K32: =J32 -> 258 | L32: =K32 -> 258 | M32: 0 | N32: =M32 -> 0 | O32: =M32 -> 0 | P32: =VLOOKUP($A:$A,[2]关卡难度!$A:$M,11,2)*R32 -> 5958 | Q32: 0 | R32: =R27 -> 1
A33: =[1]Sheet1!A33 -> 101010065 | B33: 1 | C33: =[1]Sheet1!C33 -> 1006 | D33: =[1]Sheet1!D33 -> 1006 | E33: 5 | F33: =F28+10 -> 10065 | G33: =G18 -> 3 | H33: 0 | I33: 4 | J33: =VLOOKUP($A:$A,[2]关卡难度!$A:$M,13,2)*R33 -> 516 | K33: =J33 -> 516 | L33: =K33 -> 516 | M33: 0 | N33: =M33 -> 0 | O33: =M33 -> 0 | P33: =VLOOKUP($A:$A,[2]关卡难度!$A:$M,11,2)*R33 -> 11916 | Q33: 0 | R33: =R28 -> 2
A34: =[1]Sheet1!A34 -> 101010071 | B34: 1 | C34: =[1]Sheet1!C34 -> 1007 | D34: =[1]Sheet1!D34 -> 1007 | E34: 1 | F34: =F29+10 -> 10071 | G34: =G19 -> 1 | H34: 0 | I34: 4 | J34: =VLOOKUP($A:$A,[2]关卡难度!$A:$M,13,2)*R34 -> 421 | K34: =J34 -> 421 | L34: =K34 -> 421 | M34: 0 | N34: =M34 -> 0 | O34: =M34 -> 0 | P34: =VLOOKUP($A:$A,[2]关卡难度!$A:$M,11,2)*R34 -> 9732 | Q34: 0 | R34: =R29 -> 1
A35: =[1]Sheet1!A35 -> 101010072 | B35: 1 | C35: =[1]Sheet1!C35 -> 1007 | D35: =[1]Sheet1!D35 -> 1007 | E35: 2 | F35: =F30+10 -> 10072 | G35: =G20 -> 1 | H35: 0 | I35: 4 | J35: =VLOOKUP($A:$A,[2]关卡难度!$A:$M,13,2)*R35 -> 421 | K35: =J35 -> 421 | L35: =K35 -> 421 | M35: 0 | N35: =M35 -> 0 | O35: =M35 -> 0 | P35: =VLOOKUP($A:$A,[2]关卡难度!$A:$M,11,2)*R35 -> 9732 | Q35: 0 | R35: =R30 -> 1
A36: =[1]Sheet1!A36 -> 101010073 | B36: 1 | C36: =[1]Sheet1!C36 -> 1007 | D36: =[1]Sheet1!D36 -> 1007 | E36: 3 | F36: =F31+10 -> 10073 | G36: =G21 -> 1 | H36: 0 | I36: 4 | J36: =VLOOKUP($A:$A,[2]关卡难度!$A:$M,13,2)*R36 -> 421 | K36: =J36 -> 421 | L36: =K36 -> 421 | M36: 0 | N36: =M36 -> 0 | O36: =M36 -> 0 | P36: =VLOOKUP($A:$A,[2]关卡难度!$A:$M,11,2)*R36 -> 9732 | Q36: 0 | R36: =R31 -> 1
A37: =[1]Sheet1!A37 -> 101010074 | B37: 1 | C37: =[1]Sheet1!C37 -> 1007 | D37: =[1]Sheet1!D37 -> 1007 | E37: 4 | F37: =F32+10 -> 10074 | G37: =G22 -> 1 | H37: 0 | I37: 4 | J37: =VLOOKUP($A:$A,[2]关卡难度!$A:$M,13,2)*R37 -> 421 | K37: =J37 -> 421 | L37: =K37 -> 421 | M37: 0 | N37: =M37 -> 0 | O37: =M37 -> 0 | P37: =VLOOKUP($A:$A,[2]关卡难度!$A:$M,11,2)*R37 -> 9732 | Q37: 0 | R37: =R32 -> 1
A38: =[1]Sheet1!A38 -> 101010075 | B38: 1 | C38: =[1]Sheet1!C38 -> 1007 | D38: =[1]Sheet1!D38 -> 1007 | E38: 5 | F38: =F33+10 -> 10075 | G38: =G23 -> 1 | H38: 0 | I38: 4 | J38: =VLOOKUP($A:$A,[2]关卡难度!$A:$M,13,2)*R38 -> 842 | K38: =J38 -> 842 | L38: =K38 -> 842 | M38: 0 | N38: =M38 -> 0 | O38: =M38 -> 0 | P38: =VLOOKUP($A:$A,[2]关卡难度!$A:$M,11,2)*R38 -> 19464 | Q38: 0 | R38: =R33 -> 2
A39: =[1]Sheet1!A39 -> 101010081 | B39: 1 | C39: =[1]Sheet1!C39 -> 1008 | D39: =[1]Sheet1!D39 -> 1008 | E39: 1 | F39: =F34+10 -> 10081 | G39: =G24 -> 2 | H39: 0 | I39: 4 | J39: =VLOOKUP($A:$A,[2]关卡难度!$A:$M,13,2)*R39 -> 584 | K39: =J39 -> 584 | L39: =K39 -> 584 | M39: 0 | N39: =M39 -> 0 | O39: =M39 -> 0 | P39: =VLOOKUP($A:$A,[2]关卡难度!$A:$M,11,2)*R39 -> 14043 | Q39: 0 | R39: =R34 -> 1
A40: =[1]Sheet1!A40 -> 101010082 | B40: 1 | C40: =[1]Sheet1!C40 -> 1008 | D40: =[1]Sheet1!D40 -> 1008 | E40: 2 | F40: =F35+10 -> 10082 | G40: =G25 -> 2 | H40: 0 | I40: 4 | J40: =VLOOKUP($A:$A,[2]关卡难度!$A:$M,13,2)*R40 -> 584 | K40: =J40 -> 584 | L40: =K40 -> 584 | M40: 0 | N40: =M40 -> 0 | O40: =M40 -> 0 | P40: =VLOOKUP($A:$A,[2]关卡难度!$A:$M,11,2)*R40 -> 14043 | Q40: 0 | R40: =R35 -> 1
...

Sheet Sheet2

Sheet Sheet3
